<?xml version="1.0" ?>
<!--******************************************************************
 ****** File automatically generated by generate_urdf.py script ******
 *********************************************************************-->
<robot xmlns:xacro="http://www.ros.org/wiki/xacro">
	<joint name="$(arg ns)LHipYawPitch" type="revolute">
		<parent link="$(arg ns)torso"/>
		<child link="$(arg ns)LPelvis"/>
		<origin rpy="0 0 0" xyz="0 0.05 -0.085"/>
		<axis xyz="0 0.707106 -0.707106"/>
		<limit effort="3.348" lower="-1.14529" upper="0.740718" velocity="4.16174"/>
	</joint>
	<link name="$(arg ns)LPelvis">
		<inertial>
			<mass value="0.06981"/>
			<inertia ixx="2.3407e-05" ixy="1.07922e-06" ixz="-1.76003e-06" iyy="4.76355e-05" iyz="2.76058e-06" izz="4.97021e-05"/>
			<origin rpy="0 0 0" xyz="-0.00781 -0.01114 0.02661"/>
		</inertial>
		<xacro:insert_visu_LPelvis/>
	</link>
	<joint name="$(arg ns)LHipRoll" type="revolute">
		<parent link="$(arg ns)LPelvis"/>
		<child link="$(arg ns)LHip"/>
		<origin rpy="0 0 0" xyz="0 0 0"/>
		<axis xyz="1.0 0 0"/>
		<limit effort="3.348" lower="-0.379435" upper="0.79046" velocity="4.16174"/>
	</joint>
	<link name="$(arg ns)LHip">
		<inertial>
			<mass value="0.13053"/>
			<inertia ixx="2.41106e-05" ixy="-6.08684e-07" ixz="6.33119e-06" iyy="6.34892e-05" iyz="-1.99137e-07" izz="5.67694e-05"/>
			<origin rpy="0 0 0" xyz="-0.01549 0.00029 -0.00515"/>
		</inertial>
		<xacro:insert_visu_LHip/>
	</link>
	<joint name="$(arg ns)LHipPitch" type="revolute">
		<parent link="$(arg ns)LHip"/>
		<child link="$(arg ns)LThigh"/>
		<origin rpy="0 0 0" xyz="0 0 0"/>
		<axis xyz="0 1.0 0"/>
		<limit effort="3.023" lower="-1.53589" upper="0.48398" velocity="6.40239"/>
	</joint>
	<link name="$(arg ns)LThigh">
		<inertial>
			<mass value="0.38968"/>
			<inertia ixx="0.000509844" ixy="2.11296e-06" ixz="5.64129e-05" iyy="0.000465358" iyz="-7.91029e-06" izz="0.000301098"/>
			<origin rpy="0 0 0" xyz="0.00138 0.00221 -0.05373"/>
		</inertial>
		<xacro:insert_visu_LThigh/>
	</link>
	<joint name="$(arg ns)LKneePitch" type="revolute">
		<parent link="$(arg ns)LThigh"/>
		<child link="$(arg ns)LTibia"/>
		<origin rpy="0 0 0" xyz="0 0 -0.1"/>
		<axis xyz="0 1.0 0"/>
		<limit effort="3.023" lower="-0.0923279" upper="2.11255" velocity="6.40239"/>
	</joint>
	<link name="$(arg ns)LTibia">
		<inertial>
			<mass value="0.29142"/>
			<inertia ixx="0.000470586" ixy="3.60392e-06" ixz="-2.86648e-05" iyy="0.000412654" iyz="7.13013e-06" izz="0.000185772"/>
			<origin rpy="0 0 0" xyz="0.00453 0.00225 -0.04936"/>
		</inertial>
		<xacro:insert_visu_LTibia/>
	</link>
	<joint name="$(arg ns)LAnklePitch" type="revolute">
		<parent link="$(arg ns)LTibia"/>
		<child link="$(arg ns)LAnklePitch"/>
		<origin rpy="0 0 0" xyz="0 0 -0.1029"/>
		<axis xyz="0 1.0 0"/>
		<limit effort="3.023" lower="-1.18944" upper="0.922581" velocity="6.40239"/>
	</joint>
	<link name="$(arg ns)LAnklePitch">
		<inertial>
			<mass value="0.13416"/>
			<inertia ixx="3.22034e-05" ixy="-8.83212e-09" ixz="4.27549e-06" iyy="6.7943e-05" iyz="2.84849e-07" izz="5.48269e-05"/>
			<origin rpy="0 0 0" xyz="0.00045 0.00029 0.00685"/>
		</inertial>
		<xacro:insert_visu_LAnklePitch/>
	</link>
	<joint name="$(arg ns)LAnkleRoll" type="revolute">
		<parent link="$(arg ns)LAnklePitch"/>
		<child link="$(arg ns)l_ankle"/>
		<origin rpy="0 0 0" xyz="0 0 0"/>
		<axis xyz="1.0 0 0"/>
		<limit effort="3.348" lower="-0.397761" upper="0.768992" velocity="4.16174"/>
	</joint>
	<link name="$(arg ns)l_ankle">
		<inertial>
			<mass value="0.16184"/>
			<inertia ixx="9.78911e-05" ixy="7.88039e-06" ixz="6.1279e-06" iyy="0.000369977" iyz="1.44233e-06" izz="0.000419417"/>
			<origin rpy="0 0 0" xyz="0.02542 0.0033 -0.03239"/>
		</inertial>
		<xacro:insert_visu_l_ankle/>
	</link>
	<joint name="$(arg ns)LLeg_effector_fixedjoint" type="fixed">
		<parent link="$(arg ns)l_ankle"/>
		<child link="$(arg ns)l_sole"/>
		<origin rpy="0 0 0" xyz="0 0 -0.04511"/>
		<axis xyz="0 0 0"/>
	</joint>
	<link name="$(arg ns)l_sole"/>


   <joint name="$(arg ns)base_left_motor_joint" type="fixed">
        <origin xyz="-0.02 0 0" rpy="0 0 0" />        
        <parent link="$(arg ns)l_sole"/>
        <child link="$(arg ns)left_motor" />
    </joint>

    <link name="$(arg ns)left_motor">
	<inertial>
                <origin xyz="0.0 0 0"/>
                <mass value="0.1" />
                <inertia ixx="0.001" ixy="0.0" ixz="0.0"
                         iyy="0.001" iyz="0.0" izz="0.001" />
        </inertial>
        <visual>
            <origin xyz="0 0.005 0" rpy="1.5707 0 0" />
            <geometry>
                <cylinder radius="0.015" length = "0.078"/>
            </geometry>
            <material name="gray">
                <color rgba="0.75 0.75 0.75 1"/>
            </material>
        </visual>

	<collision>
                <origin xyz="0 0 0" rpy="1.5707 0 0" />
                <geometry>
                    <cylinder radius="0.015" length = "0.078"/>
                </geometry>
        </collision>
    </link>

    <joint name="$(arg ns)left_wheel_joint_r" type="continuous">
        <origin xyz="0 -0.039 0" rpy="0 0 0"/>
        <parent link="$(arg ns)left_motor"/>
        <child link="$(arg ns)left_wheel_link_r"/>
        <axis xyz="0 1 0"/>
    </joint>

    <link name="$(arg ns)left_wheel_link_r">
	<inertial>
                <origin xyz="0 0 0"/>
                <mass value="0.01" />
                <inertia ixx="0.001" ixy="0.0" ixz="0.0"
                         iyy="0.001" iyz="0.0" izz="0.001" />
        </inertial>
	
        <visual>
            <origin xyz="0 0 0" rpy="1.5707 0 0" />
            <geometry>
                <cylinder radius="0.02" length = "0.01"/>
            </geometry>
            <material name="gray">
                <color rgba="1 1 1 0.9"/>
            </material>
        </visual>

	<collision>
                <origin xyz="0 0 0" rpy="1.5707 0 0" />
                <geometry>
                    <cylinder radius="0.02" length = "0.01"/>
                </geometry>
        </collision>
    </link>

    <joint name="$(arg ns)left_wheel_joint_l" type="continuous">
        <origin xyz="0 0.047 0" rpy="0 0 0"/>
        <parent link="$(arg ns)left_motor"/>
        <child link="$(arg ns)left_wheel_link_l"/>
        <axis xyz="0 1 0"/>
    </joint>

    <link name="$(arg ns)left_wheel_link_l">

	<inertial>
                <origin xyz="0 0 0"/>
                <mass value="0.01" />
                <inertia ixx="0.001" ixy="0.0" ixz="0.0"
                         iyy="0.001" iyz="0.0" izz="0.001" />
        </inertial>
        <visual>
            <origin xyz="0 0 0" rpy="1.5707 0 0" />
            <geometry>
                <cylinder radius="0.02" length = "0.01"/>
            </geometry>
            <material name="gray">
                <color rgba="1 1 1 0.9"/>
            </material>
        </visual>

	<collision>
                <origin xyz="0 0 0" rpy="1.5707 0 0" />
                <geometry>
                    <cylinder radius="0.02" length = "0.01"/>
                </geometry>
        </collision>
    </link>

   <joint name="$(arg ns)front_left_motor_joint" type="fixed">
        	<origin xyz="0.06 0 0" rpy="0 0 0" />        
        	<parent link="$(arg ns)l_sole"/>
        	<child link="$(arg ns)front_left_motor" />
    	</joint>

    	<link name="$(arg ns)front_left_motor">
		<inertial>
                	<origin xyz="0.0 0 0"/>
                	<mass value="0.1" />
                	<inertia ixx="0.00001" ixy="0.0" ixz="0.0"
                        	 iyy="0.00001" iyz="0.0" izz="0.00001" />
        	</inertial>
        	<visual>
            		<origin xyz="0 0.003 0" rpy="1.5707 0 0" />
            		<geometry>
                		<cylinder radius="0.015" length = "0.08"/>
            		</geometry>
            		<material name="gray">
               			 <color rgba="0.75 0.75 0.75 1"/>
            		</material>
        	</visual>

		<collision>
                	<origin xyz="0 0 0" rpy="1.5707 0 0" />
                	<geometry>
                    		<cylinder radius="0.015" length = "0.078"/>
                	</geometry>
        	</collision>
    	</link>

    <joint name="$(arg ns)front_left_wheel_joint_r" type="continuous">
        <origin xyz="0 -0.039 0" rpy="0 0 0"/>
        <parent link="$(arg ns)front_left_motor"/>
        <child link="$(arg ns)front_left_wheel_link_r"/>
        <axis xyz="0 1 0"/>
    </joint>

    <link name="$(arg ns)front_left_wheel_link_r">
	<inertial>
                <origin xyz="0 0 0"/>
                <mass value="0.01" />
                <inertia ixx="0.001" ixy="0.0" ixz="0.0"
                         iyy="0.001" iyz="0.0" izz="0.001" />
        </inertial>
	
        <visual>
            <origin xyz="0 0 0" rpy="1.5707 0 0" />
            <geometry>
                <cylinder radius="0.02" length = "0.01"/>
            </geometry>
            <material name="gray">
                <color rgba="1 1 1 0.9"/>
            </material>
        </visual>

	<collision>
                <origin xyz="0 0 0" rpy="1.5707 0 0" />
                <geometry>
                    <cylinder radius="0.02" length = "0.01"/>
                </geometry>
        </collision>
    </link>

    <joint name="$(arg ns)front_left_wheel_joint_l" type="continuous">
        <origin xyz="0 0.045 0" rpy="0 0 0"/>
        <parent link="$(arg ns)front_left_motor"/>
        <child link="$(arg ns)front_left_wheel_link_l"/>
        <axis xyz="0 1 0"/>
    </joint>

    <link name="$(arg ns)front_left_wheel_link_l">

	<inertial>
                <origin xyz="0 0 0"/>
                <mass value="0.01" />
                <inertia ixx="0.00001" ixy="0.0" ixz="0.0"
                         iyy="0.00001" iyz="0.0" izz="0.00001" />
        </inertial>
        <visual>
            <origin xyz="0 0 0" rpy="1.5707 0 0" />
            <geometry>
                <cylinder radius="0.02" length = "0.01"/>
            </geometry>
            <material name="gray">
                <color rgba="1 1 1 0.9"/>
            </material>
        </visual>

	<collision>
                <origin xyz="0 0 0" rpy="1.5707 0 0" />
                <geometry>
                    <cylinder radius="0.02" length = "0.01"/>
                </geometry>
        </collision>
    </link> 



	<joint name="$(arg ns)RHipYawPitch" type="revolute">
		<parent link="$(arg ns)torso"/>
		<child link="$(arg ns)RPelvis"/>
		<origin rpy="0 0 0" xyz="0 -0.05 -0.085"/>
		<axis xyz="0 0.707106 0.707106"/>
		<limit effort="3.348" lower="-1.14529" upper="0.740718" velocity="4.16174"/>
		<mimic joint="$(arg ns)LHipYawPitch" multiplier="1.0" offset="0"/>
	</joint>
	<link name="$(arg ns)RPelvis">
		<inertial>
			<mass value="0.06981"/>
			<inertia ixx="3.18766e-05" ixy="-1.07152e-06" ixz="-1.77295e-06" iyy="5.18361e-05" iyz="-7.00664e-06" izz="5.39657e-05"/>
			<origin rpy="0 0 0" xyz="-0.00781 0.01114 0.02661"/>
		</inertial>
		<xacro:insert_visu_RPelvis/>
	</link>
	<joint name="$(arg ns)RHipRoll" type="revolute">
		<parent link="$(arg ns)RPelvis"/>
		<child link="$(arg ns)RHip"/>
		<origin rpy="0 0 0" xyz="0 0 0"/>
		<axis xyz="1.0 0 0"/>
		<limit effort="3.348" lower="-0.79046" upper="0.379435" velocity="4.16174"/>
	</joint>
	<link name="$(arg ns)RHip">
		<inertial>
			<mass value="0.13053"/>
			<inertia ixx="2.41136e-05" ixy="5.67164e-07" ixz="6.30461e-06" iyy="6.34886e-05" iyz="1.97457e-07" izz="5.6773e-05"/>
			<origin rpy="0 0 0" xyz="-0.01549 -0.00029 -0.00515"/>
		</inertial>
		<xacro:insert_visu_RHip/>
	</link>
	<joint name="$(arg ns)RHipPitch" type="revolute">
		<parent link="$(arg ns)RHip"/>
		<child link="$(arg ns)RThigh"/>
		<origin rpy="0 0 0" xyz="0 0 0"/>
		<axis xyz="0 1.0 0"/>
		<limit effort="3.0226" lower="-1.53589" upper="0.48398" velocity="6.40239"/>
	</joint>
	<link name="$(arg ns)RThigh">
		<inertial>
			<mass value="0.38968"/>
			<inertia ixx="0.000510607" ixy="-2.02799e-06" ixz="5.69893e-05" iyy="0.0004665" iyz="7.09563e-06" izz="0.000301333"/>
			<origin rpy="0 0 0" xyz="0.00138 -0.00221 -0.05373"/>
		</inertial>
		<xacro:insert_visu_RThigh/>
	</link>
	<joint name="$(arg ns)RKneePitch" type="revolute">
		<parent link="$(arg ns)RThigh"/>
		<child link="$(arg ns)RTibia"/>
		<origin rpy="0 0 0" xyz="0 0 -0.1"/>
		<axis xyz="0 1.0 0"/>
		<limit effort="3.0226" lower="-0.0923279" upper="2.11255" velocity="6.40239"/>
	</joint>
	<link name="$(arg ns)RTibia">
		<inertial>
			<mass value="0.29142"/>
			<inertia ixx="0.000471336" ixy="-3.8668e-06" ixz="-3.71648e-05" iyy="0.00041228" iyz="-6.11093e-06" izz="0.000183997"/>
			<origin rpy="0 0 0" xyz="0.00453 -0.00225 -0.04936"/>
		</inertial>
		<xacro:insert_visu_RTibia/>
	</link>
	<joint name="$(arg ns)RAnklePitch" type="revolute">
		<parent link="$(arg ns)RTibia"/>
		<child link="$(arg ns)RAnklePitch"/>
		<origin rpy="0 0 0" xyz="0 0 -0.1029"/>
		<axis xyz="0 1.0 0"/>
		<limit effort="3.0226" lower="-1.1863" upper="0.932006" velocity="6.40239"/>
	</joint>
	<link name="$(arg ns)RAnklePitch">
		<inertial>
			<mass value="0.13416"/>
			<inertia ixx="3.22017e-05" ixy="4.68321e-08" ixz="4.28821e-06" iyy="6.79885e-05" iyz="-2.71089e-07" izz="5.48747e-05"/>
			<origin rpy="0 0 0" xyz="0.00045 -0.00029 0.00685"/>
		</inertial>
		<xacro:insert_visu_RAnklePitch/>
	</link>
	<joint name="$(arg ns)RAnkleRoll" type="revolute">
		<parent link="$(arg ns)RAnklePitch"/>
		<child link="$(arg ns)r_ankle"/>
		<origin rpy="0 0 0" xyz="0 0 0"/>
		<axis xyz="1.0 0 0"/>
		<limit effort="3.348" lower="-0.768992" upper="0.397761" velocity="4.16174"/>
	</joint>
	<link name="$(arg ns)r_ankle">
		<inertial>
			<mass value="0.16184"/>
			<inertia ixx="9.77513e-05" ixy="-7.70106e-06" ixz="5.88169e-06" iyy="0.000369108" iyz="-1.55058e-06" izz="0.000418695"/>
			<origin rpy="0 0 0" xyz="0.02542 -0.0033 -0.03239"/>
		</inertial>
		<xacro:insert_visu_r_ankle/>
	</link>
	<joint name="$(arg ns)RLeg_effector_fixedjoint" type="fixed">
		<parent link="$(arg ns)r_ankle"/>
		<child link="$(arg ns)r_sole"/>
		<origin rpy="0 0 0" xyz="0 0 -0.04511"/>
		<axis xyz="0 0 0"/>
	</joint>
	<link name="$(arg ns)r_sole"/>


    <joint name="$(arg ns)base_right_motor_joint" type="fixed">
        <origin xyz="-0.02 0 0" rpy="0 0 0" />        
        <parent link="$(arg ns)r_sole"/>
        <child link="$(arg ns)right_motor" />
    </joint>

    <link name="$(arg ns)right_motor">

	<inertial>
                <origin xyz="0.0 0 0"/>
                <mass value="0.1" />
                <inertia ixx="0.001" ixy="0.0" ixz="0.0"
                         iyy="0.001" iyz="0.0" izz="0.001" />
        </inertial>

        <visual>
            <origin xyz="0 -0.003 0" rpy="1.5707 0 0" />
            <geometry>
                <cylinder radius="0.015" length = "0.078" />
            </geometry>
            <material name="gray">
                <color rgba="0.75 0.75 0.75 1"/>
            </material>
        </visual>

	<collision>
                <origin xyz="0 0 0" rpy="1.5707 0 0" />
                <geometry>
                    <cylinder radius="0.015" length = "0.078"/>
                </geometry>
        </collision>
    </link>

    <joint name="$(arg ns)right_wheel_joint_r" type="continuous">
        <origin xyz="0 -0.0498 0" rpy="0 0 0"/>
        <parent link="$(arg ns)right_motor"/>
        <child link="$(arg ns)right_wheel_link_r"/>
        <axis xyz="0 1 0"/>
    </joint>

    <link name="$(arg ns)right_wheel_link_r">

	<inertial>
                <origin xyz="0 0 0"/>
                <mass value="0.01" />
                <inertia ixx="0.001" ixy="0.0" ixz="0.0"
                         iyy="0.001" iyz="0.0" izz="0.001" />
        </inertial>
        <visual>
            <origin xyz="0 0.003 0" rpy="1.5707 0 0" />
            <geometry>
                <cylinder radius="0.02" length = "0.01"/>
            </geometry>
            <material name="gray">
                <color rgba="1 1 1 0.9"/>
            </material>
        </visual>

	<collision>
                <origin xyz="0 0 0" rpy="1.5707 0 0" />
                <geometry>
                    <cylinder radius="0.02" length = "0.01"/>
                </geometry>
        </collision>
    </link>

    <joint name="$(arg ns)right_wheel_joint_l" type="continuous">
        <origin xyz="0 0.039 0" rpy="0 0 0"/>
        <parent link="$(arg ns)right_motor"/>
        <child link="$(arg ns)right_wheel_link_l"/>
        <axis xyz="0 1 0"/>
    </joint>

    <link name="$(arg ns)right_wheel_link_l">

	<inertial>
                <origin xyz="0 0 0"/>
                <mass value="0.01" />
                <inertia ixx="0.001" ixy="0.0" ixz="0.0"
                         iyy="0.001" iyz="0.0" izz="0.001" />
        </inertial>
        <visual>
            <origin xyz="0 0 0" rpy="1.5707 0 0" />
            <geometry>
                <cylinder radius="0.02" length = "0.01"/>
            </geometry>
            <material name="gray">
                <color rgba="1 1 1 0.9"/>
            </material>
        </visual>

	<collision>
                <origin xyz="0 0 0" rpy="1.5707 0 0" />
                <geometry>
                    <cylinder radius="0.02" length = "0.01"/>
                </geometry>
        </collision>
    </link>

   <joint name="$(arg ns)front_right_motor_joint" type="fixed">
        	<origin xyz="0.06 0 0" rpy="0 0 0" />        
        	<parent link="$(arg ns)r_sole"/>
        	<child link="$(arg ns)front_right_motor" />
    	</joint>

    	<link name="$(arg ns)front_right_motor">
		<inertial>
                	<origin xyz="0.0 0 0"/>
                	<mass value="0.1" />
                	<inertia ixx="0.00001" ixy="0.0" ixz="0.0"
                        	 iyy="0.00001" iyz="0.0" izz="0.00001" />
        	</inertial>
        	<visual>
            		<origin xyz="0 -0.003 0" rpy="1.5707 0 0" />
            		<geometry>
                		<cylinder radius="0.015" length = "0.08"/>
            		</geometry>
            		<material name="gray">
               			 <color rgba="0.75 0.75 0.75 1"/>
            		</material>
        	</visual>

		<collision>
                	<origin xyz="0 0 0" rpy="1.5707 0 0" />
                	<geometry>
                    		<cylinder radius="0.015" length = "0.078"/>
                	</geometry>
        	</collision>
    	</link>

    <joint name="$(arg ns)front_right_wheel_joint_r" type="continuous">
        <origin xyz="0 -0.046 0" rpy="0 0 0"/>
        <parent link="$(arg ns)front_right_motor"/>
        <child link="$(arg ns)front_right_wheel_link_r"/>
        <axis xyz="0 1 0"/>
    </joint>

    <link name="$(arg ns)front_right_wheel_link_r">
	<inertial>
                <origin xyz="0 0 0"/>
                <mass value="0.01" />
                <inertia ixx="0.001" ixy="0.0" ixz="0.0"
                         iyy="0.001" iyz="0.0" izz="0.001" />
        </inertial>
	
        <visual>
            <origin xyz="0 0 0" rpy="1.5707 0 0" />
            <geometry>
                <cylinder radius="0.02" length = "0.01"/>
            </geometry>
            <material name="gray">
                <color rgba="1 1 1 0.9"/>
            </material>
        </visual>

	<collision>
                <origin xyz="0 0 0" rpy="1.5707 0 0" />
                <geometry>
                    <cylinder radius="0.02" length = "0.01"/>
                </geometry>
        </collision>
    </link>

    <joint name="$(arg ns)front_right_wheel_joint_l" type="continuous">
        <origin xyz="0 0.040 0" rpy="0 0 0"/>
        <parent link="$(arg ns)front_right_motor"/>
        <child link="$(arg ns)front_right_wheel_link_l"/>
        <axis xyz="0 1 0"/>
    </joint>

    <link name="$(arg ns)front_right_wheel_link_l">

	<inertial>
                <origin xyz="0 0 0"/>
                <mass value="0.01" />
                <inertia ixx="0.00001" ixy="0.0" ixz="0.0"
                         iyy="0.00001" iyz="0.0" izz="0.00001" />
        </inertial>
        <visual>
            <origin xyz="0 0 0" rpy="1.5707 0 0" />
            <geometry>
                <cylinder radius="0.02" length = "0.01"/>
            </geometry>
            <material name="gray">
                <color rgba="1 1 1 0.9"/>
            </material>
        </visual>

	<collision>
                <origin xyz="0 0 0" rpy="1.5707 0 0" />
                <geometry>
                    <cylinder radius="0.02" length = "0.01"/>
                </geometry>
        </collision>
    </link> 
</robot>
