<?xml version="1.0" ?>
<!--******************************************************************
 ****** File automatically generated by generate_urdf.py script ******
 *********************************************************************-->
<robot xmlns:xacro="http://www.ros.org/wiki/xacro">
	<joint name="$(arg ns)HeadYaw" type="revolute">
		<parent link="$(arg ns)torso"/>
		<child link="$(arg ns)Neck"/>
		<origin rpy="0 0 0" xyz="0 0 0.1265"/>
		<axis xyz="0 0 1.0"/>
		<limit effort="1.547" lower="-2.08567" upper="2.08567" velocity="8.26797"/>
	</joint>
	<link name="$(arg ns)Neck">
		<inertial>
			<mass value="0.06442"/>
			<inertia ixx="2.65584e-05" ixy="1.57e-09" ixz="0" iyy="2.75654e-05" iyz="-5.295e-08" izz="5.53372e-06"/>
			<origin rpy="0 0 0" xyz="-1e-05 0 -0.02742"/>
		</inertial>
		<xacro:insert_visu_Neck/>
	</link>
	<joint name="$(arg ns)HeadPitch" type="revolute">
		<parent link="$(arg ns)Neck"/>
		<child link="$(arg ns)Head"/>
		<origin rpy="0 0 0" xyz="0 0 0"/>
		<axis xyz="0 1.0 0"/>
		<limit effort="1.532" lower="-0.671952" upper="0.514872" velocity="7.19407"/>
	</joint>
	<link name="$(arg ns)Head">
		<inertial>
			<mass value="0.60533"/>
			<inertia ixx="0.000957766" ixy="8.78814e-06" ixz="5.33702e-06" iyy="0.000816836" iyz="-2.99579e-05" izz="0.000984976"/>
			<origin rpy="0 0 0" xyz="-0.00112 0 0.05258"/>
		</inertial>
		<xacro:insert_visu_Head/>
	</link>
	<joint name="$(arg ns)gaze_joint" type="fixed">
		<parent link="$(arg ns)Head"/>
		<child link="$(arg ns)gaze"/>
		<origin rpy="0 0 0" xyz="0.05871 0 0.06364"/>
	</joint>
	<link name="$(arg ns)gaze"/>
</robot>
