<?xml version="1.0" encoding="utf-8"?>
<!-- =================================================================================== -->
<!-- |    This document was autogenerated by xacro from nao_robot.xacro                | -->
<!-- |    EDITING THIS FILE BY HAND IS NOT RECOMMENDED                                 | -->
<!-- =================================================================================== -->
<!--******************************************************************
 ****** File automatically generated by generate_urdf.py script ******
 *********************************************************************-->
<robot name="nao">
  <joint name="nao_1/HeadYaw" type="revolute">
    <parent link="nao_1/torso"/>
    <child link="nao_1/Neck"/>
    <origin rpy="0 0 0" xyz="0 0 0.1265"/>
    <axis xyz="0 0 1.0"/>
    <limit effort="1.547" lower="-2.08567" upper="2.08567" velocity="8.26797"/>
  </joint>
  <link name="nao_1/Neck">
    <inertial>
      <mass value="0.06442"/>
      <inertia ixx="2.65584e-05" ixy="1.57e-09" ixz="0" iyy="2.75654e-05" iyz="-5.295e-08" izz="5.53372e-06"/>
      <origin rpy="0 0 0" xyz="-1e-05 0 -0.02742"/>
    </inertial>
    <visual>
      <geometry>
        <mesh filename="package://nao_description/nao_meshes/meshes/V40/HeadYaw.dae" scale="0.1 0.1 0.1"/>
      </geometry>
      <origin rpy="0 0 0" xyz="0 0 0"/>
    </visual>
    <collision>
      <geometry>
        <mesh filename="package://nao_description/nao_meshes/meshes/V40/HeadYaw_0.10.stl" scale="0.1 0.1 0.1"/>
      </geometry>
      <origin rpy="0 0 0" xyz="0 0 0"/>
    </collision>
  </link>
  <joint name="nao_1/HeadPitch" type="revolute">
    <parent link="nao_1/Neck"/>
    <child link="nao_1/Head"/>
    <origin rpy="0 0 0" xyz="0 0 0"/>
    <axis xyz="0 1.0 0"/>
    <limit effort="1.532" lower="-0.671952" upper="0.514872" velocity="7.19407"/>
  </joint>
  <link name="nao_1/Head">
    <inertial>
      <mass value="0.60533"/>
      <inertia ixx="0.000957766" ixy="8.78814e-06" ixz="5.33702e-06" iyy="0.000816836" iyz="-2.99579e-05" izz="0.000984976"/>
      <origin rpy="0 0 0" xyz="-0.00112 0 0.05258"/>
    </inertial>
    <visual>
      <geometry>
        <mesh filename="package://nao_description/nao_meshes/meshes/V40/HeadPitch.dae" scale="0.1 0.1 0.1"/>
      </geometry>
      <origin rpy="0 0 0" xyz="0 0 0"/>
    </visual>
    <collision>
      <geometry>
        <mesh filename="package://nao_description/nao_meshes/meshes/V40/HeadPitch_0.10.stl" scale="0.1 0.1 0.1"/>
      </geometry>
      <origin rpy="0 0 0" xyz="0 0 0"/>
    </collision>
  </link>
  <joint name="nao_1/gaze_joint" type="fixed">
    <parent link="nao_1/Head"/>
    <child link="nao_1/gaze"/>
    <origin rpy="0 0 0" xyz="0.05871 0 0.06364"/>
  </joint>
  <link name="nao_1/gaze"/>
  <joint name="nao_1/LHipYawPitch" type="revolute">
    <parent link="nao_1/torso"/>
    <child link="nao_1/LPelvis"/>
    <origin rpy="0 0 0" xyz="0 0.05 -0.085"/>
    <axis xyz="0 0.707106 -0.707106"/>
    <limit effort="3.348" lower="-1.14529" upper="0.740718" velocity="4.16174"/>
  </joint>
  <link name="nao_1/LPelvis">
    <inertial>
      <mass value="0.06981"/>
      <inertia ixx="2.3407e-05" ixy="1.07922e-06" ixz="-1.76003e-06" iyy="4.76355e-05" iyz="2.76058e-06" izz="4.97021e-05"/>
      <origin rpy="0 0 0" xyz="-0.00781 -0.01114 0.02661"/>
    </inertial>
    <visual>
      <geometry>
        <mesh filename="package://nao_description/nao_meshes/meshes/V40/LHipYawPitch.dae" scale="0.1 0.1 0.1"/>
      </geometry>
      <origin rpy="0 0 0" xyz="0 0 0"/>
    </visual>
    <collision>
      <geometry>
        <mesh filename="package://nao_description/nao_meshes/meshes/V40/LHipYawPitch_0.10.stl" scale="0.1 0.1 0.1"/>
      </geometry>
      <origin rpy="0 0 0" xyz="0 0 0"/>
    </collision>
  </link>
  <joint name="nao_1/LHipRoll" type="revolute">
    <parent link="nao_1/LPelvis"/>
    <child link="nao_1/LHip"/>
    <origin rpy="0 0 0" xyz="0 0 0"/>
    <axis xyz="1.0 0 0"/>
    <limit effort="3.348" lower="-0.379435" upper="0.79046" velocity="4.16174"/>
  </joint>
  <link name="nao_1/LHip">
    <inertial>
      <mass value="0.13053"/>
      <inertia ixx="2.41106e-05" ixy="-6.08684e-07" ixz="6.33119e-06" iyy="6.34892e-05" iyz="-1.99137e-07" izz="5.67694e-05"/>
      <origin rpy="0 0 0" xyz="-0.01549 0.00029 -0.00515"/>
    </inertial>
    <visual>
      <geometry>
        <mesh filename="package://nao_description/nao_meshes/meshes/V40/LHipRoll.dae" scale="0.1 0.1 0.1"/>
      </geometry>
      <origin rpy="0 0 0" xyz="0 0 0"/>
    </visual>
    <collision>
      <geometry>
        <mesh filename="package://nao_description/nao_meshes/meshes/V40/LHipRoll_0.10.stl" scale="0.1 0.1 0.1"/>
      </geometry>
      <origin rpy="0 0 0" xyz="0 0 0"/>
    </collision>
  </link>
  <joint name="nao_1/LHipPitch" type="revolute">
    <parent link="nao_1/LHip"/>
    <child link="nao_1/LThigh"/>
    <origin rpy="0 0 0" xyz="0 0 0"/>
    <axis xyz="0 1.0 0"/>
    <limit effort="3.023" lower="-1.53589" upper="0.48398" velocity="6.40239"/>
  </joint>
  <link name="nao_1/LThigh">
    <inertial>
      <mass value="0.38968"/>
      <inertia ixx="0.000509844" ixy="2.11296e-06" ixz="5.64129e-05" iyy="0.000465358" iyz="-7.91029e-06" izz="0.000301098"/>
      <origin rpy="0 0 0" xyz="0.00138 0.00221 -0.05373"/>
    </inertial>
    <visual>
      <geometry>
        <mesh filename="package://nao_description/nao_meshes/meshes/V40/LHipPitch.dae" scale="0.1 0.1 0.1"/>
      </geometry>
      <origin rpy="0 0 0" xyz="0 0 0"/>
    </visual>
    <collision>
      <geometry>
        <mesh filename="package://nao_description/nao_meshes/meshes/V40/LHipPitch_0.10.stl" scale="0.1 0.1 0.1"/>
      </geometry>
      <origin rpy="0 0 0" xyz="0 0 0"/>
    </collision>
  </link>
  <joint name="nao_1/LKneePitch" type="revolute">
    <parent link="nao_1/LThigh"/>
    <child link="nao_1/LTibia"/>
    <origin rpy="0 0 0" xyz="0 0 -0.1"/>
    <axis xyz="0 1.0 0"/>
    <limit effort="3.023" lower="-0.0923279" upper="2.11255" velocity="6.40239"/>
  </joint>
  <link name="nao_1/LTibia">
    <inertial>
      <mass value="0.29142"/>
      <inertia ixx="0.000470586" ixy="3.60392e-06" ixz="-2.86648e-05" iyy="0.000412654" iyz="7.13013e-06" izz="0.000185772"/>
      <origin rpy="0 0 0" xyz="0.00453 0.00225 -0.04936"/>
    </inertial>
    <visual>
      <geometry>
        <mesh filename="package://nao_description/nao_meshes/meshes/V40/LKneePitch.dae" scale="0.1 0.1 0.1"/>
      </geometry>
      <origin rpy="0 0 0" xyz="0 0 0"/>
    </visual>
    <collision>
      <geometry>
        <mesh filename="package://nao_description/nao_meshes/meshes/V40/LKneePitch_0.10.stl" scale="0.1 0.1 0.1"/>
      </geometry>
      <origin rpy="0 0 0" xyz="0 0 0"/>
    </collision>
  </link>
  <joint name="nao_1/LAnklePitch" type="revolute">
    <parent link="nao_1/LTibia"/>
    <child link="nao_1/LAnklePitch"/>
    <origin rpy="0 0 0" xyz="0 0 -0.1029"/>
    <axis xyz="0 1.0 0"/>
    <limit effort="3.023" lower="-1.18944" upper="0.922581" velocity="6.40239"/>
  </joint>
  <link name="nao_1/LAnklePitch">
    <inertial>
      <mass value="0.13416"/>
      <inertia ixx="3.22034e-05" ixy="-8.83212e-09" ixz="4.27549e-06" iyy="6.7943e-05" iyz="2.84849e-07" izz="5.48269e-05"/>
      <origin rpy="0 0 0" xyz="0.00045 0.00029 0.00685"/>
    </inertial>
    <visual>
      <geometry>
        <mesh filename="package://nao_description/nao_meshes/meshes/V40/LAnklePitch.dae" scale="0.1 0.1 0.1"/>
      </geometry>
      <origin rpy="0 0 0" xyz="0 0 0"/>
    </visual>
    <collision>
      <geometry>
        <mesh filename="package://nao_description/nao_meshes/meshes/V40/LAnklePitch_0.10.stl" scale="0.1 0.1 0.1"/>
      </geometry>
      <origin rpy="0 0 0" xyz="0 0 0"/>
    </collision>
  </link>
  <joint name="nao_1/LAnkleRoll" type="revolute">
    <parent link="nao_1/LAnklePitch"/>
    <child link="nao_1/l_ankle"/>
    <origin rpy="0 0 0" xyz="0 0 0"/>
    <axis xyz="1.0 0 0"/>
    <limit effort="3.348" lower="-0.397761" upper="0.768992" velocity="4.16174"/>
  </joint>
  <link name="nao_1/l_ankle">
    <inertial>
      <mass value="0.16184"/>
      <inertia ixx="9.78911e-05" ixy="7.88039e-06" ixz="6.1279e-06" iyy="0.000369977" iyz="1.44233e-06" izz="0.000419417"/>
      <origin rpy="0 0 0" xyz="0.02542 0.0033 -0.03239"/>
    </inertial>
    <visual>
      <geometry>
        <mesh filename="package://nao_description/nao_meshes/meshes/V40/LAnkleRoll.dae" scale="0.1 0.1 0.1"/>
      </geometry>
      <origin rpy="0 0 0" xyz="0 0 0"/>
    </visual>
    <collision>
      <geometry>
        <mesh filename="package://nao_description/nao_meshes/meshes/V40/LAnkleRoll_0.10.stl" scale="0.1 0.1 0.1"/>
      </geometry>
      <origin rpy="0 0 0" xyz="0 0 0"/>
    </collision>
  </link>
  <joint name="nao_1/LLeg_effector_fixedjoint" type="fixed">
    <parent link="nao_1/l_ankle"/>
    <child link="nao_1/l_sole"/>
    <origin rpy="0 0 0" xyz="0 0 -0.04511"/>
    <axis xyz="0 0 0"/>
  </joint>
  <link name="nao_1/l_sole"/>
  <joint name="nao_1/base_left_motor_joint" type="fixed">
    <origin rpy="0 0 0" xyz="-0.02 0 0"/>
    <parent link="nao_1/l_sole"/>
    <child link="nao_1/left_motor"/>
  </joint>
  <link name="nao_1/left_motor">
    <inertial>
      <origin xyz="0.0 0 0"/>
      <mass value="0.1"/>
      <inertia ixx="0.001" ixy="0.0" ixz="0.0" iyy="0.001" iyz="0.0" izz="0.001"/>
    </inertial>
    <visual>
      <origin rpy="1.5707 0 0" xyz="0 0.005 0"/>
      <geometry>
        <cylinder length="0.078" radius="0.015"/>
      </geometry>
      <material name="gray">
        <color rgba="0.75 0.75 0.75 1"/>
      </material>
    </visual>
    <collision>
      <origin rpy="1.5707 0 0" xyz="0 0 0"/>
      <geometry>
        <cylinder length="0.078" radius="0.015"/>
      </geometry>
    </collision>
  </link>
  <joint name="nao_1/left_wheel_joint_r" type="continuous">
    <origin rpy="0 0 0" xyz="0 -0.039 0"/>
    <parent link="nao_1/left_motor"/>
    <child link="nao_1/left_wheel_link_r"/>
    <axis xyz="0 1 0"/>
  </joint>
  <link name="nao_1/left_wheel_link_r">
    <inertial>
      <origin xyz="0 0 0"/>
      <mass value="0.01"/>
      <inertia ixx="0.001" ixy="0.0" ixz="0.0" iyy="0.001" iyz="0.0" izz="0.001"/>
    </inertial>
    <visual>
      <origin rpy="1.5707 0 0" xyz="0 0 0"/>
      <geometry>
        <cylinder length="0.01" radius="0.02"/>
      </geometry>
      <material name="gray">
        <color rgba="1 1 1 0.9"/>
      </material>
    </visual>
    <collision>
      <origin rpy="1.5707 0 0" xyz="0 0 0"/>
      <geometry>
        <cylinder length="0.01" radius="0.02"/>
      </geometry>
    </collision>
  </link>
  <joint name="nao_1/left_wheel_joint_l" type="continuous">
    <origin rpy="0 0 0" xyz="0 0.047 0"/>
    <parent link="nao_1/left_motor"/>
    <child link="nao_1/left_wheel_link_l"/>
    <axis xyz="0 1 0"/>
  </joint>
  <link name="nao_1/left_wheel_link_l">
    <inertial>
      <origin xyz="0 0 0"/>
      <mass value="0.01"/>
      <inertia ixx="0.001" ixy="0.0" ixz="0.0" iyy="0.001" iyz="0.0" izz="0.001"/>
    </inertial>
    <visual>
      <origin rpy="1.5707 0 0" xyz="0 0 0"/>
      <geometry>
        <cylinder length="0.01" radius="0.02"/>
      </geometry>
      <material name="gray">
        <color rgba="1 1 1 0.9"/>
      </material>
    </visual>
    <collision>
      <origin rpy="1.5707 0 0" xyz="0 0 0"/>
      <geometry>
        <cylinder length="0.01" radius="0.02"/>
      </geometry>
    </collision>
  </link>
  <joint name="nao_1/front_left_motor_joint" type="fixed">
    <origin rpy="0 0 0" xyz="0.06 0 0"/>
    <parent link="nao_1/l_sole"/>
    <child link="nao_1/front_left_motor"/>
  </joint>
  <link name="nao_1/front_left_motor">
    <inertial>
      <origin xyz="0.0 0 0"/>
      <mass value="0.1"/>
      <inertia ixx="0.00001" ixy="0.0" ixz="0.0" iyy="0.00001" iyz="0.0" izz="0.00001"/>
    </inertial>
    <visual>
      <origin rpy="1.5707 0 0" xyz="0 0.003 0"/>
      <geometry>
        <cylinder length="0.08" radius="0.015"/>
      </geometry>
      <material name="gray">
        <color rgba="0.75 0.75 0.75 1"/>
      </material>
    </visual>
    <collision>
      <origin rpy="1.5707 0 0" xyz="0 0 0"/>
      <geometry>
        <cylinder length="0.078" radius="0.015"/>
      </geometry>
    </collision>
  </link>
  <joint name="nao_1/front_left_wheel_joint_r" type="continuous">
    <origin rpy="0 0 0" xyz="0 -0.039 0"/>
    <parent link="nao_1/front_left_motor"/>
    <child link="nao_1/front_left_wheel_link_r"/>
    <axis xyz="0 1 0"/>
  </joint>
  <link name="nao_1/front_left_wheel_link_r">
    <inertial>
      <origin xyz="0 0 0"/>
      <mass value="0.01"/>
      <inertia ixx="0.001" ixy="0.0" ixz="0.0" iyy="0.001" iyz="0.0" izz="0.001"/>
    </inertial>
    <visual>
      <origin rpy="1.5707 0 0" xyz="0 0 0"/>
      <geometry>
        <cylinder length="0.01" radius="0.02"/>
      </geometry>
      <material name="gray">
        <color rgba="1 1 1 0.9"/>
      </material>
    </visual>
    <collision>
      <origin rpy="1.5707 0 0" xyz="0 0 0"/>
      <geometry>
        <cylinder length="0.01" radius="0.02"/>
      </geometry>
    </collision>
  </link>
  <joint name="nao_1/front_left_wheel_joint_l" type="continuous">
    <origin rpy="0 0 0" xyz="0 0.045 0"/>
    <parent link="nao_1/front_left_motor"/>
    <child link="nao_1/front_left_wheel_link_l"/>
    <axis xyz="0 1 0"/>
  </joint>
  <link name="nao_1/front_left_wheel_link_l">
    <inertial>
      <origin xyz="0 0 0"/>
      <mass value="0.01"/>
      <inertia ixx="0.00001" ixy="0.0" ixz="0.0" iyy="0.00001" iyz="0.0" izz="0.00001"/>
    </inertial>
    <visual>
      <origin rpy="1.5707 0 0" xyz="0 0 0"/>
      <geometry>
        <cylinder length="0.01" radius="0.02"/>
      </geometry>
      <material name="gray">
        <color rgba="1 1 1 0.9"/>
      </material>
    </visual>
    <collision>
      <origin rpy="1.5707 0 0" xyz="0 0 0"/>
      <geometry>
        <cylinder length="0.01" radius="0.02"/>
      </geometry>
    </collision>
  </link>
  <joint name="nao_1/RHipYawPitch" type="revolute">
    <parent link="nao_1/torso"/>
    <child link="nao_1/RPelvis"/>
    <origin rpy="0 0 0" xyz="0 -0.05 -0.085"/>
    <axis xyz="0 0.707106 0.707106"/>
    <limit effort="3.348" lower="-1.14529" upper="0.740718" velocity="4.16174"/>
    <mimic joint="nao_1/LHipYawPitch" multiplier="1.0" offset="0"/>
  </joint>
  <link name="nao_1/RPelvis">
    <inertial>
      <mass value="0.06981"/>
      <inertia ixx="3.18766e-05" ixy="-1.07152e-06" ixz="-1.77295e-06" iyy="5.18361e-05" iyz="-7.00664e-06" izz="5.39657e-05"/>
      <origin rpy="0 0 0" xyz="-0.00781 0.01114 0.02661"/>
    </inertial>
    <visual>
      <geometry>
        <mesh filename="package://nao_description/nao_meshes/meshes/V40/RHipYawPitch.dae" scale="0.1 0.1 0.1"/>
      </geometry>
      <origin rpy="0 0 0" xyz="0 0 0"/>
    </visual>
    <collision>
      <geometry>
        <mesh filename="package://nao_description/nao_meshes/meshes/V40/RHipYawPitch_0.10.stl" scale="0.1 0.1 0.1"/>
      </geometry>
      <origin rpy="0 0 0" xyz="0 0 0"/>
    </collision>
  </link>
  <joint name="nao_1/RHipRoll" type="revolute">
    <parent link="nao_1/RPelvis"/>
    <child link="nao_1/RHip"/>
    <origin rpy="0 0 0" xyz="0 0 0"/>
    <axis xyz="1.0 0 0"/>
    <limit effort="3.348" lower="-0.79046" upper="0.379435" velocity="4.16174"/>
  </joint>
  <link name="nao_1/RHip">
    <inertial>
      <mass value="0.13053"/>
      <inertia ixx="2.41136e-05" ixy="5.67164e-07" ixz="6.30461e-06" iyy="6.34886e-05" iyz="1.97457e-07" izz="5.6773e-05"/>
      <origin rpy="0 0 0" xyz="-0.01549 -0.00029 -0.00515"/>
    </inertial>
    <visual>
      <geometry>
        <mesh filename="package://nao_description/nao_meshes/meshes/V40/RHipRoll.dae" scale="0.1 0.1 0.1"/>
      </geometry>
      <origin rpy="0 0 0" xyz="0 0 0"/>
    </visual>
    <collision>
      <geometry>
        <mesh filename="package://nao_description/nao_meshes/meshes/V40/RHipRoll_0.10.stl" scale="0.1 0.1 0.1"/>
      </geometry>
      <origin rpy="0 0 0" xyz="0 0 0"/>
    </collision>
  </link>
  <joint name="nao_1/RHipPitch" type="revolute">
    <parent link="nao_1/RHip"/>
    <child link="nao_1/RThigh"/>
    <origin rpy="0 0 0" xyz="0 0 0"/>
    <axis xyz="0 1.0 0"/>
    <limit effort="3.0226" lower="-1.53589" upper="0.48398" velocity="6.40239"/>
  </joint>
  <link name="nao_1/RThigh">
    <inertial>
      <mass value="0.38968"/>
      <inertia ixx="0.000510607" ixy="-2.02799e-06" ixz="5.69893e-05" iyy="0.0004665" iyz="7.09563e-06" izz="0.000301333"/>
      <origin rpy="0 0 0" xyz="0.00138 -0.00221 -0.05373"/>
    </inertial>
    <visual>
      <geometry>
        <mesh filename="package://nao_description/nao_meshes/meshes/V40/RHipPitch.dae" scale="0.1 0.1 0.1"/>
      </geometry>
      <origin rpy="0 0 0" xyz="0 0 0"/>
    </visual>
    <collision>
      <geometry>
        <mesh filename="package://nao_description/nao_meshes/meshes/V40/RHipPitch_0.10.stl" scale="0.1 0.1 0.1"/>
      </geometry>
      <origin rpy="0 0 0" xyz="0 0 0"/>
    </collision>
  </link>
  <joint name="nao_1/RKneePitch" type="revolute">
    <parent link="nao_1/RThigh"/>
    <child link="nao_1/RTibia"/>
    <origin rpy="0 0 0" xyz="0 0 -0.1"/>
    <axis xyz="0 1.0 0"/>
    <limit effort="3.0226" lower="-0.0923279" upper="2.11255" velocity="6.40239"/>
  </joint>
  <link name="nao_1/RTibia">
    <inertial>
      <mass value="0.29142"/>
      <inertia ixx="0.000471336" ixy="-3.8668e-06" ixz="-3.71648e-05" iyy="0.00041228" iyz="-6.11093e-06" izz="0.000183997"/>
      <origin rpy="0 0 0" xyz="0.00453 -0.00225 -0.04936"/>
    </inertial>
    <visual>
      <geometry>
        <mesh filename="package://nao_description/nao_meshes/meshes/V40/RKneePitch.dae" scale="0.1 0.1 0.1"/>
      </geometry>
      <origin rpy="0 0 0" xyz="0 0 0"/>
    </visual>
    <collision>
      <geometry>
        <mesh filename="package://nao_description/nao_meshes/meshes/V40/RKneePitch_0.10.stl" scale="0.1 0.1 0.1"/>
      </geometry>
      <origin rpy="0 0 0" xyz="0 0 0"/>
    </collision>
  </link>
  <joint name="nao_1/RAnklePitch" type="revolute">
    <parent link="nao_1/RTibia"/>
    <child link="nao_1/RAnklePitch"/>
    <origin rpy="0 0 0" xyz="0 0 -0.1029"/>
    <axis xyz="0 1.0 0"/>
    <limit effort="3.0226" lower="-1.1863" upper="0.932006" velocity="6.40239"/>
  </joint>
  <link name="nao_1/RAnklePitch">
    <inertial>
      <mass value="0.13416"/>
      <inertia ixx="3.22017e-05" ixy="4.68321e-08" ixz="4.28821e-06" iyy="6.79885e-05" iyz="-2.71089e-07" izz="5.48747e-05"/>
      <origin rpy="0 0 0" xyz="0.00045 -0.00029 0.00685"/>
    </inertial>
    <visual>
      <geometry>
        <mesh filename="package://nao_description/nao_meshes/meshes/V40/RAnklePitch.dae" scale="0.1 0.1 0.1"/>
      </geometry>
      <origin rpy="0 0 0" xyz="0 0 0"/>
    </visual>
    <collision>
      <geometry>
        <mesh filename="package://nao_description/nao_meshes/meshes/V40/RAnklePitch_0.10.stl" scale="0.1 0.1 0.1"/>
      </geometry>
      <origin rpy="0 0 0" xyz="0 0 0"/>
    </collision>
  </link>
  <joint name="nao_1/RAnkleRoll" type="revolute">
    <parent link="nao_1/RAnklePitch"/>
    <child link="nao_1/r_ankle"/>
    <origin rpy="0 0 0" xyz="0 0 0"/>
    <axis xyz="1.0 0 0"/>
    <limit effort="3.348" lower="-0.768992" upper="0.397761" velocity="4.16174"/>
  </joint>
  <link name="nao_1/r_ankle">
    <inertial>
      <mass value="0.16184"/>
      <inertia ixx="9.77513e-05" ixy="-7.70106e-06" ixz="5.88169e-06" iyy="0.000369108" iyz="-1.55058e-06" izz="0.000418695"/>
      <origin rpy="0 0 0" xyz="0.02542 -0.0033 -0.03239"/>
    </inertial>
    <visual>
      <geometry>
        <mesh filename="package://nao_description/nao_meshes/meshes/V40/RAnkleRoll.dae" scale="0.1 0.1 0.1"/>
      </geometry>
      <origin rpy="0 0 0" xyz="0 0 0"/>
    </visual>
    <collision>
      <geometry>
        <mesh filename="package://nao_description/nao_meshes/meshes/V40/RAnkleRoll_0.10.stl" scale="0.1 0.1 0.1"/>
      </geometry>
      <origin rpy="0 0 0" xyz="0 0 0"/>
    </collision>
  </link>
  <joint name="nao_1/RLeg_effector_fixedjoint" type="fixed">
    <parent link="nao_1/r_ankle"/>
    <child link="nao_1/r_sole"/>
    <origin rpy="0 0 0" xyz="0 0 -0.04511"/>
    <axis xyz="0 0 0"/>
  </joint>
  <link name="nao_1/r_sole"/>
  <joint name="nao_1/base_right_motor_joint" type="fixed">
    <origin rpy="0 0 0" xyz="-0.02 0 0"/>
    <parent link="nao_1/r_sole"/>
    <child link="nao_1/right_motor"/>
  </joint>
  <link name="nao_1/right_motor">
    <inertial>
      <origin xyz="0.0 0 0"/>
      <mass value="0.1"/>
      <inertia ixx="0.001" ixy="0.0" ixz="0.0" iyy="0.001" iyz="0.0" izz="0.001"/>
    </inertial>
    <visual>
      <origin rpy="1.5707 0 0" xyz="0 -0.003 0"/>
      <geometry>
        <cylinder length="0.078" radius="0.015"/>
      </geometry>
      <material name="gray">
        <color rgba="0.75 0.75 0.75 1"/>
      </material>
    </visual>
    <collision>
      <origin rpy="1.5707 0 0" xyz="0 0 0"/>
      <geometry>
        <cylinder length="0.078" radius="0.015"/>
      </geometry>
    </collision>
  </link>
  <joint name="nao_1/right_wheel_joint_r" type="continuous">
    <origin rpy="0 0 0" xyz="0 -0.0498 0"/>
    <parent link="nao_1/right_motor"/>
    <child link="nao_1/right_wheel_link_r"/>
    <axis xyz="0 1 0"/>
  </joint>
  <link name="nao_1/right_wheel_link_r">
    <inertial>
      <origin xyz="0 0 0"/>
      <mass value="0.01"/>
      <inertia ixx="0.001" ixy="0.0" ixz="0.0" iyy="0.001" iyz="0.0" izz="0.001"/>
    </inertial>
    <visual>
      <origin rpy="1.5707 0 0" xyz="0 0.003 0"/>
      <geometry>
        <cylinder length="0.01" radius="0.02"/>
      </geometry>
      <material name="gray">
        <color rgba="1 1 1 0.9"/>
      </material>
    </visual>
    <collision>
      <origin rpy="1.5707 0 0" xyz="0 0 0"/>
      <geometry>
        <cylinder length="0.01" radius="0.02"/>
      </geometry>
    </collision>
  </link>
  <joint name="nao_1/right_wheel_joint_l" type="continuous">
    <origin rpy="0 0 0" xyz="0 0.039 0"/>
    <parent link="nao_1/right_motor"/>
    <child link="nao_1/right_wheel_link_l"/>
    <axis xyz="0 1 0"/>
  </joint>
  <link name="nao_1/right_wheel_link_l">
    <inertial>
      <origin xyz="0 0 0"/>
      <mass value="0.01"/>
      <inertia ixx="0.001" ixy="0.0" ixz="0.0" iyy="0.001" iyz="0.0" izz="0.001"/>
    </inertial>
    <visual>
      <origin rpy="1.5707 0 0" xyz="0 0 0"/>
      <geometry>
        <cylinder length="0.01" radius="0.02"/>
      </geometry>
      <material name="gray">
        <color rgba="1 1 1 0.9"/>
      </material>
    </visual>
    <collision>
      <origin rpy="1.5707 0 0" xyz="0 0 0"/>
      <geometry>
        <cylinder length="0.01" radius="0.02"/>
      </geometry>
    </collision>
  </link>
  <joint name="nao_1/front_right_motor_joint" type="fixed">
    <origin rpy="0 0 0" xyz="0.06 0 0"/>
    <parent link="nao_1/r_sole"/>
    <child link="nao_1/front_right_motor"/>
  </joint>
  <link name="nao_1/front_right_motor">
    <inertial>
      <origin xyz="0.0 0 0"/>
      <mass value="0.1"/>
      <inertia ixx="0.00001" ixy="0.0" ixz="0.0" iyy="0.00001" iyz="0.0" izz="0.00001"/>
    </inertial>
    <visual>
      <origin rpy="1.5707 0 0" xyz="0 -0.003 0"/>
      <geometry>
        <cylinder length="0.08" radius="0.015"/>
      </geometry>
      <material name="gray">
        <color rgba="0.75 0.75 0.75 1"/>
      </material>
    </visual>
    <collision>
      <origin rpy="1.5707 0 0" xyz="0 0 0"/>
      <geometry>
        <cylinder length="0.078" radius="0.015"/>
      </geometry>
    </collision>
  </link>
  <joint name="nao_1/front_right_wheel_joint_r" type="continuous">
    <origin rpy="0 0 0" xyz="0 -0.046 0"/>
    <parent link="nao_1/front_right_motor"/>
    <child link="nao_1/front_right_wheel_link_r"/>
    <axis xyz="0 1 0"/>
  </joint>
  <link name="nao_1/front_right_wheel_link_r">
    <inertial>
      <origin xyz="0 0 0"/>
      <mass value="0.01"/>
      <inertia ixx="0.001" ixy="0.0" ixz="0.0" iyy="0.001" iyz="0.0" izz="0.001"/>
    </inertial>
    <visual>
      <origin rpy="1.5707 0 0" xyz="0 0 0"/>
      <geometry>
        <cylinder length="0.01" radius="0.02"/>
      </geometry>
      <material name="gray">
        <color rgba="1 1 1 0.9"/>
      </material>
    </visual>
    <collision>
      <origin rpy="1.5707 0 0" xyz="0 0 0"/>
      <geometry>
        <cylinder length="0.01" radius="0.02"/>
      </geometry>
    </collision>
  </link>
  <joint name="nao_1/front_right_wheel_joint_l" type="continuous">
    <origin rpy="0 0 0" xyz="0 0.040 0"/>
    <parent link="nao_1/front_right_motor"/>
    <child link="nao_1/front_right_wheel_link_l"/>
    <axis xyz="0 1 0"/>
  </joint>
  <link name="nao_1/front_right_wheel_link_l">
    <inertial>
      <origin xyz="0 0 0"/>
      <mass value="0.01"/>
      <inertia ixx="0.00001" ixy="0.0" ixz="0.0" iyy="0.00001" iyz="0.0" izz="0.00001"/>
    </inertial>
    <visual>
      <origin rpy="1.5707 0 0" xyz="0 0 0"/>
      <geometry>
        <cylinder length="0.01" radius="0.02"/>
      </geometry>
      <material name="gray">
        <color rgba="1 1 1 0.9"/>
      </material>
    </visual>
    <collision>
      <origin rpy="1.5707 0 0" xyz="0 0 0"/>
      <geometry>
        <cylinder length="0.01" radius="0.02"/>
      </geometry>
    </collision>
  </link>
  <link name="nao_1/base_link"/>
  <joint name="nao_1/base_link_fixedjoint" type="fixed">
    <parent link="nao_1/base_link"/>
    <child link="nao_1/torso"/>
    <origin rpy="0 0 0" xyz="0 0 0"/>
    <axis xyz="0 0 0"/>
  </joint>
  <link name="nao_1/torso">
    <inertial>
      <mass value="1.04956"/>
      <inertia ixx="0.00308361" ixy="1.43116e-05" ixz="-3.30211e-05" iyy="0.0028835" iyz="-2.70793e-05" izz="0.0015924"/>
      <origin rpy="0 0 0" xyz="-0.00413 0 0.04342"/>
    </inertial>
    <visual>
      <geometry>
        <mesh filename="package://nao_description/nao_meshes/meshes/V40/Torso.dae" scale="0.1 0.1 0.1"/>
      </geometry>
      <origin rpy="0 0 0" xyz="0 0 0"/>
    </visual>
    <collision>
      <geometry>
        <mesh filename="package://nao_description/nao_meshes/meshes/V40/Torso_0.10.stl" scale="0.1 0.1 0.1"/>
      </geometry>
      <origin rpy="0 0 0" xyz="0 0 0"/>
    </collision>
  </link>
  <joint name="nao_1/LShoulderPitch" type="revolute">
    <parent link="nao_1/torso"/>
    <child link="nao_1/LShoulder"/>
    <origin rpy="0 0 0" xyz="0 0.098 0.1"/>
    <axis xyz="0 1.0 0"/>
    <limit effort="1.329" lower="-2.08567" upper="2.08567" velocity="8.26797"/>
  </joint>
  <link name="nao_1/LShoulder">
    <inertial>
      <mass value="0.07504"/>
      <inertia ixx="3.10677e-05" ixy="1.2692e-06" ixz="6.04576e-09" iyy="1.39498e-05" iyz="-2.99484e-07" izz="3.30001e-05"/>
      <origin rpy="0 0 0" xyz="-0.00165 -0.02663 0.00014"/>
    </inertial>
    <visual>
      <geometry>
        <mesh filename="package://nao_description/nao_meshes/meshes/V40/LShoulderPitch.dae" scale="0.1 0.1 0.1"/>
      </geometry>
      <origin rpy="0 0 0" xyz="0 0 0"/>
    </visual>
    <collision>
      <geometry>
        <mesh filename="package://nao_description/nao_meshes/meshes/V40/LShoulderPitch_0.10.stl" scale="0.1 0.1 0.1"/>
      </geometry>
      <origin rpy="0 0 0" xyz="0 0 0"/>
    </collision>
  </link>
  <joint name="nao_1/LShoulderRoll" type="revolute">
    <parent link="nao_1/LShoulder"/>
    <child link="nao_1/LBicep"/>
    <origin rpy="0 0 0" xyz="0 0 0"/>
    <axis xyz="0 0 1.0"/>
    <limit effort="1.7835" lower="-0.314159" upper="1.32645" velocity="7.19407"/>
  </joint>
  <link name="nao_1/LBicep">
    <inertial>
      <mass value="0.15777"/>
      <inertia ixx="8.7181e-05" ixy="-2.53381e-05" ixz="-1.4213e-05" iyy="0.000274712" iyz="4.71439e-07" izz="0.000241812"/>
      <origin rpy="0 0 0" xyz="0.02455 0.00563 0.0033"/>
    </inertial>
    <visual>
      <geometry>
        <mesh filename="package://nao_description/nao_meshes/meshes/V40/LShoulderRoll.dae" scale="0.1 0.1 0.1"/>
      </geometry>
      <origin rpy="0 0 0" xyz="0 0 0"/>
    </visual>
    <collision>
      <geometry>
        <mesh filename="package://nao_description/nao_meshes/meshes/V40/LShoulderRoll_0.10.stl" scale="0.1 0.1 0.1"/>
      </geometry>
      <origin rpy="0 0 0" xyz="0 0 0"/>
    </collision>
  </link>
  <joint name="nao_1/LElbowYaw" type="revolute">
    <parent link="nao_1/LBicep"/>
    <child link="nao_1/LElbow"/>
    <origin rpy="0 0 0" xyz="0.105 0.015 0"/>
    <axis xyz="1.0 0 0"/>
    <limit effort="1.547" lower="-2.08567" upper="2.08567" velocity="8.26797"/>
  </joint>
  <link name="nao_1/LElbow">
    <inertial>
      <mass value="0.06483"/>
      <inertia ixx="5.59588e-06" ixy="4.21e-09" ixz="2.92241e-07" iyy="2.66179e-05" iyz="-1.84e-09" izz="2.76294e-05"/>
      <origin rpy="0 0 0" xyz="-0.02744 0 -0.00014"/>
    </inertial>
  </link>
  <joint name="nao_1/LElbowRoll" type="revolute">
    <parent link="nao_1/LElbow"/>
    <child link="nao_1/LForeArm"/>
    <origin rpy="0 0 0" xyz="0 0 0"/>
    <axis xyz="0 0 1.0"/>
    <limit effort="1.532" lower="-1.54462" upper="-0.0349066" velocity="7.19407"/>
  </joint>
  <link name="nao_1/LForeArm">
    <inertial>
      <mass value="0.07761"/>
      <inertia ixx="2.46746e-05" ixy="3.23152e-06" ixz="1.58221e-06" iyy="3.83837e-05" iyz="1.39194e-07" izz="3.59708e-05"/>
      <origin rpy="0 0 0" xyz="0.02556 0.00281 0.00076"/>
    </inertial>
    <visual>
      <geometry>
        <mesh filename="package://nao_description/nao_meshes/meshes/V40/LElbowRoll.dae" scale="0.1 0.1 0.1"/>
      </geometry>
      <origin rpy="0 0 0" xyz="0 0 0"/>
    </visual>
    <collision>
      <geometry>
        <mesh filename="package://nao_description/nao_meshes/meshes/V40/LElbowRoll_0.10.stl" scale="0.1 0.1 0.1"/>
      </geometry>
      <origin rpy="0 0 0" xyz="0 0 0"/>
    </collision>
  </link>
  <joint name="nao_1/LWristYaw" type="revolute">
    <parent link="nao_1/LForeArm"/>
    <child link="nao_1/l_wrist"/>
    <origin rpy="0 0 0" xyz="0.05595 0 0"/>
    <axis xyz="1.0 0 0"/>
    <limit effort="0.4075" lower="-1.82387" upper="1.82387" velocity="24.6229"/>
  </joint>
  <link name="nao_1/l_wrist">
    <inertial>
      <mass value="0.18533"/>
      <inertia ixx="6.86477e-05" ixy="1.15465e-07" ixz="-2.87254e-06" iyy="0.000135756" iyz="2.67539e-06" izz="0.000133228"/>
      <origin rpy="0 0 0" xyz="0.03434 -0.00088 0.00308"/>
    </inertial>
    <visual>
      <geometry>
        <mesh filename="package://nao_description/nao_meshes/meshes/V40/LWristYaw.dae" scale="0.1 0.1 0.1"/>
      </geometry>
      <origin rpy="0 0 0" xyz="0 0 0"/>
    </visual>
    <collision>
      <geometry>
        <mesh filename="package://nao_description/nao_meshes/meshes/V40/LWristYaw_0.10.stl" scale="0.1 0.1 0.1"/>
      </geometry>
      <origin rpy="0 0 0" xyz="0 0 0"/>
    </collision>
  </link>
  <joint name="nao_1/LHand" type="revolute">
    <parent link="nao_1/l_wrist"/>
    <child link="nao_1/l_gripper"/>
    <origin rpy="0 0 0" xyz="0.05775 0 -0.01231"/>
    <axis xyz="1.0 0 0"/>
    <limit effort="0.292" lower="0" upper="1.0" velocity="8.33"/>
  </joint>
  <link name="nao_1/l_gripper">
    <inertial>
      <mass value="2e-06"/>
      <inertia ixx="1.1e-09" ixy="0" ixz="0" iyy="1.1e-09" iyz="0" izz="1.1e-09"/>
    </inertial>
  </link>
  <joint name="nao_1/RShoulderPitch" type="revolute">
    <parent link="nao_1/torso"/>
    <child link="nao_1/RShoulder"/>
    <origin rpy="0 0 0" xyz="0 -0.098 0.1"/>
    <axis xyz="0 1.0 0"/>
    <limit effort="1.329" lower="-2.08567" upper="2.08567" velocity="8.26797"/>
  </joint>
  <link name="nao_1/RShoulder">
    <inertial>
      <mass value="0.07504"/>
      <inertia ixx="3.10677e-05" ixy="-1.2692e-06" ixz="6.04576e-09" iyy="1.39498e-05" iyz="2.99484e-07" izz="3.30001e-05"/>
      <origin rpy="0 0 0" xyz="-0.00165 0.02663 0.00014"/>
    </inertial>
    <visual>
      <geometry>
        <mesh filename="package://nao_description/nao_meshes/meshes/V40/RShoulderPitch.dae" scale="0.1 0.1 0.1"/>
      </geometry>
      <origin rpy="0 0 0" xyz="0 0 0"/>
    </visual>
    <collision>
      <geometry>
        <mesh filename="package://nao_description/nao_meshes/meshes/V40/RShoulderPitch_0.10.stl" scale="0.1 0.1 0.1"/>
      </geometry>
      <origin rpy="0 0 0" xyz="0 0 0"/>
    </collision>
  </link>
  <joint name="nao_1/RShoulderRoll" type="revolute">
    <parent link="nao_1/RShoulder"/>
    <child link="nao_1/RBicep"/>
    <origin rpy="0 0 0" xyz="0 0 0"/>
    <axis xyz="0 0 1.0"/>
    <limit effort="1.783" lower="-1.32645" upper="0.314159" velocity="7.19407"/>
  </joint>
  <link name="nao_1/RBicep">
    <inertial>
      <mass value="0.15777"/>
      <inertia ixx="0.000103401" ixy="5.48849e-05" ixz="-1.32643e-05" iyy="0.00027077" iyz="9.16707e-06" izz="0.000254529"/>
      <origin rpy="0 0 0" xyz="0.02455 -0.00563 0.0033"/>
    </inertial>
    <visual>
      <geometry>
        <mesh filename="package://nao_description/nao_meshes/meshes/V40/RShoulderRoll.dae" scale="0.1 0.1 0.1"/>
      </geometry>
      <origin rpy="0 0 0" xyz="0 0 0"/>
    </visual>
    <collision>
      <geometry>
        <mesh filename="package://nao_description/nao_meshes/meshes/V40/RShoulderRoll_0.10.stl" scale="0.1 0.1 0.1"/>
      </geometry>
      <origin rpy="0 0 0" xyz="0 0 0"/>
    </collision>
  </link>
  <joint name="nao_1/RElbowYaw" type="revolute">
    <parent link="nao_1/RBicep"/>
    <child link="nao_1/RElbow"/>
    <origin rpy="0 0 0" xyz="0.105 -0.015 0"/>
    <axis xyz="1.0 0 0"/>
    <limit effort="1.547" lower="-2.08567" upper="2.08567" velocity="8.26797"/>
  </joint>
  <link name="nao_1/RElbow">
    <inertial>
      <mass value="0.06483"/>
      <inertia ixx="5.59588e-06" ixy="4.21e-09" ixz="2.92241e-07" iyy="2.66179e-05" iyz="-1.84e-09" izz="2.76294e-05"/>
      <origin rpy="0 0 0" xyz="-0.02744 0 -0.00014"/>
    </inertial>
  </link>
  <joint name="nao_1/RElbowRoll" type="revolute">
    <parent link="nao_1/RElbow"/>
    <child link="nao_1/RForeArm"/>
    <origin rpy="0 0 0" xyz="0 0 0"/>
    <axis xyz="0 0 1.0"/>
    <limit effort="1.532" lower="0.0349066" upper="1.54462" velocity="7.19407"/>
  </joint>
  <link name="nao_1/RForeArm">
    <inertial>
      <mass value="0.07761"/>
      <inertia ixx="2.47331e-05" ixy="-3.2418e-06" ixz="9.06451e-07" iyy="3.84719e-05" iyz="-1.38804e-07" izz="3.59319e-05"/>
      <origin rpy="0 0 0" xyz="0.02556 -0.00281 0.00076"/>
    </inertial>
    <visual>
      <geometry>
        <mesh filename="package://nao_description/nao_meshes/meshes/V40/RElbowRoll.dae" scale="0.1 0.1 0.1"/>
      </geometry>
      <origin rpy="0 0 0" xyz="0 0 0"/>
    </visual>
    <collision>
      <geometry>
        <mesh filename="package://nao_description/nao_meshes/meshes/V40/RElbowRoll_0.10.stl" scale="0.1 0.1 0.1"/>
      </geometry>
      <origin rpy="0 0 0" xyz="0 0 0"/>
    </collision>
  </link>
  <joint name="nao_1/RWristYaw" type="revolute">
    <parent link="nao_1/RForeArm"/>
    <child link="nao_1/r_wrist"/>
    <origin rpy="0 0 0" xyz="0.05595 0 0"/>
    <axis xyz="1.0 0 0"/>
    <limit effort="0.4075" lower="-1.82387" upper="1.82387" velocity="24.6229"/>
  </joint>
  <link name="nao_1/r_wrist">
    <inertial>
      <mass value="0.18533"/>
      <inertia ixx="6.86477e-05" ixy="1.13165e-05" ixz="-2.87254e-06" iyy="0.000135756" iyz="3.68003e-06" izz="0.000133228"/>
      <origin rpy="0 0 0" xyz="0.03434 0.00088 0.00308"/>
    </inertial>
    <visual>
      <geometry>
        <mesh filename="package://nao_description/nao_meshes/meshes/V40/RWristYaw.dae" scale="0.1 0.1 0.1"/>
      </geometry>
      <origin rpy="0 0 0" xyz="0 0 0"/>
    </visual>
    <collision>
      <geometry>
        <mesh filename="package://nao_description/nao_meshes/meshes/V40/RWristYaw_0.10.stl" scale="0.1 0.1 0.1"/>
      </geometry>
      <origin rpy="0 0 0" xyz="0 0 0"/>
    </collision>
  </link>
  <joint name="nao_1/RHand" type="revolute">
    <parent link="nao_1/r_wrist"/>
    <child link="nao_1/r_gripper"/>
    <origin rpy="0 0 0" xyz="0.05775 0 -0.01231"/>
    <axis xyz="1.0 0 0"/>
    <limit effort="0.292" lower="0" upper="1.0" velocity="8.33"/>
  </joint>
  <link name="nao_1/r_gripper">
    <inertial>
      <mass value="2e-06"/>
      <inertia ixx="1.1e-09" ixy="0" ixz="0" iyy="1.1e-09" iyz="0" izz="1.1e-09"/>
    </inertial>
  </link>
  <link name="nao_1/LFootBumperRight_frame"/>
  <joint name="nao_1/LFoot/Bumper/Right_sensor_fixedjoint" type="fixed">
    <parent link="nao_1/l_ankle"/>
    <child link="nao_1/LFootBumperRight_frame"/>
    <origin rpy="0 0 0" xyz="0.0876 -0.014 -0.0353"/>
    <axis xyz="0 0 0"/>
  </joint>
  <link name="nao_1/RFsrRL_frame">
    <collision>
      <geometry>
        <box size="0.01 0.01 0.005"/>
      </geometry>
      <origin rpy="0 0 0" xyz="0 0 0"/>
    </collision>
    <inertial>
      <mass value="2e-06"/>
      <inertia ixx="1.1e-09" ixy="0" ixz="0" iyy="1.1e-09" iyz="0" izz="1.1e-09"/>
    </inertial>
  </link>
  <joint name="nao_1/RFoot/FSR/RearLeft_sensor_fixedjoint" type="fixed">
    <parent link="nao_1/r_ankle"/>
    <child link="nao_1/RFsrRL_frame"/>
    <origin rpy="0 0 0" xyz="-0.03025 0.0191 -0.04511"/>
    <axis xyz="0 0 0"/>
  </joint>
  <link name="nao_1/CameraBottom_optical_frame"/>
  <joint name="nao_1/CameraBottom_optical_frame_fixedjoint" type="fixed">
    <parent link="nao_1/CameraBottom_frame"/>
    <child link="nao_1/CameraBottom_optical_frame"/>
    <origin rpy="-1.57079632679 0 -1.57079632679" xyz="0 0 0"/>
  </joint>
  <link name="nao_1/RFsrRR_frame">
    <collision>
      <geometry>
        <box size="0.01 0.01 0.005"/>
      </geometry>
      <origin rpy="0 0 0" xyz="0 0 0"/>
    </collision>
    <inertial>
      <mass value="2e-06"/>
      <inertia ixx="1.1e-09" ixy="0" ixz="0" iyy="1.1e-09" iyz="0" izz="1.1e-09"/>
    </inertial>
  </link>
  <joint name="nao_1/RFoot/FSR/RearRight_sensor_fixedjoint" type="fixed">
    <parent link="nao_1/r_ankle"/>
    <child link="nao_1/RFsrRR_frame"/>
    <origin rpy="0 0 0" xyz="-0.02965 -0.0299 -0.04511"/>
    <axis xyz="0 0 0"/>
  </joint>
  <link name="nao_1/LFsrFR_frame">
    <collision>
      <geometry>
        <box size="0.01 0.01 0.005"/>
      </geometry>
      <origin rpy="0 0 0" xyz="0 0 0"/>
    </collision>
    <inertial>
      <mass value="2e-06"/>
      <inertia ixx="1.1e-09" ixy="0" ixz="0" iyy="1.1e-09" iyz="0" izz="1.1e-09"/>
    </inertial>
  </link>
  <joint name="nao_1/LFoot/FSR/FrontRight_sensor_fixedjoint" type="fixed">
    <parent link="nao_1/l_ankle"/>
    <child link="nao_1/LFsrFR_frame"/>
    <origin rpy="0 0 0" xyz="0.07025 -0.0231 -0.04511"/>
    <axis xyz="0 0 0"/>
  </joint>
  <link name="nao_1/LHandTouchBack_frame"/>
  <joint name="nao_1/LHand/Touch/Back_sensor_fixedjoint" type="fixed">
    <parent link="nao_1/l_wrist"/>
    <child link="nao_1/LHandTouchBack_frame"/>
    <origin rpy="3.14159 -1.5708 3.14159" xyz="0.038 0 0.025"/>
    <axis xyz="0 0 0"/>
  </joint>
  <link name="nao_1/LHandTouchLeft_frame"/>
  <joint name="nao_1/LHand/Touch/Left_sensor_fixedjoint" type="fixed">
    <parent link="nao_1/l_wrist"/>
    <child link="nao_1/LHandTouchLeft_frame"/>
    <origin rpy="0 0 1.5708" xyz="0.032 0.025 0.003"/>
    <axis xyz="0 0 0"/>
  </joint>
  <link name="nao_1/RFootBumperRight_frame"/>
  <joint name="nao_1/RFoot/Bumper/Right_sensor_fixedjoint" type="fixed">
    <parent link="nao_1/r_ankle"/>
    <child link="nao_1/RFootBumperRight_frame"/>
    <origin rpy="0 0 0" xyz="0.0876 -0.019 -0.0353"/>
    <axis xyz="0 0 0"/>
  </joint>
  <link name="nao_1/RFsrFR_frame">
    <collision>
      <geometry>
        <box size="0.01 0.01 0.005"/>
      </geometry>
      <origin rpy="0 0 0" xyz="0 0 0"/>
    </collision>
    <inertial>
      <mass value="2e-06"/>
      <inertia ixx="1.1e-09" ixy="0" ixz="0" iyy="1.1e-09" iyz="0" izz="1.1e-09"/>
    </inertial>
  </link>
  <joint name="nao_1/RFoot/FSR/FrontRight_sensor_fixedjoint" type="fixed">
    <parent link="nao_1/r_ankle"/>
    <child link="nao_1/RFsrFR_frame"/>
    <origin rpy="0 0 0" xyz="0.07025 -0.0299 -0.04511"/>
    <axis xyz="0 0 0"/>
  </joint>
  <link name="nao_1/MicroSurroundLeft_frame"/>
  <joint name="nao_1/MicroLeft_sensor_fixedjoint" type="fixed">
    <parent link="nao_1/Head"/>
    <child link="nao_1/MicroSurroundLeft_frame"/>
    <origin rpy="0 0 0" xyz="-0.0195 0.0606 0.0331"/>
    <axis xyz="0 0 0"/>
  </joint>
  <link name="nao_1/LFsrRR_frame">
    <collision>
      <geometry>
        <box size="0.01 0.01 0.005"/>
      </geometry>
      <origin rpy="0 0 0" xyz="0 0 0"/>
    </collision>
    <inertial>
      <mass value="2e-06"/>
      <inertia ixx="1.1e-09" ixy="0" ixz="0" iyy="1.1e-09" iyz="0" izz="1.1e-09"/>
    </inertial>
  </link>
  <joint name="nao_1/LFoot/FSR/RearRight_sensor_fixedjoint" type="fixed">
    <parent link="nao_1/l_ankle"/>
    <child link="nao_1/LFsrRR_frame"/>
    <origin rpy="0 0 0" xyz="-0.02965 -0.0191 -0.04511"/>
    <axis xyz="0 0 0"/>
  </joint>
  <link name="nao_1/MicroSurroundRight_frame"/>
  <joint name="nao_1/MicroRight_sensor_fixedjoint" type="fixed">
    <parent link="nao_1/Head"/>
    <child link="nao_1/MicroSurroundRight_frame"/>
    <origin rpy="0 0 0" xyz="-0.0195 -0.0606 0.0331"/>
    <axis xyz="0 0 0"/>
  </joint>
  <link name="nao_1/ImuTorsoAccelerometer_frame"/>
  <joint name="nao_1/Accelerometer_sensor_fixedjoint" type="fixed">
    <parent link="nao_1/torso"/>
    <child link="nao_1/ImuTorsoAccelerometer_frame"/>
    <origin rpy="0 0 0" xyz="-0.008 0.00606 0.027"/>
    <axis xyz="0 0 0"/>
  </joint>
  <link name="nao_1/HeadTouchFront_frame"/>
  <joint name="nao_1/Head/Touch/Front_sensor_fixedjoint" type="fixed">
    <parent link="nao_1/Head"/>
    <child link="nao_1/HeadTouchFront_frame"/>
    <origin rpy="0 -1.1861 0" xyz="0.0312 0 0.1014"/>
    <axis xyz="0 0 0"/>
  </joint>
  <link name="nao_1/RFootBumperLeft_frame"/>
  <joint name="nao_1/RFoot/Bumper/Left_sensor_fixedjoint" type="fixed">
    <parent link="nao_1/r_ankle"/>
    <child link="nao_1/RFootBumperLeft_frame"/>
    <origin rpy="0 0 0" xyz="0.0876 0.014 -0.0353"/>
    <axis xyz="0 0 0"/>
  </joint>
  <link name="nao_1/RSonar_frame"/>
  <joint name="nao_1/Sonar/Right_sensor_fixedjoint" type="fixed">
    <parent link="nao_1/torso"/>
    <child link="nao_1/RSonar_frame"/>
    <origin rpy="0.00478508 0.0436497 -0.392441" xyz="0.00558253 -0.0192068 0.0623853"/>
    <axis xyz="0 0 0"/>
  </joint>
  <link name="nao_1/RHandTouchRight_frame"/>
  <joint name="nao_1/RHand/Touch/Right_sensor_fixedjoint" type="fixed">
    <parent link="nao_1/r_wrist"/>
    <child link="nao_1/RHandTouchRight_frame"/>
    <origin rpy="0 0 -1.5708" xyz="0.035 -0.025 0.0035"/>
    <axis xyz="0 0 0"/>
  </joint>
  <link name="nao_1/RHandTouchBack_frame"/>
  <joint name="nao_1/RHand/Touch/Back_sensor_fixedjoint" type="fixed">
    <parent link="nao_1/r_wrist"/>
    <child link="nao_1/RHandTouchBack_frame"/>
    <origin rpy="3.14159 -1.5708 3.14159" xyz="0.038 0 0.025"/>
    <axis xyz="0 0 0"/>
  </joint>
  <link name="nao_1/RFsrFL_frame">
    <collision>
      <geometry>
        <box size="0.01 0.01 0.005"/>
      </geometry>
      <origin rpy="0 0 0" xyz="0 0 0"/>
    </collision>
    <inertial>
      <mass value="2e-06"/>
      <inertia ixx="1.1e-09" ixy="0" ixz="0" iyy="1.1e-09" iyz="0" izz="1.1e-09"/>
    </inertial>
  </link>
  <joint name="nao_1/RFoot/FSR/FrontLeft_sensor_fixedjoint" type="fixed">
    <parent link="nao_1/r_ankle"/>
    <child link="nao_1/RFsrFL_frame"/>
    <origin rpy="0 0 0" xyz="0.07025 0.0231 -0.04511"/>
    <axis xyz="0 0 0"/>
  </joint>
  <link name="nao_1/LSonar_frame"/>
  <joint name="nao_1/Sonar/Left_sensor_fixedjoint" type="fixed">
    <parent link="nao_1/torso"/>
    <child link="nao_1/LSonar_frame"/>
    <origin rpy="-0.00478508 0.0436497 0.392441" xyz="0.00558253 0.0192068 0.0623853"/>
    <axis xyz="0 0 0"/>
  </joint>
  <link name="nao_1/LFsrFL_frame">
    <collision>
      <geometry>
        <box size="0.01 0.01 0.005"/>
      </geometry>
      <origin rpy="0 0 0" xyz="0 0 0"/>
    </collision>
    <inertial>
      <mass value="2e-06"/>
      <inertia ixx="1.1e-09" ixy="0" ixz="0" iyy="1.1e-09" iyz="0" izz="1.1e-09"/>
    </inertial>
  </link>
  <joint name="nao_1/LFoot/FSR/FrontLeft_sensor_fixedjoint" type="fixed">
    <parent link="nao_1/l_ankle"/>
    <child link="nao_1/LFsrFL_frame"/>
    <origin rpy="0 0 0" xyz="0.07025 0.0299 -0.04511"/>
    <axis xyz="0 0 0"/>
  </joint>
  <link name="nao_1/LFsrRL_frame">
    <collision>
      <geometry>
        <box size="0.01 0.01 0.005"/>
      </geometry>
      <origin rpy="0 0 0" xyz="0 0 0"/>
    </collision>
    <inertial>
      <mass value="2e-06"/>
      <inertia ixx="1.1e-09" ixy="0" ixz="0" iyy="1.1e-09" iyz="0" izz="1.1e-09"/>
    </inertial>
  </link>
  <joint name="nao_1/LFoot/FSR/RearLeft_sensor_fixedjoint" type="fixed">
    <parent link="nao_1/l_ankle"/>
    <child link="nao_1/LFsrRL_frame"/>
    <origin rpy="0 0 0" xyz="-0.03025 0.0299 -0.04511"/>
    <axis xyz="0 0 0"/>
  </joint>
  <link name="nao_1/RHandTouchLeft_frame"/>
  <joint name="nao_1/RHand/Touch/Left_sensor_fixedjoint" type="fixed">
    <parent link="nao_1/r_wrist"/>
    <child link="nao_1/RHandTouchLeft_frame"/>
    <origin rpy="0 0 0" xyz="0.032 0.025 0.003"/>
    <axis xyz="0 0 0"/>
  </joint>
  <link name="nao_1/CameraBottom_frame"/>
  <joint name="nao_1/CameraBottom_sensor_fixedjoint" type="fixed">
    <parent link="nao_1/Head"/>
    <child link="nao_1/CameraBottom_frame"/>
    <origin rpy="0 0 0" xyz="0.05071 0 0.01774"/>
    <axis xyz="0 0 0"/>
  </joint>
  <link name="nao_1/CameraTop_frame"/>
  <joint name="nao_1/CameraTop_sensor_fixedjoint" type="fixed">
    <parent link="nao_1/Head"/>
    <child link="nao_1/CameraTop_frame"/>
    <origin rpy="0 0 0" xyz="0.05871 0 0.06364"/>
    <axis xyz="0 0 0"/>
  </joint>
  <link name="nao_1/CameraTop_optical_frame"/>
  <joint name="nao_1/CameraTop_optical_frame_fixedjoint" type="fixed">
    <parent link="nao_1/CameraTop_frame"/>
    <child link="nao_1/CameraTop_optical_frame"/>
    <origin rpy="-1.57079632679 0 -1.57079632679" xyz="0 0 0"/>
  </joint>
  <link name="nao_1/Rplidar_frame">
    <inertial>
      <mass value="0.1"/>
      <origin xyz="0 0 0"/>
      <inertia ixx="0.01" ixy="0.0" ixz="0.0" iyy="0.01" iyz="0.0" izz="0.01"/>
    </inertial>
    <visual>
      <origin rpy="0 0 0" xyz=" 0 0 0 "/>
      <geometry>
        <box size="0.01 0.01 0.005"/>
      </geometry>
      <material name="red"/>
    </visual>
    <collision>
      <origin rpy="0 0 0" xyz="0.0 0.0 0.0"/>
      <geometry>
        <cylinder length="0.01" radius="0.01"/>
      </geometry>
    </collision>
  </link>
  <joint name="nao_1/Rplidar_sensor_fixedjoint" type="fixed">
    <origin rpy="0 0 0" xyz="0 0 0.025"/>
    <parent link="nao_1/Head"/>
    <child link="nao_1/Rplidar_frame"/>
  </joint>
  <link name="nao_1/LInfraRed_frame"/>
  <joint name="nao_1/InfraredL_sensor_fixedjoint" type="fixed">
    <parent link="nao_1/Head"/>
    <child link="nao_1/LInfraRed_frame"/>
    <origin rpy="0 0 0" xyz="0.0441 0.0257 0.0466"/>
    <axis xyz="0 0 0"/>
  </joint>
  <link name="nao_1/ImuTorsoGyrometer_frame"/>
  <joint name="nao_1/Gyrometer_sensor_fixedjoint" type="fixed">
    <parent link="nao_1/torso"/>
    <child link="nao_1/ImuTorsoGyrometer_frame"/>
    <origin rpy="0 0 0" xyz="-0.008 0.006 0.029"/>
    <axis xyz="0 0 0"/>
  </joint>
  <link name="nao_1/MicroFrontCenter_frame"/>
  <joint name="nao_1/MicroFront_sensor_fixedjoint" type="fixed">
    <parent link="nao_1/Head"/>
    <child link="nao_1/MicroFrontCenter_frame"/>
    <origin rpy="0 0 0" xyz="0.041 0 0.091"/>
    <axis xyz="0 0 0"/>
  </joint>
  <link name="nao_1/HeadTouchRear_frame"/>
  <joint name="nao_1/Head/Touch/Rear_sensor_fixedjoint" type="fixed">
    <parent link="nao_1/Head"/>
    <child link="nao_1/HeadTouchRear_frame"/>
    <origin rpy="3.14159 -1.33319 -3.14159" xyz="-0.0257 0 0.1045"/>
    <axis xyz="0 0 0"/>
  </joint>
  <link name="nao_1/HeadTouchMiddle_frame"/>
  <joint name="nao_1/Head/Touch/Middle_sensor_fixedjoint" type="fixed">
    <parent link="nao_1/Head"/>
    <child link="nao_1/HeadTouchMiddle_frame"/>
    <origin rpy="3.14159 -1.57079 -3.14159" xyz="0.001 0 0.1099"/>
    <axis xyz="0 0 0"/>
  </joint>
  <link name="nao_1/RInfraRed_frame"/>
  <joint name="nao_1/InfraredR_sensor_fixedjoint" type="fixed">
    <parent link="nao_1/Head"/>
    <child link="nao_1/RInfraRed_frame"/>
    <origin rpy="0 0 0" xyz="0.0441 -0.0257 0.0466"/>
    <axis xyz="0 0 0"/>
  </joint>
  <link name="nao_1/ChestButton_frame"/>
  <joint name="nao_1/ChestBoard/Button_sensor_fixedjoint" type="fixed">
    <parent link="nao_1/torso"/>
    <child link="nao_1/ChestButton_frame"/>
    <origin rpy="0 0 0" xyz="0.049871 0.001588 0.055163"/>
    <axis xyz="0 0 0"/>
  </joint>
  <link name="nao_1/LFootBumperLeft_frame"/>
  <joint name="nao_1/LFoot/Bumper/Left_sensor_fixedjoint" type="fixed">
    <parent link="nao_1/l_ankle"/>
    <child link="nao_1/LFootBumperLeft_frame"/>
    <origin rpy="0 0 0" xyz="0.0876 0.019 -0.0353"/>
    <axis xyz="0 0 0"/>
  </joint>
  <link name="nao_1/MicroRearCenter_frame"/>
  <joint name="nao_1/MicroRear_sensor_fixedjoint" type="fixed">
    <parent link="nao_1/Head"/>
    <child link="nao_1/MicroRearCenter_frame"/>
    <origin rpy="0 0 0" xyz="-0.0577 0 0.0693"/>
    <axis xyz="0 0 0"/>
  </joint>
  <link name="nao_1/LHandTouchRight_frame"/>
  <joint name="nao_1/LHand/Touch/Right_sensor_fixedjoint" type="fixed">
    <parent link="nao_1/l_wrist"/>
    <child link="nao_1/LHandTouchRight_frame"/>
    <origin rpy="0 0 -1.5708" xyz="0.035 -0.025 0.0035"/>
    <axis xyz="0 0 0"/>
  </joint>
  <link name="nao_1/RFinger23_link">
    <inertial>
      <mass value="2e-06"/>
      <inertia ixx="1.1e-09" ixy="0" ixz="0" iyy="1.1e-09" iyz="0" izz="1.1e-09"/>
    </inertial>
    <visual>
      <geometry>
        <mesh filename="package://nao_description/nao_meshes/meshes/V40/RFinger23.dae" scale="0.1 0.1 0.1"/>
      </geometry>
      <origin rpy="0 0 0" xyz="0 0 0"/>
    </visual>
    <collision>
      <geometry>
        <mesh filename="package://nao_description/nao_meshes/meshes/V40/RFinger23_0.10.stl" scale="0.1 0.1 0.1"/>
      </geometry>
      <origin rpy="0 0 0" xyz="0 0 0"/>
    </collision>
  </link>
  <joint name="nao_1/RFinger23" type="fixed">
    <parent link="nao_1/RFinger22_link"/>
    <child link="nao_1/RFinger23_link"/>
    <origin rpy="0 0 -0.999899" xyz="0.01436 0 0"/>
    <axis xyz="0 0 1.0"/>
    <!--	<mimic joint="RHand" multiplier="0.999899" offset="0"/> -->
  </joint>
  <link name="nao_1/RFinger13_link">
    <inertial>
      <mass value="2e-06"/>
      <inertia ixx="1.1e-09" ixy="0" ixz="0" iyy="1.1e-09" iyz="0" izz="1.1e-09"/>
    </inertial>
    <visual>
      <geometry>
        <mesh filename="package://nao_description/nao_meshes/meshes/V40/RFinger13.dae" scale="0.1 0.1 0.1"/>
      </geometry>
      <origin rpy="0 0 0" xyz="0 0 0"/>
    </visual>
    <collision>
      <geometry>
        <mesh filename="package://nao_description/nao_meshes/meshes/V40/RFinger13_0.10.stl" scale="0.1 0.1 0.1"/>
      </geometry>
      <origin rpy="0 0 0" xyz="0 0 0"/>
    </collision>
  </link>
  <joint name="nao_1/RFinger13" type="fixed">
    <parent link="nao_1/RFinger12_link"/>
    <child link="nao_1/RFinger13_link"/>
    <origin rpy="0 0 -0.999899" xyz="0.01436 0 0"/>
    <axis xyz="0 0 1.0"/>
    <!--	<mimic joint="RHand" multiplier="0.999899" offset="0"/>  -->
  </joint>
  <link name="nao_1/RFinger12_link">
    <inertial>
      <mass value="2e-06"/>
      <inertia ixx="1.1e-09" ixy="0" ixz="0" iyy="1.1e-09" iyz="0" izz="1.1e-09"/>
    </inertial>
    <visual>
      <geometry>
        <mesh filename="package://nao_description/nao_meshes/meshes/V40/RFinger12.dae" scale="0.1 0.1 0.1"/>
      </geometry>
      <origin rpy="0 0 0" xyz="0 0 0"/>
    </visual>
    <collision>
      <geometry>
        <mesh filename="package://nao_description/nao_meshes/meshes/V40/RFinger12_0.10.stl" scale="0.1 0.1 0.1"/>
      </geometry>
      <origin rpy="0 0 0" xyz="0 0 0"/>
    </collision>
  </link>
  <joint name="nao_1/RFinger12" type="fixed">
    <parent link="nao_1/RFinger11_link"/>
    <child link="nao_1/RFinger12_link"/>
    <origin rpy="0 0 -0.999899" xyz="0.01436 0 0"/>
    <axis xyz="0 0 1.0"/>
    <!--	<mimic joint="RHand" multiplier="0.999899" offset="0"/> -->
  </joint>
  <link name="nao_1/LFinger21_link">
    <inertial>
      <mass value="2e-06"/>
      <inertia ixx="1.1e-09" ixy="0" ixz="0" iyy="1.1e-09" iyz="0" izz="1.1e-09"/>
    </inertial>
    <visual>
      <geometry>
        <mesh filename="package://nao_description/nao_meshes/meshes/V40/LFinger21.dae" scale="0.1 0.1 0.1"/>
      </geometry>
      <origin rpy="0 0 0" xyz="0 0 0"/>
    </visual>
    <collision>
      <geometry>
        <mesh filename="package://nao_description/nao_meshes/meshes/V40/LFinger21_0.10.stl" scale="0.1 0.1 0.1"/>
      </geometry>
      <origin rpy="0 0 0" xyz="0 0 0"/>
    </collision>
  </link>
  <joint name="nao_1/LFinger21" type="fixed">
    <parent link="nao_1/l_wrist"/>
    <child link="nao_1/LFinger21_link"/>
    <origin rpy="1.25539 0.976662 -0.264067" xyz="0.06907 -0.01157 -0.00304"/>
    <axis xyz="0 0 1.0"/>
    <!--	<mimic joint="LHand" multiplier="0.999899" offset="0"/> -->
  </joint>
  <link name="nao_1/LFinger13_link">
    <inertial>
      <mass value="2e-06"/>
      <inertia ixx="1.1e-09" ixy="0" ixz="0" iyy="1.1e-09" iyz="0" izz="1.1e-09"/>
    </inertial>
    <visual>
      <geometry>
        <mesh filename="package://nao_description/nao_meshes/meshes/V40/LFinger13.dae" scale="0.1 0.1 0.1"/>
      </geometry>
      <origin rpy="0 0 0" xyz="0 0 0"/>
    </visual>
    <collision>
      <geometry>
        <mesh filename="package://nao_description/nao_meshes/meshes/V40/LFinger13_0.10.stl" scale="0.1 0.1 0.1"/>
      </geometry>
      <origin rpy="0 0 0" xyz="0 0 0"/>
    </collision>
  </link>
  <joint name="nao_1/LFinger13" type="fixed">
    <parent link="nao_1/LFinger12_link"/>
    <child link="nao_1/LFinger13_link"/>
    <origin rpy="0 0 -0.999899" xyz="0.01436 0 0"/>
    <axis xyz="0 0 1.0"/>
    <!--	<mimic joint="LHand" multiplier="0.999899" offset="0"/> -->
  </joint>
  <link name="nao_1/LFinger11_link">
    <inertial>
      <mass value="2e-06"/>
      <inertia ixx="1.1e-09" ixy="0" ixz="0" iyy="1.1e-09" iyz="0" izz="1.1e-09"/>
    </inertial>
    <visual>
      <geometry>
        <mesh filename="package://nao_description/nao_meshes/meshes/V40/LFinger11.dae" scale="0.1 0.1 0.1"/>
      </geometry>
      <origin rpy="0 0 0" xyz="0 0 0"/>
    </visual>
    <collision>
      <geometry>
        <mesh filename="package://nao_description/nao_meshes/meshes/V40/LFinger11_0.10.stl" scale="0.1 0.1 0.1"/>
      </geometry>
      <origin rpy="0 0 0" xyz="0 0 0"/>
    </collision>
  </link>
  <joint name="nao_1/LFinger11" type="fixed">
    <parent link="nao_1/l_wrist"/>
    <child link="nao_1/LFinger11_link"/>
    <origin rpy="1.8862 0.976662 0.264067" xyz="0.06907 0.01157 -0.00304"/>
    <axis xyz="0 0 1.0"/>
    <!--	<mimic joint="LHand" multiplier="0.999899" offset="0"/> -->
  </joint>
  <link name="nao_1/RFinger22_link">
    <inertial>
      <mass value="2e-06"/>
      <inertia ixx="1.1e-09" ixy="0" ixz="0" iyy="1.1e-09" iyz="0" izz="1.1e-09"/>
    </inertial>
    <visual>
      <geometry>
        <mesh filename="package://nao_description/nao_meshes/meshes/V40/RFinger22.dae" scale="0.1 0.1 0.1"/>
      </geometry>
      <origin rpy="0 0 0" xyz="0 0 0"/>
    </visual>
    <collision>
      <geometry>
        <mesh filename="package://nao_description/nao_meshes/meshes/V40/RFinger22_0.10.stl" scale="0.1 0.1 0.1"/>
      </geometry>
      <origin rpy="0 0 0" xyz="0 0 0"/>
    </collision>
  </link>
  <joint name="nao_1/RFinger22" type="fixed">
    <parent link="nao_1/RFinger21_link"/>
    <child link="nao_1/RFinger22_link"/>
    <origin rpy="0 0 -0.999899" xyz="0.01436 0 0"/>
    <axis xyz="0 0 1.0"/>
    <!--	<mimic joint="RHand" multiplier="0.999899" offset="0"/> -->
  </joint>
  <link name="nao_1/LFinger22_link">
    <inertial>
      <mass value="2e-06"/>
      <inertia ixx="1.1e-09" ixy="0" ixz="0" iyy="1.1e-09" iyz="0" izz="1.1e-09"/>
    </inertial>
    <visual>
      <geometry>
        <mesh filename="package://nao_description/nao_meshes/meshes/V40/LFinger22.dae" scale="0.1 0.1 0.1"/>
      </geometry>
      <origin rpy="0 0 0" xyz="0 0 0"/>
    </visual>
    <collision>
      <geometry>
        <mesh filename="package://nao_description/nao_meshes/meshes/V40/LFinger22_0.10.stl" scale="0.1 0.1 0.1"/>
      </geometry>
      <origin rpy="0 0 0" xyz="0 0 0"/>
    </collision>
  </link>
  <joint name="nao_1/LFinger22" type="fixed">
    <parent link="nao_1/LFinger21_link"/>
    <child link="nao_1/LFinger22_link"/>
    <origin rpy="0 0 -0.999899" xyz="0.01436 0 0"/>
    <axis xyz="0 0 1.0"/>
    <!--	<mimic joint="LHand" multiplier="0.999899" offset="0"/> -->
  </joint>
  <link name="nao_1/RFinger21_link">
    <inertial>
      <mass value="2e-06"/>
      <inertia ixx="1.1e-09" ixy="0" ixz="0" iyy="1.1e-09" iyz="0" izz="1.1e-09"/>
    </inertial>
    <visual>
      <geometry>
        <mesh filename="package://nao_description/nao_meshes/meshes/V40/RFinger21.dae" scale="0.1 0.1 0.1"/>
      </geometry>
      <origin rpy="0 0 0" xyz="0 0 0"/>
    </visual>
    <collision>
      <geometry>
        <mesh filename="package://nao_description/nao_meshes/meshes/V40/RFinger21_0.10.stl" scale="0.1 0.1 0.1"/>
      </geometry>
      <origin rpy="0 0 0" xyz="0 0 0"/>
    </collision>
  </link>
  <joint name="nao_1/RFinger21" type="fixed">
    <parent link="nao_1/r_wrist"/>
    <child link="nao_1/RFinger21_link"/>
    <origin rpy="1.25539 0.976662 -0.264067" xyz="0.06907 -0.01157 -0.00304"/>
    <axis xyz="0 0 1.0"/>
    <!--	<mimic joint="RHand" multiplier="0.999899" offset="0"/> -->
  </joint>
  <link name="nao_1/LFinger12_link">
    <inertial>
      <mass value="2e-06"/>
      <inertia ixx="1.1e-09" ixy="0" ixz="0" iyy="1.1e-09" iyz="0" izz="1.1e-09"/>
    </inertial>
    <visual>
      <geometry>
        <mesh filename="package://nao_description/nao_meshes/meshes/V40/LFinger12.dae" scale="0.1 0.1 0.1"/>
      </geometry>
      <origin rpy="0 0 0" xyz="0 0 0"/>
    </visual>
    <collision>
      <geometry>
        <mesh filename="package://nao_description/nao_meshes/meshes/V40/LFinger12_0.10.stl" scale="0.1 0.1 0.1"/>
      </geometry>
      <origin rpy="0 0 0" xyz="0 0 0"/>
    </collision>
  </link>
  <joint name="nao_1/LFinger12" type="fixed">
    <parent link="nao_1/LFinger11_link"/>
    <child link="nao_1/LFinger12_link"/>
    <origin rpy="0 0 -0.999899" xyz="0.01436 0 0"/>
    <axis xyz="0 0 1.0"/>
    <!--	<mimic joint="LHand" multiplier="0.999899" offset="0"/> -->
  </joint>
  <link name="nao_1/RFinger11_link">
    <inertial>
      <mass value="2e-06"/>
      <inertia ixx="1.1e-09" ixy="0" ixz="0" iyy="1.1e-09" iyz="0" izz="1.1e-09"/>
    </inertial>
    <visual>
      <geometry>
        <mesh filename="package://nao_description/nao_meshes/meshes/V40/RFinger11.dae" scale="0.1 0.1 0.1"/>
      </geometry>
      <origin rpy="0 0 0" xyz="0 0 0"/>
    </visual>
    <collision>
      <geometry>
        <mesh filename="package://nao_description/nao_meshes/meshes/V40/RFinger11_0.10.stl" scale="0.1 0.1 0.1"/>
      </geometry>
      <origin rpy="0 0 0" xyz="0 0 0"/>
    </collision>
  </link>
  <joint name="nao_1/RFinger11" type="fixed">
    <parent link="nao_1/r_wrist"/>
    <child link="nao_1/RFinger11_link"/>
    <origin rpy="1.8862 0.976662 0.264067" xyz="0.06907 0.01157 -0.00304"/>
    <axis xyz="0 0 1.0"/>
    <!--	<mimic joint="RHand" multiplier="0.999899" offset="0"/> -->
  </joint>
  <link name="nao_1/LFinger23_link">
    <inertial>
      <mass value="2e-06"/>
      <inertia ixx="1.1e-09" ixy="0" ixz="0" iyy="1.1e-09" iyz="0" izz="1.1e-09"/>
    </inertial>
    <visual>
      <geometry>
        <mesh filename="package://nao_description/nao_meshes/meshes/V40/LFinger23.dae" scale="0.1 0.1 0.1"/>
      </geometry>
      <origin rpy="0 0 0" xyz="0 0 0"/>
    </visual>
    <collision>
      <geometry>
        <mesh filename="package://nao_description/nao_meshes/meshes/V40/LFinger23_0.10.stl" scale="0.1 0.1 0.1"/>
      </geometry>
      <origin rpy="0 0 0" xyz="0 0 0"/>
    </collision>
  </link>
  <joint name="nao_1/LFinger23" type="fixed">
    <parent link="nao_1/LFinger22_link"/>
    <child link="nao_1/LFinger23_link"/>
    <origin rpy="0 0 -0.999899" xyz="0.01436 0 0"/>
    <axis xyz="0 0 1.0"/>
    <!--	<mimic joint="LHand" multiplier="0.999899" offset="0"/> -->
  </joint>
  <link name="nao_1/LThumb1_link">
    <inertial>
      <mass value="2e-06"/>
      <inertia ixx="1.1e-09" ixy="0" ixz="0" iyy="0" iyz="0" izz="0"/>
    </inertial>
    <visual>
      <geometry>
        <mesh filename="package://nao_description/nao_meshes/meshes/V40/LThumb1.dae" scale="0.1 0.1 0.1"/>
      </geometry>
      <origin rpy="0 0 0" xyz="0 0 0"/>
    </visual>
    <collision>
      <geometry>
        <mesh filename="package://nao_description/nao_meshes/meshes/V40/LThumb1_0.10.stl" scale="0.1 0.1 0.1"/>
      </geometry>
      <origin rpy="0 0 0" xyz="0 0 0"/>
    </collision>
  </link>
  <joint name="nao_1/LThumb1" type="fixed">
    <parent link="nao_1/l_wrist"/>
    <child link="nao_1/LThumb1_link"/>
    <origin rpy="-1.5708 0.0472984 -3.26826e-08" xyz="0.04895 0 -0.02638"/>
    <axis xyz="0 0 1.0"/>
    <!--	<mimic joint="LHand" multiplier="0.999899" offset="0"/> -->
  </joint>
  <link name="nao_1/RThumb1_link">
    <inertial>
      <mass value="2e-06"/>
      <inertia ixx="1.1e-09" ixy="0" ixz="0" iyy="1.1e-09" iyz="0" izz="1.1e-09"/>
    </inertial>
    <visual>
      <geometry>
        <mesh filename="package://nao_description/nao_meshes/meshes/V40/RThumb1.dae" scale="0.1 0.1 0.1"/>
      </geometry>
      <origin rpy="0 0 0" xyz="0 0 0"/>
    </visual>
    <collision>
      <geometry>
        <mesh filename="package://nao_description/nao_meshes/meshes/V40/RThumb1_0.10.stl" scale="0.1 0.1 0.1"/>
      </geometry>
      <origin rpy="0 0 0" xyz="0 0 0"/>
    </collision>
  </link>
  <joint name="nao_1/RThumb1" type="fixed">
    <parent link="nao_1/r_wrist"/>
    <child link="nao_1/RThumb1_link"/>
    <origin rpy="-1.5708 0.0472984 -3.26826e-08" xyz="0.04895 0 -0.02638"/>
    <axis xyz="0 0 1.0"/>
    <!--	<mimic joint="RHand" multiplier="0.999899" offset="0"/> -->
  </joint>
  <link name="nao_1/RThumb2_link">
    <inertial>
      <mass value="2e-06"/>
      <inertia ixx="0" ixy="0" ixz="0" iyy="0" iyz="0" izz="0"/>
    </inertial>
    <visual>
      <geometry>
        <mesh filename="package://nao_description/nao_meshes/meshes/V40/RThumb2.dae" scale="0.1 0.1 0.1"/>
      </geometry>
      <origin rpy="0 0 0" xyz="0 0 0"/>
    </visual>
    <collision>
      <geometry>
        <mesh filename="package://nao_description/nao_meshes/meshes/V40/RThumb2_0.10.stl" scale="0.1 0.1 0.1"/>
      </geometry>
      <origin rpy="0 0 0" xyz="0 0 0"/>
    </collision>
  </link>
  <joint name="nao_1/RThumb2" type="fixed">
    <parent link="nao_1/RThumb1_link"/>
    <child link="nao_1/RThumb2_link"/>
    <origin rpy="0 0 -0.999899" xyz="0.01436 0 0"/>
    <axis xyz="0 0 1.0"/>
    <!--	<mimic joint="RHand" multiplier="0.999899" offset="0"/> -->
  </joint>
  <link name="nao_1/LThumb2_link">
    <inertial>
      <mass value="2e-06"/>
      <inertia ixx="0" ixy="0" ixz="0" iyy="0" iyz="0" izz="0"/>
    </inertial>
    <visual>
      <geometry>
        <mesh filename="package://nao_description/nao_meshes/meshes/V40/LThumb2.dae" scale="0.1 0.1 0.1"/>
      </geometry>
      <origin rpy="0 0 0" xyz="0 0 0"/>
    </visual>
    <collision>
      <geometry>
        <mesh filename="package://nao_description/nao_meshes/meshes/V40/LThumb2_0.10.stl" scale="0.1 0.1 0.1"/>
      </geometry>
      <origin rpy="0 0 0" xyz="0 0 0"/>
    </collision>
  </link>
  <joint name="nao_1/LThumb2" type="fixed">
    <parent link="nao_1/LThumb1_link"/>
    <child link="nao_1/LThumb2_link"/>
    <origin rpy="0 0 -0.999899" xyz="0.01436 0 0"/>
    <axis xyz="0 0 1.0"/>
    <!--	<mimic joint="LHand" multiplier="0.999899" offset="0"/> -->
  </joint>
  <!-- GAZEBO ROS CONTROL AND IMU PLUGIN -->
  <gazebo>
    <plugin filename="/opt/ros/melodic/lib/libgazebo_ros_diff_drive.so" name="left_wheel_drive_controller">
      <rosDebugLevel>Debug</rosDebugLevel>
      <publishWheelTF>false</publishWheelTF>
      <broadcastTF>true</broadcastTF>
      <publishTf>true</publishTf>
      <leftJoint>nao_1/front_left_wheel_joint_l</leftJoint>
      <rightJoint>nao_1/front_left_wheel_joint_r</rightJoint>
      <publishWheelJointState>true</publishWheelJointState>
      <alwaysOn>true</alwaysOn>
      <updateRate>100.0</updateRate>
      <legacyMode>true</legacyMode>
      <wheelSeparation>0.3</wheelSeparation>
      <wheelDiameter>0.1</wheelDiameter>
      <wheelTorque>20</wheelTorque>
      <wheelAcceleration>2</wheelAcceleration>
      <commandTopic>left/cmd_vel</commandTopic>
      <robotBaseFrame>nao_1/base_link</robotBaseFrame>
      <publishOdomTF>true</publishOdomTF>
      <publish_odom>true</publish_odom>
      <odometryTopic>odom</odometryTopic>
      <odometryFrame>nao_1/odom</odometryFrame>
      <odometrySource>world</odometrySource>
    </plugin>
    <plugin filename="/opt/ros/melodic/lib/libgazebo_ros_diff_drive.so" name="right_wheel_drive_controller">
      <rosDebugLevel>Debug</rosDebugLevel>
      <publishWheelTF>false</publishWheelTF>
      <broadcastTF>true</broadcastTF>
      <publishTf>true</publishTf>
      <leftJoint>nao_1/front_right_wheel_joint_l</leftJoint>
      <rightJoint>nao_1/front_right_wheel_joint_r</rightJoint>
      <publishWheelJointState>true</publishWheelJointState>
      <alwaysOn>true</alwaysOn>
      <updateRate>100.0</updateRate>
      <legacyMode>true</legacyMode>
      <wheelSeparation>0.3</wheelSeparation>
      <wheelDiameter>0.1</wheelDiameter>
      <wheelTorque>20</wheelTorque>
      <wheelAcceleration>2</wheelAcceleration>
      <commandTopic>right/cmd_vel</commandTopic>
      <robotBaseFrame>nao_1/base_link</robotBaseFrame>
      <publishOdomTF>true</publishOdomTF>
      <publish_odom>true</publish_odom>
      <odometryTopic>odom</odometryTopic>
      <odometryFrame>nao_1/odom</odometryFrame>
      <odometrySource>world</odometrySource>
    </plugin>
  </gazebo>
  <!--
    <gazebo>
      <plugin name="skid_steer_drive_controller" filename="libgazebo_ros_skid_steer_drive.so">
        <rosDebugLevel>Debug</rosDebugLevel>
        <updateRate>100.0</updateRate>
        <robotNamespace>/</robotNamespace>
        <leftJoint>front_left_wheel_joint_l</leftJoint>
        <rightJoint>front_left_wheel_joint_r</rightJoint>
        <leftJoint>front_right_wheel_joint_l</leftJoint>
        <rightJoint>front_right_wheel_joint_r</rightJoint>
        <wheelSeparation>0.3</wheelSeparation>
        <wheelDiameter>0.1</wheelDiameter>
        <robotBaseFrame>base_link</robotBaseFrame>
        <torque>20</torque>
        <topicName>cmd_vel</topicName>
        <broadcastTF>true</broadcastTF>
      </plugin>
    </gazebo>
-->
  <gazebo>
    <plugin filename="libgazebo_ros_control.so" name="gazebo_ros_control">
      <robotSimType>gazebo_ros_control/DefaultRobotHWSim</robotSimType>
    </plugin>
    <!--        <plugin filename="libgazebo_ros_imu.so" name="gazebo_ros_imu_controller">
            <robotNamespace>/nao_dcm</robotNamespace>
            <topicName>imu_data</topicName>
            <bodyName>imu</bodyName>
            <frameId>ImuAccelerometer_frame</frameId>
            <gaussianNoise>2.89e-08</gaussianNoise>
            <accelGaussianNoise>2.89e-08 2.89e-08 2.89e-08</accelGaussianNoise>
            <rateGaussianNoise>2.89e-08 2.89e-08 2.89e-08</rateGaussianNoise>
            <headingGaussianNoise>2.89e-08 2.89e-08 2.89e-08</headingGaussianNoise>
            <xyzOffsets>0 0 0</xyzOffsets>
            <rpyOffsets>0 0 0</rpyOffsets>
            <updateRate>30.0</updateRate>
            <alwaysOn>true</alwaysOn>
        </plugin>
-->
    <!--        <plugin name="gazebo_ros_imu_controller" filename="">
            <robotNamespace>/nao_dcm</robotNamespace>
            <topicName>imu_data</topicName>
            <bodyName>imu</bodyName>
            <frameId>imu</frameId>
            <gaussianNoise>2.89e-08</gaussianNoise>
            <accelGaussianNoise>2.89e-08 2.89e-08 2.89e-08</accelGaussianNoise>
            <rateGaussianNoise>2.89e-08 2.89e-08 2.89e-08</rateGaussianNoise>
            <headingGaussianNoise>2.89e-08 2.89e-08 2.89e-08</headingGaussianNoise>
            <xyzOffsets>0 0 0</xyzOffsets>
            <rpyOffsets>0 0 0</rpyOffsets>
            <updateRate>30.0</updateRate>
            <alwaysOn>true</alwaysOn>
        </plugin>
-->
    <!-- Mimic joints through plugin develop by costashatz based on implementation by Goncalo Cabrita -->
    <plugin filename="libroboticsgroup_gazebo_mimic_joint_plugin.so" name="mimic_hipyawpitch">
      <joint>LHipYawPitch</joint>
      <mimicJoint>RHipYawPitch</mimicJoint>
      <multiplier>1.0</multiplier>
      <offset>0.0</offset>
    </plugin>
    <plugin filename="libroboticsgroup_gazebo_mimic_joint_plugin.so" name="mimic_LFinger01">
      <joint>nao_1/LHand</joint>
      <mimicJoint>nao_1/LFinger01</mimicJoint>
      <multiplier>-0.785398163398</multiplier>
      <offset>0.785398163398</offset>
    </plugin>
    <plugin filename="libroboticsgroup_gazebo_mimic_joint_plugin.so" name="mimic_LFinger02">
      <joint>nao_1/LHand</joint>
      <mimicJoint>nao_1/LFinger02</mimicJoint>
      <multiplier>-0.785398163398</multiplier>
      <offset>0.785398163398</offset>
    </plugin>
    <plugin filename="libroboticsgroup_gazebo_mimic_joint_plugin.so" name="mimic_LFinger03">
      <joint>nao_1/LHand</joint>
      <mimicJoint>nao_1/LFinger03</mimicJoint>
      <multiplier>-0.785398163398</multiplier>
      <offset>0.785398163398</offset>
    </plugin>
    <plugin filename="libroboticsgroup_gazebo_mimic_joint_plugin.so" name="mimic_LFinger01">
      <joint>nao_1/LHand</joint>
      <mimicJoint>nao_1/LFinger01</mimicJoint>
      <multiplier>-0.785398163398</multiplier>
      <offset>0.785398163398</offset>
    </plugin>
    <plugin filename="libroboticsgroup_gazebo_mimic_joint_plugin.so" name="mimic_LFinger02">
      <joint>nao_1/LHand</joint>
      <mimicJoint>nao_1/LFinger02</mimicJoint>
      <multiplier>-0.785398163398</multiplier>
      <offset>0.785398163398</offset>
    </plugin>
    <plugin filename="libroboticsgroup_gazebo_mimic_joint_plugin.so" name="mimic_LFinger03">
      <joint>nao_1/LHand</joint>
      <mimicJoint>nao_1/LFinger03</mimicJoint>
      <multiplier>-0.785398163398</multiplier>
      <offset>0.785398163398</offset>
    </plugin>
    <plugin filename="libroboticsgroup_gazebo_mimic_joint_plugin.so" name="mimic_RFinger01">
      <joint>nao_1/RHand</joint>
      <mimicJoint>nao_1/RFinger01</mimicJoint>
      <multiplier>-0.785398163398</multiplier>
      <offset>0.785398163398</offset>
    </plugin>
    <plugin filename="libroboticsgroup_gazebo_mimic_joint_plugin.so" name="mimic_RFinger02">
      <joint>nao_1/RHand</joint>
      <mimicJoint>nao_1/RFinger02</mimicJoint>
      <multiplier>-0.785398163398</multiplier>
      <offset>0.785398163398</offset>
    </plugin>
    <plugin filename="libroboticsgroup_gazebo_mimic_joint_plugin.so" name="mimic_RFinger03">
      <joint>nao_1/RHand</joint>
      <mimicJoint>nao_1/RFinger03</mimicJoint>
      <multiplier>-0.785398163398</multiplier>
      <offset>0.785398163398</offset>
    </plugin>
    <plugin filename="libroboticsgroup_gazebo_mimic_joint_plugin.so" name="mimic_RFinger01">
      <joint>nao_1/RHand</joint>
      <mimicJoint>nao_1/RFinger01</mimicJoint>
      <multiplier>-0.785398163398</multiplier>
      <offset>0.785398163398</offset>
    </plugin>
    <plugin filename="libroboticsgroup_gazebo_mimic_joint_plugin.so" name="mimic_RFinger02">
      <joint>nao_1/RHand</joint>
      <mimicJoint>nao_1/RFinger02</mimicJoint>
      <multiplier>-0.785398163398</multiplier>
      <offset>0.785398163398</offset>
    </plugin>
    <plugin filename="libroboticsgroup_gazebo_mimic_joint_plugin.so" name="mimic_RFinger03">
      <joint>nao_1/RHand</joint>
      <mimicJoint>nao_1/RFinger03</mimicJoint>
      <multiplier>-0.785398163398</multiplier>
      <offset>0.785398163398</offset>
    </plugin>
    <plugin filename="libroboticsgroup_gazebo_mimic_joint_plugin.so" name="LThumb1">
      <joint>nao_1/LHand</joint>
      <mimicJoint>nao_1/LThumb1</mimicJoint>
      <multiplier>-0.785398163398</multiplier>
      <offset>0.785398163398</offset>
    </plugin>
    <plugin filename="libroboticsgroup_gazebo_mimic_joint_plugin.so" name="LThumb2">
      <joint>nao_1/LHand</joint>
      <mimicJoint>nao_1/LThumb2</mimicJoint>
      <multiplier>-0.785398163398</multiplier>
      <offset>0.785398163398</offset>
    </plugin>
    <plugin filename="libroboticsgroup_gazebo_mimic_joint_plugin.so" name="RThumb1">
      <joint>nao_1/RHand</joint>
      <mimicJoint>nao_1/RThumb1</mimicJoint>
      <multiplier>-0.785398163398</multiplier>
      <offset>0.785398163398</offset>
    </plugin>
    <plugin filename="libroboticsgroup_gazebo_mimic_joint_plugin.so" name="RThumb2">
      <joint>nao_1/RHand</joint>
      <mimicJoint>nao_1/RThumb2</mimicJoint>
      <multiplier>-0.785398163398</multiplier>
      <offset>0.785398163398</offset>
    </plugin>
    <plugin filename="libroboticsgroup_gazebo_disable_link_plugin.so" name="LFinger11_link">
      <link>nao_1/LFinger11_link</link>
    </plugin>
    <plugin filename="libroboticsgroup_gazebo_disable_link_plugin.so" name="LFinger12_link">
      <link>nao_1/LFinger12_link</link>
    </plugin>
    <plugin filename="libroboticsgroup_gazebo_disable_link_plugin.so" name="LFinger13_link">
      <link>nao_1/LFinger13_link</link>
    </plugin>
    <plugin filename="libroboticsgroup_gazebo_disable_link_plugin.so" name="LFinger21_link">
      <link>nao_1/LFinger21_link</link>
    </plugin>
    <plugin filename="libroboticsgroup_gazebo_disable_link_plugin.so" name="LFinger22_link">
      <link>nao_1/LFinger22_link</link>
    </plugin>
    <plugin filename="libroboticsgroup_gazebo_disable_link_plugin.so" name="LFinger23_link">
      <link>nao_1/LFinger23_link</link>
    </plugin>
    <plugin filename="libroboticsgroup_gazebo_disable_link_plugin.so" name="LThumb1_link">
      <link>nao_1/LThumb1_link</link>
    </plugin>
    <plugin filename="libroboticsgroup_gazebo_disable_link_plugin.so" name="LThumb2_link">
      <link>nao_1/LThumb2_link</link>
    </plugin>
    <plugin filename="libroboticsgroup_gazebo_disable_link_plugin.so" name="l_gripper">
      <link>nao_1/l_gripper</link>
    </plugin>
    <plugin filename="libroboticsgroup_gazebo_disable_link_plugin.so" name="RFinger11_link">
      <link>nao_1/RFinger11_link</link>
    </plugin>
    <plugin filename="libroboticsgroup_gazebo_disable_link_plugin.so" name="RFinger12_link">
      <link>nao_1/RFinger12_link</link>
    </plugin>
    <plugin filename="libroboticsgroup_gazebo_disable_link_plugin.so" name="RFinger13_link">
      <link>nao_1/RFinger13_link</link>
    </plugin>
    <plugin filename="libroboticsgroup_gazebo_disable_link_plugin.so" name="RFinger21_link">
      <link>nao_1/RFinger21_link</link>
    </plugin>
    <plugin filename="libroboticsgroup_gazebo_disable_link_plugin.so" name="RFinger22_link">
      <link>nao_1/RFinger22_link</link>
    </plugin>
    <plugin filename="libroboticsgroup_gazebo_disable_link_plugin.so" name="RFinger23_link">
      <link>nao_1/RFinger23_link</link>
    </plugin>
    <plugin filename="libroboticsgroup_gazebo_disable_link_plugin.so" name="RThumb1_link">
      <link>nao_1/RThumb1_link</link>
    </plugin>
    <plugin filename="libroboticsgroup_gazebo_disable_link_plugin.so" name="RThumb2_link">
      <link>nao_1/RThumb2_link</link>
    </plugin>
    <plugin filename="libroboticsgroup_gazebo_disable_link_plugin.so" name="r_gripper">
      <link>nao_1/r_gripper</link>
    </plugin>
  </gazebo>
  <!-- END OF GAZEBO ROS CONTROL PLUGIN -->
  <!-- GAZEBO MATERIALS -->
  <gazebo reference="nao_1/torso">
    <mu1>0.5</mu1>
    <mu2>0.5</mu2>
    <selfCollide>false</selfCollide>
    <turnGravityOff>false</turnGravityOff>
  </gazebo>
  <gazebo reference="nao_1/Neck">
    <mu1>0.5</mu1>
    <mu2>0.5</mu2>
    <selfCollide>false</selfCollide>
    <turnGravityOff>false</turnGravityOff>
  </gazebo>
  <gazebo reference="nao_1/Head">
    <mu1>0.5</mu1>
    <mu2>0.5</mu2>
    <selfCollide>false</selfCollide>
    <turnGravityOff>false</turnGravityOff>
  </gazebo>
  <gazebo reference="nao_1/gaze">
    <mu1>0.5</mu1>
    <mu2>0.5</mu2>
    <selfCollide>false</selfCollide>
    <turnGravityOff>false</turnGravityOff>
  </gazebo>
  <!--    <gazebo reference="LShoulderDummy">
        <mu1>0.5</mu1>
        <mu2>0.5</mu2>
        <selfCollide>false</selfCollide>
        <turnGravityOff>false</turnGravityOff>
    </gazebo>
    <gazebo reference="RShoulderDummy">
        <mu1>0.5</mu1>
        <mu2>0.5</mu2>
        <selfCollide>false</selfCollide>
        <turnGravityOff>false</turnGravityOff>
    </gazebo> -->
  <!-- ARMS -->
  <gazebo reference="nao_1/LShoulder">
    <mu1>0.5</mu1>
    <mu2>0.5</mu2>
    <selfCollide>false</selfCollide>
    <turnGravityOff>false</turnGravityOff>
  </gazebo>
  <gazebo reference="nao_1/LBicep">
    <mu1>0.5</mu1>
    <mu2>0.5</mu2>
    <selfCollide>false</selfCollide>
    <turnGravityOff>false</turnGravityOff>
  </gazebo>
  <gazebo reference="nao_1/LElbow">
    <mu1>0.5</mu1>
    <mu2>0.5</mu2>
    <selfCollide>false</selfCollide>
    <turnGravityOff>false</turnGravityOff>
  </gazebo>
  <gazebo reference="nao_1/LForeArm">
    <mu1>0.5</mu1>
    <mu2>0.5</mu2>
    <selfCollide>false</selfCollide>
    <turnGravityOff>false</turnGravityOff>
  </gazebo>
  <gazebo reference="nao_1/l_wrist">
    <mu1>0.5</mu1>
    <mu2>0.5</mu2>
    <selfCollide>false</selfCollide>
    <turnGravityOff>false</turnGravityOff>
  </gazebo>
  <gazebo reference="nao_1/l_gripper">
    <mu1>0.5</mu1>
    <mu2>0.5</mu2>
    <selfCollide>false</selfCollide>
    <turnGravityOff>true</turnGravityOff>
  </gazebo>
  <gazebo reference="nao_1/RShoulder">
    <mu1>0.5</mu1>
    <mu2>0.5</mu2>
    <selfCollide>false</selfCollide>
    <turnGravityOff>false</turnGravityOff>
  </gazebo>
  <gazebo reference="nao_1/RBicep">
    <mu1>0.5</mu1>
    <mu2>0.5</mu2>
    <selfCollide>false</selfCollide>
    <turnGravityOff>false</turnGravityOff>
  </gazebo>
  <gazebo reference="nao_1/RElbow">
    <mu1>0.5</mu1>
    <mu2>0.5</mu2>
    <selfCollide>false</selfCollide>
    <turnGravityOff>false</turnGravityOff>
  </gazebo>
  <gazebo reference="nao_1/RForeArm">
    <mu1>0.5</mu1>
    <mu2>0.5</mu2>
    <selfCollide>false</selfCollide>
    <turnGravityOff>false</turnGravityOff>
  </gazebo>
  <gazebo reference="nao_1/r_wrist">
    <mu1>0.5</mu1>
    <mu2>0.5</mu2>
    <selfCollide>false</selfCollide>
    <turnGravityOff>false</turnGravityOff>
  </gazebo>
  <gazebo reference="nao_1/r_gripper">
    <mu1>0.5</mu1>
    <mu2>0.5</mu2>
    <selfCollide>false</selfCollide>
    <turnGravityOff>true</turnGravityOff>
  </gazebo>
  <!--    <gazebo reference="LElbowDummy">
        <mu1>0.5</mu1>
        <mu2>0.5</mu2>
        <selfCollide>false</selfCollide>
        <turnGravityOff>false</turnGravityOff>
    </gazebo>
-->
  <gazebo reference="nao_1/LFinger11_link">
    <mu1>0.5</mu1>
    <mu2>0.5</mu2>
    <selfCollide>false</selfCollide>
    <turnGravityOff>false</turnGravityOff>
  </gazebo>
  <gazebo reference="nao_1/LFinger12_link">
    <mu1>0.5</mu1>
    <mu2>0.5</mu2>
    <selfCollide>false</selfCollide>
    <turnGravityOff>false</turnGravityOff>
  </gazebo>
  <gazebo reference="nao_1/LFinger13_link">
    <mu1>0.5</mu1>
    <mu2>0.5</mu2>
    <selfCollide>false</selfCollide>
    <turnGravityOff>false</turnGravityOff>
  </gazebo>
  <gazebo reference="nao_1/LFinger21_link">
    <mu1>0.5</mu1>
    <mu2>0.5</mu2>
    <selfCollide>false</selfCollide>
    <turnGravityOff>false</turnGravityOff>
  </gazebo>
  <gazebo reference="nao_1/LFinger22_link">
    <mu1>0.5</mu1>
    <mu2>0.5</mu2>
    <selfCollide>false</selfCollide>
    <turnGravityOff>false</turnGravityOff>
  </gazebo>
  <gazebo reference="nao_1/LFinger23_link">
    <mu1>0.5</mu1>
    <mu2>0.5</mu2>
    <selfCollide>false</selfCollide>
    <turnGravityOff>false</turnGravityOff>
  </gazebo>
  <gazebo reference="nao_1/LThumb1_link">
    <mu1>0.5</mu1>
    <mu2>0.5</mu2>
    <selfCollide>false</selfCollide>
    <turnGravityOff>false</turnGravityOff>
  </gazebo>
  <gazebo reference="nao_1/LThumb2_link">
    <mu1>0.5</mu1>
    <mu2>0.5</mu2>
    <selfCollide>false</selfCollide>
    <turnGravityOff>false</turnGravityOff>
  </gazebo>
  <gazebo reference="nao_1/LPelvis">
    <mu1>0.5</mu1>
    <mu2>0.5</mu2>
    <selfCollide>false</selfCollide>
    <turnGravityOff>false</turnGravityOff>
  </gazebo>
  <gazebo reference="nao_1/LHip">
    <mu1>0.5</mu1>
    <mu2>0.5</mu2>
    <selfCollide>false</selfCollide>
    <turnGravityOff>false</turnGravityOff>
  </gazebo>
  <gazebo reference="nao_1/LThigh">
    <mu1>0.5</mu1>
    <mu2>0.5</mu2>
    <selfCollide>false</selfCollide>
    <turnGravityOff>false</turnGravityOff>
  </gazebo>
  <gazebo reference="nao_1/LTibia">
    <mu1>0.5</mu1>
    <mu2>0.5</mu2>
    <selfCollide>false</selfCollide>
    <turnGravityOff>false</turnGravityOff>
  </gazebo>
  <!-- left leg wheels -->
  <gazebo reference="nao_1/left_wheel_link_l">
    <mu1>0.5</mu1>
    <mu2>0.5</mu2>
    <selfCollide>false</selfCollide>
    <turnGravityOff>false</turnGravityOff>
    <material>Gazebo/Gray</material>
  </gazebo>
  <gazebo reference="nao_1/left_wheel_link_r">
    <mu1>0.5</mu1>
    <mu2>0.5</mu2>
    <selfCollide>false</selfCollide>
    <turnGravityOff>false</turnGravityOff>
    <material>Gazebo/Gray</material>
  </gazebo>
  <gazebo reference="nao_1/front_left_wheel_link_l">
    <mu1>0.5</mu1>
    <mu2>0.5</mu2>
    <selfCollide>false</selfCollide>
    <turnGravityOff>false</turnGravityOff>
    <material>Gazebo/Gray</material>
  </gazebo>
  <gazebo reference="nao_1/front_left_wheel_link_r">
    <mu1>0.5</mu1>
    <mu2>0.5</mu2>
    <selfCollide>false</selfCollide>
    <turnGravityOff>false</turnGravityOff>
    <material>Gazebo/Gray</material>
  </gazebo>
  <!-- right wheels -->
  <gazebo reference="nao_1/right_wheel_link_l">
    <mu1>0.5</mu1>
    <mu2>0.5</mu2>
    <selfCollide>false</selfCollide>
    <turnGravityOff>false</turnGravityOff>
    <material>Gazebo/Gray</material>
  </gazebo>
  <gazebo reference="nao_1/right_wheel_link_r">
    <mu1>0.5</mu1>
    <mu2>0.5</mu2>
    <selfCollide>false</selfCollide>
    <turnGravityOff>false</turnGravityOff>
    <material>Gazebo/Gray</material>
  </gazebo>
  <gazebo reference="nao_1/front_right_wheel_link_l">
    <mu1>0.5</mu1>
    <mu2>0.5</mu2>
    <selfCollide>false</selfCollide>
    <turnGravityOff>false</turnGravityOff>
    <material>Gazebo/Gray</material>
  </gazebo>
  <gazebo reference="nao_1/front_right_wheel_link_r">
    <mu1>0.5</mu1>
    <mu2>0.5</mu2>
    <selfCollide>false</selfCollide>
    <turnGravityOff>false</turnGravityOff>
    <material>Gazebo/Gray</material>
  </gazebo>
  <gazebo reference="nao_1/LAnklePitch">
    <mu1>0.5</mu1>
    <mu2>0.5</mu2>
    <selfCollide>false</selfCollide>
    <turnGravityOff>false</turnGravityOff>
  </gazebo>
  <gazebo reference="nao_1/l_ankle">
    <mu1>0.5</mu1>
    <mu2>0.5</mu2>
    <selfCollide>false</selfCollide>
    <turnGravityOff>false</turnGravityOff>
    <fdir1>1 0 0</fdir1>
    <maxVel>0.1</maxVel>
    <minDepth>0.003</minDepth>
  </gazebo>
  <gazebo reference="nao_1/RPelvis">
    <mu1>0.5</mu1>
    <mu2>0.5</mu2>
    <selfCollide>false</selfCollide>
    <turnGravityOff>false</turnGravityOff>
  </gazebo>
  <gazebo reference="nao_1/RHip">
    <mu1>0.5</mu1>
    <mu2>0.5</mu2>
    <selfCollide>false</selfCollide>
    <turnGravityOff>false</turnGravityOff>
  </gazebo>
  <gazebo reference="nao_1/RThigh">
    <mu1>0.5</mu1>
    <mu2>0.5</mu2>
    <selfCollide>false</selfCollide>
    <turnGravityOff>false</turnGravityOff>
  </gazebo>
  <gazebo reference="nao_1/RTibia">
    <mu1>0.5</mu1>
    <mu2>0.5</mu2>
    <selfCollide>false</selfCollide>
    <turnGravityOff>false</turnGravityOff>
  </gazebo>
  <gazebo reference="nao_1/RAnklePitch">
    <mu1>0.5</mu1>
    <mu2>0.5</mu2>
    <selfCollide>false</selfCollide>
    <turnGravityOff>false</turnGravityOff>
  </gazebo>
  <gazebo reference="nao_1/r_ankle">
    <mu1>0.5</mu1>
    <mu2>0.5</mu2>
    <selfCollide>false</selfCollide>
    <turnGravityOff>false</turnGravityOff>
    <fdir1>1 0 0</fdir1>
    <maxVel>0.1</maxVel>
    <minDepth>0.003</minDepth>
  </gazebo>
  <gazebo reference="nao_1/RFinger11_link">
    <mu1>0.5</mu1>
    <mu2>0.5</mu2>
    <selfCollide>false</selfCollide>
    <turnGravityOff>false</turnGravityOff>
  </gazebo>
  <gazebo reference="nao_1/RFinger12_link">
    <mu1>0.5</mu1>
    <mu2>0.5</mu2>
    <selfCollide>false</selfCollide>
    <turnGravityOff>false</turnGravityOff>
  </gazebo>
  <gazebo reference="nao_1/RFinger13_link">
    <mu1>0.5</mu1>
    <mu2>0.5</mu2>
    <selfCollide>false</selfCollide>
    <turnGravityOff>false</turnGravityOff>
  </gazebo>
  <gazebo reference="nao_1/RFinger21_link">
    <mu1>0.5</mu1>
    <mu2>0.5</mu2>
    <selfCollide>false</selfCollide>
    <turnGravityOff>false</turnGravityOff>
  </gazebo>
  <gazebo reference="nao_1/RFinger22_link">
    <mu1>0.5</mu1>
    <mu2>0.5</mu2>
    <selfCollide>false</selfCollide>
    <turnGravityOff>false</turnGravityOff>
  </gazebo>
  <gazebo reference="nao_1/RFinger23_link">
    <mu1>0.5</mu1>
    <mu2>0.5</mu2>
    <selfCollide>false</selfCollide>
    <turnGravityOff>false</turnGravityOff>
  </gazebo>
  <gazebo reference="nao_1/RThumb1_link">
    <mu1>0.5</mu1>
    <mu2>0.5</mu2>
    <selfCollide>false</selfCollide>
    <turnGravityOff>false</turnGravityOff>
  </gazebo>
  <gazebo reference="nao_1/RThumb2_link">
    <mu1>0.5</mu1>
    <mu2>0.5</mu2>
    <selfCollide>false</selfCollide>
    <turnGravityOff>false</turnGravityOff>
  </gazebo>
  <!--

        RGB CAMERAS: Working
-->
  <gazebo reference="nao_1/CameraTop_frame">
    <sensor name="CameraTop" type="camera">
      <update_rate>5.0</update_rate>
      <camera name="camera_top">
        <horizontal_fov>1.06290551</horizontal_fov>
        <image>
          <width>640</width>
          <height>480</height>
          <format>R8G8B8</format>
        </image>
        <clip>
          <near>0.03</near>
          <far>500</far>
        </clip>
        <noise>
          <type>gaussian</type>
          <mean>0.0</mean>
          <stddev>0.007</stddev>
        </noise>
      </camera>
      <plugin filename="libgazebo_ros_camera.so" name="camera_controller">
        <alwaysOn>true</alwaysOn>
        <updateRate>5.0</updateRate>
        <cameraName>camera_Top</cameraName>
        <imageTopicName>image_raw</imageTopicName>
        <cameraInfoTopicName>camera_info</cameraInfoTopicName>
        <frameName>nao_1/CameraTop_optical_frame</frameName>
        <hackBaseline>0.07</hackBaseline>
        <distortionK1>-0.0545211</distortionK1>
        <distortionK2>0.06919734</distortionK2>
        <distortionK3>-0.0241095</distortionK3>
        <distortionT1>-0.0112245</distortionT1>
        <distortionT2>0.0</distortionT2>
      </plugin>
    </sensor>
  </gazebo>
  <gazebo reference="nao_1/CameraBottom_frame">
    <sensor name="CameraBottom" type="depth">
      <always_on>true</always_on>
      <update_rate>20.0</update_rate>
      <camera name="camera_bottom">
        <horizontal_fov>1.06290551</horizontal_fov>
        <image>
          <width>640</width>
          <height>480</height>
          <format>R8G8B8</format>
        </image>
        <clip>
          <near>0.05</near>
          <far>500</far>
        </clip>
      </camera>
      <plugin filename="libgazebo_ros_openni_kinect.so" name="kinect_camera_controller">
        <alwaysOn>true</alwaysOn>
        <updateRate>20.0</updateRate>
        <cameraName>kinect_camera_Bottom</cameraName>
        <imageTopicName>kinect/image_raw</imageTopicName>
        <cameraInfoTopicName>kinect/camera_info</cameraInfoTopicName>
        <frameName>nao_1/CameraBottom_optical_frame</frameName>
        <depthImageTopicName>depth/image_raw</depthImageTopicName>
        <depthImageInfoTopicName>depth/camera_info</depthImageInfoTopicName>
        <pointCloudTopicName>depth/points</pointCloudTopicName>
        <pointCloudCutoff>0.5</pointCloudCutoff>
        <distortionK1>0.00000001</distortionK1>
        <distortionK2>0.00000001</distortionK2>
        <distortionK3>0.00000001</distortionK3>
        <distortionT1>0.00000001</distortionT1>
        <distortionT2>0.00000001</distortionT2>
        <CxPrime>0</CxPrime>
        <Cx>0</Cx>
        <Cy>0</Cy>
        <focalLength>0</focalLength>
        <hackBaseline>0</hackBaseline>
      </plugin>
    </sensor>
  </gazebo>
  <gazebo reference="nao_1/Rplidar_frame">
    <sensor name="rplidar" type="ray">
      <pose>0 0 0 0 0 0</pose>
      <visualize>false</visualize>
      <update_rate>5.5</update_rate>
      <ray>
        <scan>
          <horizontal>
            <samples>360</samples>
            <resolution>1</resolution>
            <min_angle>-3</min_angle>
            <max_angle>3</max_angle>
          </horizontal>
        </scan>
        <range>
          <min>0.10</min>
          <max>6.0</max>
          <resolution>0.01</resolution>
        </range>
        <noise>
          <type>gaussian</type>
          <mean>0.0</mean>
          <stddev>0.01</stddev>
        </noise>
      </ray>
      <plugin filename="libgazebo_ros_laser.so" name="gazebo_rplidar">
        <topicName>scan</topicName>
        <frameName>nao_1/Rplidar_frame</frameName>
      </plugin>
    </sensor>
  </gazebo>
  <!--

        CameraDepth : not displayed at the right spot

<gazebo reference="CameraDepth3_frame">
    <sensor type="depth" name="openni_camera_camera2">
        <always_on>1</always_on>
        <visualize>true</visualize>
        <camera>
            <horizontal_fov>1.01229</horizontal_fov>
            <image>
                <width>320</width>
                <height>240</height>
                <format>R8G8B8</format>
            </image>
            <depth_camera>

            </depth_camera>
            <clip>
                <near>0.1</near>
                <far>100</far>
            </clip>
        </camera>
        <plugin name="depth_cam_controller2" filename="libgazebo_ros_openni_kinect.so">
            <baseline>0.2</baseline>
            <alwaysOn>true</alwaysOn>
            <updateRate>0.1</updateRate>
            <cameraName>xtion2</cameraName>
            <imageTopicName>/xtion2/ir/image_raw</imageTopicName>
            <cameraInfoTopicName>/xtion2/ir/camera_info</cameraInfoTopicName>
            <depthImageTopicName>/xtion2/depth/image_raw</depthImageTopicName>
            <depthImageInfoTopicName>/xtion2/depth/camera_info</depthImageInfoTopicName>
            <pointCloudTopicName>/xtion2/depth/points</pointCloudTopicName>
            <frameName>CameraDepth2_frame</frameName>
            <pointCloudCutoff>0.5</pointCloudCutoff>
            <distortionK1>0.00000001</distortionK1>
            <distortionK2>0.00000001</distortionK2>
            <distortionK3>0.00000001</distortionK3>
            <distortionT1>0.00000001</distortionT1>
            <distortionT2>0.00000001</distortionT2>
            <CxPrime>0</CxPrime>
            <Cx>0</Cx>
            <Cy>0</Cy>
            <focalLength>0</focalLength>
            <hackBaseline>0</hackBaseline>
        </plugin>
    </sensor>
</gazebo>
-->
  <!--
    BUMPERS + FSR
libgazebo_ros_bumper.so bugged right now, waiting for new release


<gazebo reference="LFootBumper_frame">
  <sensor type="contact" name="LFootBumper">
    <update_rate>10</update_rate>
    <contact>
      <collision>LFootBumper_frame_collision</collision>
    </contact>
    <plugin filename="libgazebo_ros_bumper.so" name="gazebo_nao_ros_bumper">
      <alwaysOn>true</alwaysOn>
      <bumperTopicName>LFootBumper</bumperTopicName>
      <frameName>LFootBumper_frame</frameName>
    </plugin>
  </sensor>
</gazebo>
-->
  <gazebo reference="nao_1/RFsrFL_frame">
    <mu1>0.5</mu1>
    <mu2>0.5</mu2>
    <selfCollide>false</selfCollide>
    <turnGravityOff>false</turnGravityOff>
    <fdir1>1 0 0</fdir1>
    <maxVel>0.1</maxVel>
    <minDepth>0.003</minDepth>
    <sensor name="RFsrFL" type="contact">
      <always_on>1</always_on>
      <update_rate>20</update_rate>
      <visualize>false</visualize>
      <contact>
        <collision>RFsrFL_frame_collision</collision>
      </contact>
      <plugin filename="libgazebo_ros_bumper.so" name="gazebo_nao_RFsrFL">
        <robotNamespace>nao_robot</robotNamespace>
        <alwaysOn>true</alwaysOn>
        <bumperTopicName>FSR/RFoot/FrontLeft</bumperTopicName>
        <frameName>RFsrFL_frame</frameName>
      </plugin>
    </sensor>
  </gazebo>
  <gazebo reference="nao_1/RFsrFR_frame">
    <mu1>0.5</mu1>
    <mu2>0.5</mu2>
    <selfCollide>false</selfCollide>
    <turnGravityOff>false</turnGravityOff>
    <fdir1>1 0 0</fdir1>
    <maxVel>0.1</maxVel>
    <minDepth>0.003</minDepth>
    <sensor name="RFsrFR" type="contact">
      <always_on>1</always_on>
      <update_rate>20</update_rate>
      <visualize>false</visualize>
      <contact>
        <collision>RFsrFR_frame_collision</collision>
      </contact>
      <plugin filename="libgazebo_ros_bumper.so" name="gazebo_nao_RFsrFR">
        <robotNamespace>nao_robot</robotNamespace>
        <alwaysOn>true</alwaysOn>
        <bumperTopicName>FSR/RFoot/FrontRight</bumperTopicName>
        <frameName>RFsrFR_frame</frameName>
      </plugin>
    </sensor>
  </gazebo>
  <gazebo reference="nao_1/RFsrRL_frame">
    <mu1>0.5</mu1>
    <mu2>0.5</mu2>
    <selfCollide>false</selfCollide>
    <turnGravityOff>false</turnGravityOff>
    <fdir1>1 0 0</fdir1>
    <maxVel>0.1</maxVel>
    <minDepth>0.003</minDepth>
    <sensor name="RFsrRL" type="contact">
      <always_on>1</always_on>
      <update_rate>20</update_rate>
      <visualize>false</visualize>
      <contact>
        <collision>RFsrRL_frame_collision</collision>
      </contact>
      <plugin filename="libgazebo_ros_bumper.so" name="gazebo_nao_RFsrRL">
        <robotNamespace>nao_robot</robotNamespace>
        <alwaysOn>true</alwaysOn>
        <bumperTopicName>FSR/RFoot/RearLeft</bumperTopicName>
        <frameName>RFsrRL_frame</frameName>
      </plugin>
    </sensor>
  </gazebo>
  <gazebo reference="nao_1/RFsrRR_frame">
    <mu1>0.5</mu1>
    <mu2>0.5</mu2>
    <selfCollide>false</selfCollide>
    <turnGravityOff>false</turnGravityOff>
    <fdir1>1 0 0</fdir1>
    <maxVel>0.1</maxVel>
    <minDepth>0.003</minDepth>
    <sensor name="RFsrRR" type="contact">
      <always_on>1</always_on>
      <update_rate>20</update_rate>
      <visualize>false</visualize>
      <contact>
        <collision>RFsrRR_frame_collision</collision>
      </contact>
      <plugin filename="libgazebo_ros_bumper.so" name="gazebo_nao_RFsrRR">
        <robotNamespace>nao_robot</robotNamespace>
        <alwaysOn>true</alwaysOn>
        <bumperTopicName>FSR/RFoot/RearRight</bumperTopicName>
        <frameName>RFsrRR_frame</frameName>
      </plugin>
    </sensor>
  </gazebo>
  <gazebo reference="nao_1/LFsrFL_frame">
    <mu1>0.5</mu1>
    <mu2>0.5</mu2>
    <selfCollide>false</selfCollide>
    <turnGravityOff>false</turnGravityOff>
    <fdir1>1 0 0</fdir1>
    <maxVel>0.1</maxVel>
    <minDepth>0.003</minDepth>
    <sensor name="LFsrFL" type="contact">
      <always_on>1</always_on>
      <update_rate>20</update_rate>
      <visualize>false</visualize>
      <contact>
        <collision>LFsrFL_frame_collision</collision>
      </contact>
      <plugin filename="libgazebo_ros_bumper.so" name="gazebo_nao_LFsrFL">
        <robotNamespace>nao_robot</robotNamespace>
        <alwaysOn>true</alwaysOn>
        <bumperTopicName>FSR/LFoot/FrontLeft</bumperTopicName>
        <frameName>LFsrFL_frame</frameName>
      </plugin>
    </sensor>
  </gazebo>
  <gazebo reference="nao_1/LFsrFR_frame">
    <mu1>0.5</mu1>
    <mu2>0.5</mu2>
    <selfCollide>false</selfCollide>
    <turnGravityOff>false</turnGravityOff>
    <fdir1>1 0 0</fdir1>
    <maxVel>0.1</maxVel>
    <minDepth>0.003</minDepth>
    <sensor name="LFsrFR" type="contact">
      <always_on>1</always_on>
      <update_rate>20</update_rate>
      <visualize>false</visualize>
      <contact>
        <collision>LFsrFR_frame_collision</collision>
      </contact>
      <plugin filename="libgazebo_ros_bumper.so" name="gazebo_nao_ros_bumper">
        <robotNamespace>nao_robot</robotNamespace>
        <alwaysOn>true</alwaysOn>
        <bumperTopicName>FSR/LFoot/FrontRight</bumperTopicName>
        <frameName>LFsrFR_frame</frameName>
      </plugin>
    </sensor>
  </gazebo>
  <gazebo reference="nao_1/LFsrRL_frame">
    <mu1>0.5</mu1>
    <mu2>0.5</mu2>
    <selfCollide>false</selfCollide>
    <turnGravityOff>false</turnGravityOff>
    <fdir1>1 0 0</fdir1>
    <maxVel>0.1</maxVel>
    <minDepth>0.003</minDepth>
    <sensor name="LFsrRL" type="contact">
      <always_on>1</always_on>
      <update_rate>20</update_rate>
      <visualize>false</visualize>
      <contact>
        <collision>LFsrRL_frame_collision</collision>
      </contact>
      <plugin filename="libgazebo_ros_bumper.so" name="gazebo_nao_ros_bumper">
        <robotNamespace>nao_robot</robotNamespace>
        <alwaysOn>true</alwaysOn>
        <bumperTopicName>FSR/LFoot/RearLeft</bumperTopicName>
        <frameName>LFsrRL_frame</frameName>
      </plugin>
    </sensor>
  </gazebo>
  <gazebo reference="nao_1/LFsrRR_frame">
    <mu1>0.5</mu1>
    <mu2>0.5</mu2>
    <selfCollide>false</selfCollide>
    <turnGravityOff>false</turnGravityOff>
    <fdir1>1 0 0</fdir1>
    <maxVel>0.1</maxVel>
    <minDepth>0.003</minDepth>
    <sensor name="LFsrRR" type="contact">
      <always_on>1</always_on>
      <update_rate>20</update_rate>
      <visualize>false</visualize>
      <contact>
        <collision>LFsrRR_frame_collision</collision>
      </contact>
      <plugin filename="libgazebo_ros_bumper.so" name="gazebo_nao_ros_bumper">
        <robotNamespace>nao_robot</robotNamespace>
        <alwaysOn>true</alwaysOn>
        <bumperTopicName>FSR/LFoot/RearRight</bumperTopicName>
        <frameName>LFsrRR_frame</frameName>
      </plugin>
    </sensor>
  </gazebo>
  <!--
    Sonars
-->
  <gazebo reference="nao_1/LSonar_frame">
    <sensor name="LSonar" type="ray">
      <pose>0 0 0 0 0 0</pose>
      <update_rate>20</update_rate>
      <visualize>false</visualize>
      <ray>
        <scan>
          <horizontal>
            <samples>5</samples>
            <resolution>1</resolution>
            <min_angle>-0.2617993877991494</min_angle>
            <max_angle>0.2617993877991494</max_angle>
            <!--
          <min_angle>-0.10</min_angle>
          <max_angle>0.10</max_angle>
-->
          </horizontal>
          <vertical>
            <samples>5</samples>
            <resolution>1</resolution>
            <min_angle>-0.13</min_angle>
            <max_angle>0.13</max_angle>
            <!--
          <min_angle>-0.2617993877991494</min_angle>
          <max_angle>0.2617993877991494</max_angle>
-->
          </vertical>
        </scan>
        <range>
          <min>0.025</min>
          <max>2.55</max>
          <resolution>1</resolution>
        </range>
      </ray>
      <plugin filename="libgazebo_ros_range.so" name="gazebo_ros_range">
        <robotNamespace>nao_robot</robotNamespace>
        <gaussianNoise>0.05</gaussianNoise>
        <alwaysOn>true</alwaysOn>
        <updateRate>20</updateRate>
        <topicName>sonar_left</topicName>
        <frameName>LSonar_frame</frameName>
        <minRange>0.025</minRange>
        <maxRange>2.55</maxRange>
        <fov>0.5235987755982988</fov>
        <!--      <fov>0.1</fov> -->
        <radiation>ultrasound</radiation>
      </plugin>
    </sensor>
  </gazebo>
  <gazebo reference="nao_1/RSonar_frame">
    <sensor name="RSonar" type="ray">
      <pose>0 0 0 0 0 0</pose>
      <update_rate>20</update_rate>
      <visualize>false</visualize>
      <ray>
        <scan>
          <horizontal>
            <samples>5</samples>
            <resolution>1</resolution>
            <min_angle>-0.2617993877991494</min_angle>
            <max_angle>0.2617993877991494</max_angle>
          </horizontal>
          <vertical>
            <samples>5</samples>
            <resolution>1</resolution>
            <min_angle>-0.13</min_angle>
            <max_angle>0.13</max_angle>
          </vertical>
        </scan>
        <range>
          <min>0.025</min>
          <max>2.55</max>
          <resolution>1</resolution>
        </range>
      </ray>
      <plugin filename="libgazebo_ros_range.so" name="gazebo_ros_range">
        <robotNamespace>nao_robot</robotNamespace>
        <gaussianNoise>0.05</gaussianNoise>
        <alwaysOn>true</alwaysOn>
        <updateRate>20</updateRate>
        <topicName>sonar_right</topicName>
        <frameName>RSonar_frame</frameName>
        <minRange>0.025</minRange>
        <maxRange>2.55</maxRange>
        <fov>0.5235987755982988</fov>
        <radiation>ultrasound</radiation>
      </plugin>
    </sensor>
  </gazebo>
  <!-- HEAD -->
  <transmission name="HeadYaw_Transmission">
    <type>transmission_interface/SimpleTransmission</type>
    <joint name="nao_1/HeadYaw">
      <hardwareInterface>hardware_interface/PositionJointInterface</hardwareInterface>
    </joint>
    <actuator name="HeadYaw_Motor">
      <!-- Dummy Values -->
      <hardwareInterface>hardware_interface/PositionJointInterface</hardwareInterface>
      <mechanicalReduction>150.27</mechanicalReduction>
    </actuator>
  </transmission>
  <transmission name="HeadPitch_Transmission">
    <type>transmission_interface/SimpleTransmission</type>
    <joint name="nao_1/HeadPitch">
      <hardwareInterface>hardware_interface/PositionJointInterface</hardwareInterface>
    </joint>
    <actuator name="HeadPitch_Motor">
      <!-- Dummy Values -->
      <hardwareInterface>hardware_interface/PositionJointInterface</hardwareInterface>
      <mechanicalReduction>173.22</mechanicalReduction>
    </actuator>
  </transmission>
  <transmission name="LShoulderPitch_Transmission">
    <type>transmission_interface/SimpleTransmission</type>
    <joint name="nao_1/LShoulderPitch">
      <hardwareInterface>hardware_interface/PositionJointInterface</hardwareInterface>
    </joint>
    <actuator name="LShoulderPitch_Motor">
      <hardwareInterface>hardware_interface/PositionJointInterface</hardwareInterface>
      <mechanicalReduction>150.27</mechanicalReduction>
    </actuator>
  </transmission>
  <transmission name="LShoulderRoll_Transmission">
    <type>transmission_interface/SimpleTransmission</type>
    <joint name="nao_1/LShoulderRoll">
      <hardwareInterface>hardware_interface/PositionJointInterface</hardwareInterface>
    </joint>
    <actuator name="LShoulderRoll_Motor">
      <hardwareInterface>hardware_interface/PositionJointInterface</hardwareInterface>
      <mechanicalReduction>173.22</mechanicalReduction>
    </actuator>
  </transmission>
  <transmission name="LElbowYaw_Transmission">
    <type>transmission_interface/SimpleTransmission</type>
    <joint name="nao_1/LElbowYaw">
      <hardwareInterface>hardware_interface/PositionJointInterface</hardwareInterface>
    </joint>
    <actuator name="LElbowYaw_Motor">
      <hardwareInterface>hardware_interface/PositionJointInterface</hardwareInterface>
      <mechanicalReduction>150.27</mechanicalReduction>
    </actuator>
  </transmission>
  <transmission name="LElbowRoll_Transmission">
    <type>transmission_interface/SimpleTransmission</type>
    <joint name="nao_1/LElbowRoll">
      <hardwareInterface>hardware_interface/PositionJointInterface</hardwareInterface>
    </joint>
    <actuator name="LElbowRoll_Motor">
      <hardwareInterface>hardware_interface/PositionJointInterface</hardwareInterface>
      <mechanicalReduction>173.22</mechanicalReduction>
    </actuator>
  </transmission>
  <transmission name="LWristYaw_Transmission">
    <type>transmission_interface/SimpleTransmission</type>
    <joint name="nao_1/LWristYaw">
      <hardwareInterface>hardware_interface/PositionJointInterface</hardwareInterface>
    </joint>
    <actuator name="LWristYaw_Motor">
      <hardwareInterface>hardware_interface/PositionJointInterface</hardwareInterface>
      <mechanicalReduction>50.61</mechanicalReduction>
    </actuator>
  </transmission>
  <transmission name="LHand_Transmission">
    <type>transmission_interface/SimpleTransmission</type>
    <joint name="nao_1/LHand">
      <hardwareInterface>hardware_interface/PositionJointInterface</hardwareInterface>
    </joint>
    <actuator name="LHand_Motor">
      <hardwareInterface>hardware_interface/PositionJointInterface</hardwareInterface>
      <mechanicalReduction>36.24</mechanicalReduction>
    </actuator>
  </transmission>
  <transmission name="RShoulderPitch_Transmission">
    <type>transmission_interface/SimpleTransmission</type>
    <joint name="nao_1/RShoulderPitch">
      <hardwareInterface>hardware_interface/PositionJointInterface</hardwareInterface>
    </joint>
    <actuator name="RShoulderPitch_Motor">
      <hardwareInterface>hardware_interface/PositionJointInterface</hardwareInterface>
      <mechanicalReduction>150.27</mechanicalReduction>
    </actuator>
  </transmission>
  <transmission name="RShoulderRoll_Transmission">
    <type>transmission_interface/SimpleTransmission</type>
    <joint name="nao_1/RShoulderRoll">
      <hardwareInterface>hardware_interface/PositionJointInterface</hardwareInterface>
    </joint>
    <actuator name="RShoulderRoll_Motor">
      <hardwareInterface>hardware_interface/PositionJointInterface</hardwareInterface>
      <mechanicalReduction>173.22</mechanicalReduction>
    </actuator>
  </transmission>
  <transmission name="RElbowYaw_Transmission">
    <type>transmission_interface/SimpleTransmission</type>
    <joint name="nao_1/RElbowYaw">
      <hardwareInterface>hardware_interface/PositionJointInterface</hardwareInterface>
    </joint>
    <actuator name="RElbowYaw_Motor">
      <hardwareInterface>hardware_interface/PositionJointInterface</hardwareInterface>
      <mechanicalReduction>150.27</mechanicalReduction>
    </actuator>
  </transmission>
  <transmission name="RElbowRoll_Transmission">
    <type>transmission_interface/SimpleTransmission</type>
    <joint name="nao_1/RElbowRoll">
      <hardwareInterface>hardware_interface/PositionJointInterface</hardwareInterface>
    </joint>
    <actuator name="RElbowRoll_Motor">
      <hardwareInterface>hardware_interface/PositionJointInterface</hardwareInterface>
      <mechanicalReduction>173.22</mechanicalReduction>
    </actuator>
  </transmission>
  <transmission name="RWristYaw_Transmission">
    <type>transmission_interface/SimpleTransmission</type>
    <joint name="nao_1/RWristYaw">
      <hardwareInterface>hardware_interface/PositionJointInterface</hardwareInterface>
    </joint>
    <actuator name="RWristYaw_Motor">
      <hardwareInterface>hardware_interface/PositionJointInterface</hardwareInterface>
      <mechanicalReduction>50.61</mechanicalReduction>
    </actuator>
  </transmission>
  <transmission name="RHand_Transmission">
    <type>transmission_interface/SimpleTransmission</type>
    <joint name="nao_1/RHand">
      <hardwareInterface>hardware_interface/PositionJointInterface</hardwareInterface>
    </joint>
    <actuator name="RHand_Motor">
      <hardwareInterface>hardware_interface/PositionJointInterface</hardwareInterface>
      <mechanicalReduction>36.24</mechanicalReduction>
    </actuator>
  </transmission>
  <transmission name="LHipYawPitch_Transmission">
    <type>transmission_interface/SimpleTransmission</type>
    <joint name="nao_1/LHipYawPitch">
      <hardwareInterface>hardware_interface/PositionJointInterface</hardwareInterface>
    </joint>
    <actuator name="LHipYawPitch_Motor">
      <!-- Dummy Values -->
      <hardwareInterface>hardware_interface/PositionJointInterface</hardwareInterface>
      <mechanicalReduction>201.3</mechanicalReduction>
    </actuator>
  </transmission>
  <transmission name="LHipRoll_Transmission">
    <type>transmission_interface/SimpleTransmission</type>
    <joint name="nao_1/LHipRoll">
      <hardwareInterface>hardware_interface/PositionJointInterface</hardwareInterface>
    </joint>
    <actuator name="LHipRoll_Motor">
      <!-- Dummy Values -->
      <hardwareInterface>hardware_interface/PositionJointInterface</hardwareInterface>
      <mechanicalReduction>201.3</mechanicalReduction>
    </actuator>
  </transmission>
  <transmission name="LHipPitch_Transmission">
    <type>transmission_interface/SimpleTransmission</type>
    <joint name="nao_1/LHipPitch">
      <hardwareInterface>hardware_interface/PositionJointInterface</hardwareInterface>
    </joint>
    <actuator name="LHipPitch_Motor">
      <!-- Dummy Values -->
      <hardwareInterface>hardware_interface/PositionJointInterface</hardwareInterface>
      <mechanicalReduction>130.85</mechanicalReduction>
    </actuator>
  </transmission>
  <transmission name="LKneePitch_Transmission">
    <type>transmission_interface/SimpleTransmission</type>
    <joint name="nao_1/LKneePitch">
      <hardwareInterface>hardware_interface/PositionJointInterface</hardwareInterface>
    </joint>
    <actuator name="LKneePitch_Motor">
      <!-- Dummy Values -->
      <hardwareInterface>hardware_interface/PositionJointInterface</hardwareInterface>
      <mechanicalReduction>130.85</mechanicalReduction>
    </actuator>
  </transmission>
  <transmission name="LAnklePitch_Transmission">
    <type>transmission_interface/SimpleTransmission</type>
    <joint name="nao_1/LAnklePitch">
      <hardwareInterface>hardware_interface/PositionJointInterface</hardwareInterface>
    </joint>
    <actuator name="LAnklePitch_Motor">
      <!-- Dummy Values -->
      <hardwareInterface>hardware_interface/PositionJointInterface</hardwareInterface>
      <mechanicalReduction>130.85</mechanicalReduction>
    </actuator>
  </transmission>
  <transmission name="LAnkleRoll_Transmission">
    <type>transmission_interface/SimpleTransmission</type>
    <joint name="nao_1/LAnkleRoll">
      <hardwareInterface>hardware_interface/PositionJointInterface</hardwareInterface>
    </joint>
    <actuator name="LAnkleRoll_Motor">
      <!-- Dummy Values -->
      <hardwareInterface>hardware_interface/PositionJointInterface</hardwareInterface>
      <mechanicalReduction>201.3</mechanicalReduction>
    </actuator>
  </transmission>
  <transmission name="RHipYawPitch_Transmission">
    <type>transmission_interface/SimpleTransmission</type>
    <joint name="nao_1/RHipYawPitch">
      <hardwareInterface>hardware_interface/PositionJointInterface</hardwareInterface>
    </joint>
    <actuator name="RHipYawPitch_Motor">
      <!-- Dummy Values -->
      <hardwareInterface>hardware_interface/PositionJointInterface</hardwareInterface>
      <mechanicalReduction>201.3</mechanicalReduction>
    </actuator>
  </transmission>
  <transmission name="RHipRoll_Transmission">
    <type>transmission_interface/SimpleTransmission</type>
    <joint name="nao_1/RHipRoll">
      <hardwareInterface>hardware_interface/PositionJointInterface</hardwareInterface>
    </joint>
    <actuator name="RHipRoll_Motor">
      <!-- Dummy Values -->
      <hardwareInterface>hardware_interface/PositionJointInterface</hardwareInterface>
      <mechanicalReduction>201.3</mechanicalReduction>
    </actuator>
  </transmission>
  <transmission name="RHipPitch_Transmission">
    <type>transmission_interface/SimpleTransmission</type>
    <joint name="nao_1/RHipPitch">
      <hardwareInterface>hardware_interface/PositionJointInterface</hardwareInterface>
    </joint>
    <actuator name="RHipPitch_Motor">
      <!-- Dummy Values -->
      <hardwareInterface>hardware_interface/PositionJointInterface</hardwareInterface>
      <mechanicalReduction>130.85</mechanicalReduction>
    </actuator>
  </transmission>
  <transmission name="RKneePitch_Transmission">
    <type>transmission_interface/SimpleTransmission</type>
    <joint name="nao_1/RKneePitch">
      <hardwareInterface>hardware_interface/PositionJointInterface</hardwareInterface>
    </joint>
    <actuator name="RKneePitch_Motor">
      <!-- Dummy Values -->
      <hardwareInterface>hardware_interface/PositionJointInterface</hardwareInterface>
      <mechanicalReduction>130.85</mechanicalReduction>
    </actuator>
  </transmission>
  <transmission name="RAnklePitch_Transmission">
    <type>transmission_interface/SimpleTransmission</type>
    <joint name="nao_1/RAnklePitch">
      <hardwareInterface>hardware_interface/PositionJointInterface</hardwareInterface>
    </joint>
    <actuator name="RAnklePitch_Motor">
      <!-- Dummy Values -->
      <hardwareInterface>hardware_interface/PositionJointInterface</hardwareInterface>
      <mechanicalReduction>130.85</mechanicalReduction>
    </actuator>
  </transmission>
  <transmission name="RAnkleRoll_Transmission">
    <type>transmission_interface/SimpleTransmission</type>
    <joint name="nao_1/RAnkleRoll">
      <hardwareInterface>hardware_interface/PositionJointInterface</hardwareInterface>
    </joint>
    <actuator name="RAnkleRoll_Motor">
      <!-- Dummy Values -->
      <hardwareInterface>hardware_interface/PositionJointInterface</hardwareInterface>
      <mechanicalReduction>201.3</mechanicalReduction>
    </actuator>
  </transmission>
  <transmission name="wheel_ll_joint_trans">
    <type>transmission_interface/SimpleTransmission</type>
    <joint name="nao_1/left_wheel_joint_l">
      <hardwareInterface>hardware_interface/VelocityJointInterface</hardwareInterface>
    </joint>
    <actuator name="left_motor">
      <hardwareInterface>hardware_interface/VelocityJointInterface</hardwareInterface>
      <mechanicalReduction>50.61</mechanicalReduction>
    </actuator>
  </transmission>
  <transmission name="wheel_lr_joint_trans">
    <type>transmission_interface/SimpleTransmission</type>
    <joint name="nao_1/left_wheel_joint_r">
      <hardwareInterface>hardware_interface/VelocityJointInterface</hardwareInterface>
    </joint>
    <actuator name="left_motor">
      <hardwareInterface>hardware_interface/VelocityJointInterface</hardwareInterface>
      <mechanicalReduction>50.61</mechanicalReduction>
    </actuator>
  </transmission>
  <transmission name="front_wheel_ll_joint_trans">
    <type>transmission_interface/SimpleTransmission</type>
    <joint name="nao_1/front_left_wheel_joint_l">
      <hardwareInterface>hardware_interface/VelocityJointInterface</hardwareInterface>
    </joint>
    <actuator name="front_left_motor">
      <hardwareInterface>hardware_interface/VelocityJointInterface</hardwareInterface>
      <mechanicalReduction>50.61</mechanicalReduction>
    </actuator>
  </transmission>
  <transmission name="front_wheel_lr_joint_trans">
    <type>transmission_interface/SimpleTransmission</type>
    <joint name="nao_1/front_left_wheel_joint_r">
      <hardwareInterface>hardware_interface/VelocityJointInterface</hardwareInterface>
    </joint>
    <actuator name="front_left_motor">
      <hardwareInterface>hardware_interface/VelocityJointInterface</hardwareInterface>
      <mechanicalReduction>50.61</mechanicalReduction>
    </actuator>
  </transmission>
  <transmission name="wheel_rl_joint_trans">
    <type>transmission_interface/SimpleTransmission</type>
    <joint name="nao_1/right_wheel_joint_l">
      <hardwareInterface>hardware_interface/VelocityJointInterface</hardwareInterface>
    </joint>
    <actuator name="right_motor">
      <hardwareInterface>hardware_interface/VelocityJointInterface</hardwareInterface>
      <mechanicalReduction>50.61</mechanicalReduction>
    </actuator>
  </transmission>
  <transmission name="wheel_rr_joint_trans">
    <type>transmission_interface/SimpleTransmission</type>
    <joint name="nao_1/right_wheel_joint_r">
      <hardwareInterface>hardware_interface/VelocityJointInterface</hardwareInterface>
    </joint>
    <actuator name="right_motor">
      <hardwareInterface>hardware_interface/VelocityJointInterface</hardwareInterface>
      <mechanicalReduction>50.61</mechanicalReduction>
    </actuator>
  </transmission>
  <transmission name="front_wheel_rl_joint_trans">
    <type>transmission_interface/SimpleTransmission</type>
    <joint name="nao_1/front_right_wheel_joint_l">
      <hardwareInterface>hardware_interface/VelocityJointInterface</hardwareInterface>
    </joint>
    <actuator name="front_right_motor">
      <hardwareInterface>hardware_interface/VelocityJointInterface</hardwareInterface>
      <mechanicalReduction>50.61</mechanicalReduction>
    </actuator>
  </transmission>
  <transmission name="front_wheel_rr_joint_trans">
    <type>transmission_interface/SimpleTransmission</type>
    <joint name="nao_1/front_right_wheel_joint_r">
      <hardwareInterface>hardware_interface/VelocityJointInterface</hardwareInterface>
    </joint>
    <actuator name="front_right_motor">
      <hardwareInterface>hardware_interface/VelocityJointInterface</hardwareInterface>
      <mechanicalReduction>50.61</mechanicalReduction>
    </actuator>
  </transmission>
</robot>

