<robot name="NaoH21V40">
    <material name="LightGrey">
        <texture />
        <color rgba="0.9 0.9 0.9 1" />
    </material>
    <link name="Accelerometer" />
    <link name="Battery" />
    <link name="CameraBottom" />
    <link name="CameraTop" />
    <link name="ChestBoard/Button" />
    <link name="Gyrometer" />
    <link name="Head/Touch/Front" />
    <link name="Head/Touch/Middle" />
    <link name="Head/Touch/Rear" />
    <link name="HeadPitch" />
    <link name="HeadPitchBothCollision_shape">
        <collision>
            <origin xyz="0 0 0" rpy="0 -0 0" />
            <geometry>
                <cylinder radius="0.053" length="0.141" />
            </geometry>
        </collision>
    </link>
    <link name="HeadYaw" />
    <link name="Head_effector" />
    <link name="InfraredL" />
    <link name="InfraredR" />
    <link name="LAnklePitch" />
    <link name="LAnklePitchSphereCollision_shape">
        <collision>
            <origin xyz="0 0 0" rpy="0 -0 0" />
            <geometry>
                <sphere radius="0.05" />
            </geometry>
        </collision>
    </link>
    <link name="LAnkleRoll" />
    <link name="LAnkleRollBothCollision_shape">
        <collision>
            <origin xyz="0 0 0" rpy="0 -0 0" />
            <geometry>
                <cylinder radius="0.02" length="0.075" />
            </geometry>
        </collision>
    </link>
    <link name="LArm_effector" />
    <link name="LElbowRoll" />
    <link name="LElbowRollBothCollision_shape">
        <collision>
            <origin xyz="0 0 0" rpy="0 -0 0" />
            <geometry>
                <cylinder radius="0.036" length="0.1743" />
            </geometry>
        </collision>
    </link>
    <link name="LElbowRollSphereCollision_shape">
        <collision>
            <origin xyz="0 0 0" rpy="0 -0 0" />
            <geometry>
                <sphere radius="0.04" />
            </geometry>
        </collision>
    </link>
    <link name="LElbowYaw" />
    <link name="LFoot/Bumper/Left" />
    <link name="LFoot/Bumper/Right" />
    <link name="LFoot/FSR/FrontLeft" />
    <link name="LFoot/FSR/FrontRight" />
    <link name="LFoot/FSR/RearLeft" />
    <link name="LFoot/FSR/RearRight" />
    <link name="LHipPitch" />
    <link name="LHipPitchBothCollision_shape">
        <collision>
            <origin xyz="0 0 0" rpy="0 -0 0" />
            <geometry>
                <cylinder radius="0.045" length="0.132718" />
            </geometry>
        </collision>
    </link>
    <link name="LHipPitchMidCollision_shape">
        <collision>
            <origin xyz="0 0 0" rpy="0 -0 0" />
            <geometry>
                <sphere radius="0.05" />
            </geometry>
        </collision>
    </link>
    <link name="LHipRoll" />
    <link name="LHipYawPitch" />
    <link name="LHipYawPitchCollision_shape">
        <collision>
            <origin xyz="0 0 0" rpy="0 -0 0" />
            <geometry>
                <sphere radius="0.035" />
            </geometry>
        </collision>
    </link>
    <link name="LKneePitch" />
    <link name="LKneePitchBothCollision_shape">
        <collision>
            <origin xyz="0 0 0" rpy="0 -0 0" />
            <geometry>
                <cylinder radius="0.047" length="0.1404" />
            </geometry>
        </collision>
    </link>
    <link name="LLeg_effector" />
    <link name="LShoulderPitch" />
    <link name="LShoulderRoll" />
    <link name="MicroFront" />
    <link name="MicroLeft" />
    <link name="MicroRear" />
    <link name="MicroRight" />
    <link name="RAnklePitch" />
    <link name="RAnklePitchSphereCollision_shape">
        <collision>
            <origin xyz="0 0 0" rpy="0 -0 0" />
            <geometry>
                <sphere radius="0.05" />
            </geometry>
        </collision>
    </link>
    <link name="RAnkleRoll" />
    <link name="RAnkleRollBothCollision_shape">
        <collision>
            <origin xyz="0 0 0" rpy="0 -0 0" />
            <geometry>
                <cylinder radius="0.02" length="0.075" />
            </geometry>
        </collision>
    </link>
    <link name="RArm_effector" />
    <link name="RElbowRoll" />
    <link name="RElbowRollBothCollision_shape">
        <collision>
            <origin xyz="0 0 0" rpy="0 -0 0" />
            <geometry>
                <cylinder radius="0.036" length="0.1743" />
            </geometry>
        </collision>
    </link>
    <link name="RElbowRollSphereCollision_shape">
        <collision>
            <origin xyz="0 0 0" rpy="0 -0 0" />
            <geometry>
                <sphere radius="0.04" />
            </geometry>
        </collision>
    </link>
    <link name="RElbowYaw" />
    <link name="RFoot/Bumper/Left" />
    <link name="RFoot/Bumper/Right" />
    <link name="RFoot/FSR/FrontLeft" />
    <link name="RFoot/FSR/FrontRight" />
    <link name="RFoot/FSR/RearLeft" />
    <link name="RFoot/FSR/RearRight" />
    <link name="RHipPitch" />
    <link name="RHipPitchBothCollision_shape">
        <collision>
            <origin xyz="0 0 0" rpy="0 -0 0" />
            <geometry>
                <cylinder radius="0.045" length="0.132718" />
            </geometry>
        </collision>
    </link>
    <link name="RHipPitchMidCollision_shape">
        <collision>
            <origin xyz="0 0 0" rpy="0 -0 0" />
            <geometry>
                <sphere radius="0.05" />
            </geometry>
        </collision>
    </link>
    <link name="RHipRoll" />
    <link name="RHipYawPitch" />
    <link name="RHipYawPitchCollision_shape">
        <collision>
            <origin xyz="0 0 0" rpy="0 -0 0" />
            <geometry>
                <sphere radius="0.035" />
            </geometry>
        </collision>
    </link>
    <link name="RKneePitch" />
    <link name="RKneePitchBothCollision_shape">
        <collision>
            <origin xyz="0 0 0" rpy="0 -0 0" />
            <geometry>
                <cylinder radius="0.047" length="0.1404" />
            </geometry>
        </collision>
    </link>
    <link name="RLeg_effector" />
    <link name="RShoulderPitch" />
    <link name="RShoulderRoll" />
    <link name="Sonar/Left" />
    <link name="Sonar/Right" />
    <link name="SpeakerLeft" />
    <link name="SpeakerRight" />
    <link name="TorsoDownBackCollision_shape">
        <collision>
            <origin xyz="0 0 0" rpy="0 -0 0" />
            <geometry>
                <sphere radius="0.04" />
            </geometry>
        </collision>
    </link>
    <link name="TorsoDownCollision_shape">
        <collision>
            <origin xyz="0 0 0" rpy="0 -0 0" />
            <geometry>
                <sphere radius="0.0453" />
            </geometry>
        </collision>
    </link>
    <link name="TorsoUpBackCollision_shape">
        <collision>
            <origin xyz="0 0 0" rpy="0 -0 0" />
            <geometry>
                <sphere radius="0.06" />
            </geometry>
        </collision>
    </link>
    <link name="TorsoUpCollision_shape">
        <collision>
            <origin xyz="0 0 0" rpy="0 -0 0" />
            <geometry>
                <sphere radius="0.0642" />
            </geometry>
        </collision>
    </link>
    <link name="Torso_link">
        <inertial>
            <mass value="1.04956" />
            <origin xyz="-0.00413 0 0.04342" rpy="0 -0 0" />
            <inertia ixx="0.00308361" ixy="1.43116e-05" ixz="-3.30211e-05" iyy="0.0028835" iyz="-2.70793e-05" izz="0.0015924" />
        </inertial>
        <visual>
            <origin xyz="0 0 0" rpy="0 -0 0" />
            <geometry>
                <mesh filename="file:////share/alrobotmodel/meshes/nao/V40/Torso.mesh" scale="1 1 1" />
            </geometry>
            <material name="LightGrey">
                <texture />
                <color rgba="0.9 0.9 0.9 1" />
            </material>
        </visual>
    </link>
    <link name="HeadYaw_link">
        <inertial>
            <mass value="0.06442" />
            <origin xyz="-1e-05 0 -0.02742" rpy="0 -0 0" />
            <inertia ixx="2.65584e-05" ixy="1.57e-09" ixz="-6.76037e-10" iyy="2.75654e-05" iyz="-5.295e-08" izz="5.53372e-06" />
        </inertial>
        <visual>
            <origin xyz="0 0 0" rpy="0 -0 0" />
            <geometry>
                <mesh filename="file:////share/alrobotmodel/meshes/nao/V40/HeadYaw.mesh" scale="1 1 1" />
            </geometry>
            <material name="LightGrey">
                <texture />
                <color rgba="0.9 0.9 0.9 1" />
            </material>
        </visual>
    </link>
    <link name="HeadPitch_link">
        <inertial>
            <mass value="0.60533" />
            <origin xyz="0.05258 -0.00112 -2.29834e-09" rpy="1.5708 5.55112e-17 1.5708" />
            <inertia ixx="0.000957766" ixy="8.78814e-06" ixz="5.33702e-06" iyy="0.000816836" iyz="-2.99579e-05" izz="0.000984976" />
        </inertial>
        <visual>
            <origin xyz="0 0 0" rpy="1.5708 5.55112e-17 1.5708" />
            <geometry>
                <mesh filename="file:////share/alrobotmodel/meshes/nao/V40/HeadPitch.mesh" scale="1 1 1" />
            </geometry>
            <material name="LightGrey">
                <texture />
                <color rgba="0.9 0.9 0.9 1" />
            </material>
        </visual>
    </link>
    <link name="LShoulderPitch_link">
        <inertial>
            <mass value="0.07504" />
            <origin xyz="-0.00165 -0.000139999 -0.02663" rpy="1.5708 -0 0" />
            <inertia ixx="3.10677e-05" ixy="1.2692e-06" ixz="6.04576e-09" iyy="1.39498e-05" iyz="-2.99484e-07" izz="3.30001e-05" />
        </inertial>
        <visual>
            <origin xyz="0 0 0" rpy="1.5708 -0 0" />
            <geometry>
                <mesh filename="file:////share/alrobotmodel/meshes/nao/V40/LShoulderPitch.mesh" scale="1 1 1" />
            </geometry>
            <material name="LightGrey">
                <texture />
                <color rgba="0.9 0.9 0.9 1" />
            </material>
        </visual>
    </link>
    <link name="LShoulderRoll_link">
        <inertial>
            <mass value="0.15777" />
            <origin xyz="0.00563 -0.02455 0.0033" rpy="0 -0 -1.5708" />
            <inertia ixx="8.7181e-05" ixy="-2.53381e-05" ixz="-1.4213e-05" iyy="0.000274712" iyz="4.71439e-07" izz="0.000241812" />
        </inertial>
        <visual>
            <origin xyz="0 0 0" rpy="0 -0 -1.5708" />
            <geometry>
                <mesh filename="file:////share/alrobotmodel/meshes/nao/V40/LShoulderRoll.mesh" scale="1 1 1" />
            </geometry>
            <material name="LightGrey">
                <texture />
                <color rgba="0.9 0.9 0.9 1" />
            </material>
        </visual>
    </link>
    <link name="LElbowYaw_link">
        <inertial>
            <mass value="0.06483" />
            <origin xyz="1.19332e-09 -0.00014 -0.02744" rpy="1.5708 -1.5708 -3.14159" />
            <inertia ixx="5.59588e-06" ixy="4.21e-09" ixz="2.92241e-07" iyy="2.66179e-05" iyz="-1.84e-09" izz="2.76294e-05" />
        </inertial>
    </link>
    <link name="LElbowRoll_link">
        <inertial>
            <mass value="0.18405" />
            <origin xyz="0.00114 -0.0653 0.00051" rpy="0 -0 -1.5708" />
            <inertia ixx="7.78172e-05" ixy="1.36722e-06" ixz="1.35711e-05" iyy="0.00033599" iyz="-4.38503e-07" izz="0.000337098" />
        </inertial>
        <visual>
            <origin xyz="0 0 0" rpy="0 -0 -1.5708" />
            <geometry>
                <mesh filename="file:////share/alrobotmodel/meshes/nao/V40/LElbowRollComplete.mesh" scale="1 1 1" />
            </geometry>
            <material name="LightGrey">
                <texture />
                <color rgba="0.9 0.9 0.9 1" />
            </material>
        </visual>
    </link>
    <link name="LHipYawPitch_link">
        <inertial>
            <mass value="0.06981" />
            <origin xyz="0.0109389 -0.00781 -0.0266933" rpy="2.35619 -0 1.5708" />
            <inertia ixx="2.3407e-05" ixy="1.07922e-06" ixz="-1.76003e-06" iyy="4.76355e-05" iyz="2.76058e-06" izz="4.97021e-05" />
        </inertial>
        <visual>
            <origin xyz="0 0 0" rpy="2.35619 -0 1.5708" />
            <geometry>
                <mesh filename="file:////share/alrobotmodel/meshes/nao/V40/LHipYawPitch.mesh" scale="1 1 1" />
            </geometry>
            <material name="LightGrey">
                <texture />
                <color rgba="0.9 0.9 0.9 1" />
            </material>
        </visual>
    </link>
    <link name="LHipRoll_link">
        <inertial>
            <mass value="0.13053" />
            <origin xyz="-0.00515 -0.00029 -0.01549" rpy="8.74228e-08 -1.5708 3.14159" />
            <inertia ixx="2.41106e-05" ixy="-6.08684e-07" ixz="6.33119e-06" iyy="6.34892e-05" iyz="-1.99137e-07" izz="5.67694e-05" />
        </inertial>
        <visual>
            <origin xyz="0 0 0" rpy="8.74228e-08 -1.5708 3.14159" />
            <geometry>
                <mesh filename="file:////share/alrobotmodel/meshes/nao/V40/LHipRoll.mesh" scale="1 1 1" />
            </geometry>
            <material name="LightGrey">
                <texture />
                <color rgba="0.9 0.9 0.9 1" />
            </material>
        </visual>
    </link>
    <link name="LHipPitch_link">
        <inertial>
            <mass value="0.38968" />
            <origin xyz="-0.05373 0.00138 0.00221" rpy="1.5708 5.55112e-17 1.5708" />
            <inertia ixx="0.000509844" ixy="2.11296e-06" ixz="5.64129e-05" iyy="0.000465358" iyz="-7.91029e-06" izz="0.000301098" />
        </inertial>
        <visual>
            <origin xyz="0 0 0" rpy="1.5708 5.55112e-17 1.5708" />
            <geometry>
                <mesh filename="file:////share/alrobotmodel/meshes/nao/V40/LHipPitch.mesh" scale="1 1 1" />
            </geometry>
            <material name="LightGrey">
                <texture />
                <color rgba="0.9 0.9 0.9 1" />
            </material>
        </visual>
    </link>
    <link name="LKneePitch_link">
        <inertial>
            <mass value="0.29142" />
            <origin xyz="-0.04936 0.00453 0.00225" rpy="1.5708 5.55112e-17 1.5708" />
            <inertia ixx="0.000470586" ixy="3.60392e-06" ixz="-2.86648e-05" iyy="0.000412654" iyz="7.13013e-06" izz="0.000185772" />
        </inertial>
        <visual>
            <origin xyz="0 0 0" rpy="1.5708 5.55112e-17 1.5708" />
            <geometry>
                <mesh filename="file:////share/alrobotmodel/meshes/nao/V40/LKneePitch.mesh" scale="1 1 1" />
            </geometry>
            <material name="LightGrey">
                <texture />
                <color rgba="0.9 0.9 0.9 1" />
            </material>
        </visual>
    </link>
    <link name="LAnklePitch_link">
        <inertial>
            <mass value="0.13416" />
            <origin xyz="0.00685 0.00045 0.00029" rpy="1.5708 5.55112e-17 1.5708" />
            <inertia ixx="3.22034e-05" ixy="-8.83212e-09" ixz="4.27549e-06" iyy="6.7943e-05" iyz="2.84849e-07" izz="5.48269e-05" />
        </inertial>
        <visual>
            <origin xyz="0 0 0" rpy="1.5708 5.55112e-17 1.5708" />
            <geometry>
                <mesh filename="file:////share/alrobotmodel/meshes/nao/V40/LAnklePitch.mesh" scale="1 1 1" />
            </geometry>
            <material name="LightGrey">
                <texture />
                <color rgba="0.9 0.9 0.9 1" />
            </material>
        </visual>
    </link>
    <link name="LAnkleRoll_link">
        <inertial>
            <mass value="0.16184" />
            <origin xyz="-0.03239 -0.0033 0.02542" rpy="8.74228e-08 -1.5708 3.14159" />
            <inertia ixx="9.78911e-05" ixy="7.88039e-06" ixz="6.1279e-06" iyy="0.000369977" iyz="1.44233e-06" izz="0.000419417" />
        </inertial>
        <visual>
            <origin xyz="0 0 0" rpy="8.74228e-08 -1.5708 3.14159" />
            <geometry>
                <mesh filename="file:////share/alrobotmodel/meshes/nao/V40/LAnkleRoll.mesh" scale="1 1 1" />
            </geometry>
            <material name="LightGrey">
                <texture />
                <color rgba="0.9 0.9 0.9 1" />
            </material>
        </visual>
    </link>
    <link name="RHipYawPitch_link">
        <inertial>
            <mass value="0.06981" />
            <origin xyz="0.0109389 -0.00781 0.0266933" rpy="0.785398 -0 1.5708" />
            <inertia ixx="3.18766e-05" ixy="-1.07152e-06" ixz="-1.77295e-06" iyy="5.18361e-05" iyz="-7.00664e-06" izz="5.39657e-05" />
        </inertial>
        <visual>
            <origin xyz="0 0 0" rpy="0.785398 -0 1.5708" />
            <geometry>
                <mesh filename="file:////share/alrobotmodel/meshes/nao/V40/RHipYawPitch.mesh" scale="1 1 1" />
            </geometry>
            <material name="LightGrey">
                <texture />
                <color rgba="0.9 0.9 0.9 1" />
            </material>
        </visual>
    </link>
    <link name="RHipRoll_link">
        <inertial>
            <mass value="0.13053" />
            <origin xyz="-0.00515 0.00029 -0.01549" rpy="8.74228e-08 -1.5708 3.14159" />
            <inertia ixx="2.41136e-05" ixy="5.67164e-07" ixz="6.30461e-06" iyy="6.34886e-05" iyz="1.97457e-07" izz="5.6773e-05" />
        </inertial>
        <visual>
            <origin xyz="0 0 0" rpy="8.74228e-08 -1.5708 3.14159" />
            <geometry>
                <mesh filename="file:////share/alrobotmodel/meshes/nao/V40/RHipRoll.mesh" scale="1 1 1" />
            </geometry>
            <material name="LightGrey">
                <texture />
                <color rgba="0.9 0.9 0.9 1" />
            </material>
        </visual>
    </link>
    <link name="RHipPitch_link">
        <inertial>
            <mass value="0.38968" />
            <origin xyz="-0.05373 0.00138 -0.00221" rpy="1.5708 5.55112e-17 1.5708" />
            <inertia ixx="0.000510607" ixy="-2.02799e-06" ixz="5.69893e-05" iyy="0.0004665" iyz="7.09563e-06" izz="0.000301333" />
        </inertial>
        <visual>
            <origin xyz="0 0 0" rpy="1.5708 5.55112e-17 1.5708" />
            <geometry>
                <mesh filename="file:////share/alrobotmodel/meshes/nao/V40/RHipPitch.mesh" scale="1 1 1" />
            </geometry>
            <material name="LightGrey">
                <texture />
                <color rgba="0.9 0.9 0.9 1" />
            </material>
        </visual>
    </link>
    <link name="RKneePitch_link">
        <inertial>
            <mass value="0.29142" />
            <origin xyz="-0.04936 0.00453 -0.00225" rpy="1.5708 5.55112e-17 1.5708" />
            <inertia ixx="0.000471336" ixy="-3.8668e-06" ixz="-3.71648e-05" iyy="0.00041228" iyz="-6.11093e-06" izz="0.000183997" />
        </inertial>
        <visual>
            <origin xyz="0 0 0" rpy="1.5708 5.55112e-17 1.5708" />
            <geometry>
                <mesh filename="file:////share/alrobotmodel/meshes/nao/V40/RKneePitch.mesh" scale="1 1 1" />
            </geometry>
            <material name="LightGrey">
                <texture />
                <color rgba="0.9 0.9 0.9 1" />
            </material>
        </visual>
    </link>
    <link name="RAnklePitch_link">
        <inertial>
            <mass value="0.13416" />
            <origin xyz="0.00685 0.00045 -0.00029" rpy="1.5708 5.55112e-17 1.5708" />
            <inertia ixx="3.22017e-05" ixy="4.68321e-08" ixz="4.28821e-06" iyy="6.79885e-05" iyz="-2.71089e-07" izz="5.48747e-05" />
        </inertial>
        <visual>
            <origin xyz="0 0 0" rpy="1.5708 5.55112e-17 1.5708" />
            <geometry>
                <mesh filename="file:////share/alrobotmodel/meshes/nao/V40/RAnklePitch.mesh" scale="1 1 1" />
            </geometry>
            <material name="LightGrey">
                <texture />
                <color rgba="0.9 0.9 0.9 1" />
            </material>
        </visual>
    </link>
    <link name="RAnkleRoll_link">
        <inertial>
            <mass value="0.16184" />
            <origin xyz="-0.03239 0.0033 0.02542" rpy="8.74228e-08 -1.5708 3.14159" />
            <inertia ixx="9.77513e-05" ixy="-7.70106e-06" ixz="5.88169e-06" iyy="0.000369108" iyz="-1.55058e-06" izz="0.000418695" />
        </inertial>
        <visual>
            <origin xyz="0 0 0" rpy="8.74228e-08 -1.5708 3.14159" />
            <geometry>
                <mesh filename="file:////share/alrobotmodel/meshes/nao/V40/RAnkleRoll.mesh" scale="1 1 1" />
            </geometry>
            <material name="LightGrey">
                <texture />
                <color rgba="0.9 0.9 0.9 1" />
            </material>
        </visual>
    </link>
    <link name="RShoulderPitch_link">
        <inertial>
            <mass value="0.07504" />
            <origin xyz="-0.00165 -0.000140001 0.02663" rpy="1.5708 -0 0" />
            <inertia ixx="3.10677e-05" ixy="-1.2692e-06" ixz="6.04576e-09" iyy="1.39498e-05" iyz="2.99484e-07" izz="3.30001e-05" />
        </inertial>
        <visual>
            <origin xyz="0 0 0" rpy="1.5708 -0 0" />
            <geometry>
                <mesh filename="file:////share/alrobotmodel/meshes/nao/V40/RShoulderPitch.mesh" scale="1 1 1" />
            </geometry>
            <material name="LightGrey">
                <texture />
                <color rgba="0.9 0.9 0.9 1" />
            </material>
        </visual>
    </link>
    <link name="RShoulderRoll_link">
        <inertial>
            <mass value="0.15777" />
            <origin xyz="-0.00563 -0.02455 0.0033" rpy="0 -0 -1.5708" />
            <inertia ixx="0.000103401" ixy="5.48849e-05" ixz="-1.32643e-05" iyy="0.00027077" iyz="9.16707e-06" izz="0.000254529" />
        </inertial>
        <visual>
            <origin xyz="0 0 0" rpy="0 -0 -1.5708" />
            <geometry>
                <mesh filename="file:////share/alrobotmodel/meshes/nao/V40/RShoulderRoll.mesh" scale="1 1 1" />
            </geometry>
            <material name="LightGrey">
                <texture />
                <color rgba="0.9 0.9 0.9 1" />
            </material>
        </visual>
    </link>
    <link name="RElbowYaw_link">
        <inertial>
            <mass value="0.06483" />
            <origin xyz="1.19332e-09 -0.00014 -0.02744" rpy="1.5708 -1.5708 -3.14159" />
            <inertia ixx="5.59588e-06" ixy="4.21e-09" ixz="2.92241e-07" iyy="2.66179e-05" iyz="-1.84e-09" izz="2.76294e-05" />
        </inertial>
    </link>
    <link name="RElbowRoll_link">
        <inertial>
            <mass value="0.18405" />
            <origin xyz="-0.00114 -0.0653 0.00051" rpy="0 -0 -1.5708" />
            <inertia ixx="7.78172e-05" ixy="-2.60349e-05" ixz="1.35711e-05" iyy="0.00033599" iyz="-6.52517e-07" izz="0.000337098" />
        </inertial>
        <visual>
            <origin xyz="0 0 0" rpy="0 -0 -1.5708" />
            <geometry>
                <mesh filename="file:////share/alrobotmodel/meshes/nao/V40/RElbowRollComplete.mesh" scale="1 1 1" />
            </geometry>
            <material name="LightGrey">
                <texture />
                <color rgba="0.9 0.9 0.9 1" />
            </material>
        </visual>
    </link>
    <link name="USSensor1" />
    <link name="USSensor2" />
    <link name="USSensor3" />
    <link name="USSensor4" />
    <link name="base_link" />
    <joint name="Accelerometer_fixedjoint" type="fixed">
        <origin xyz="-0.008 0.00606 0.027" rpy="0 -0 0" />
        <axis xyz="0 0 0" />
        <parent link="Torso_link" />
        <child link="Accelerometer" />
    </joint>
    <joint name="Battery_fixedjoint" type="fixed">
        <origin xyz="0 0 0" rpy="0 -0 0" />
        <axis xyz="0 0 0" />
        <parent link="Torso_link" />
        <child link="Battery" />
    </joint>
    <joint name="CameraBottom_fixedjoint" type="fixed">
        <origin xyz="0.01774 0.05071 0" rpy="1.5708 5.55112e-17 2.26369" />
        <axis xyz="0 0 0" />
        <parent link="HeadPitch_link" />
        <child link="CameraBottom" />
    </joint>
    <joint name="CameraTop_fixedjoint" type="fixed">
        <origin xyz="0.06364 0.05871 0" rpy="1.5708 5.55112e-17 1.59174" />
        <axis xyz="0 0 0" />
        <parent link="HeadPitch_link" />
        <child link="CameraTop" />
    </joint>
    <joint name="ChestBoard/Button_fixedjoint" type="fixed">
        <origin xyz="0.049871 0.001588 0.055163" rpy="0 -0 0" />
        <axis xyz="0 0 0" />
        <parent link="Torso_link" />
        <child link="ChestBoard/Button" />
    </joint>
    <joint name="Gyrometer_fixedjoint" type="fixed">
        <origin xyz="-0.008 0.006 0.029" rpy="0 -0 0" />
        <axis xyz="0 0 0" />
        <parent link="Torso_link" />
        <child link="Gyrometer" />
    </joint>
    <joint name="Head/Touch/Front_fixedjoint" type="fixed">
        <origin xyz="0.1014 0.0312 0" rpy="1.5708 -0 0.384697" />
        <axis xyz="0 0 0" />
        <parent link="HeadPitch_link" />
        <child link="Head/Touch/Front" />
    </joint>
    <joint name="Head/Touch/Middle_fixedjoint" type="fixed">
        <origin xyz="0.1099 0.001 0" rpy="1.5708 4.23516e-22 -4e-06" />
        <axis xyz="0 0 0" />
        <parent link="HeadPitch_link" />
        <child link="Head/Touch/Middle" />
    </joint>
    <joint name="Head/Touch/Rear_fixedjoint" type="fixed">
        <origin xyz="0.1045 -0.0257 0" rpy="1.5708 -0 -0.237603" />
        <axis xyz="0 0 0" />
        <parent link="HeadPitch_link" />
        <child link="Head/Touch/Rear" />
    </joint>
    <joint name="HeadPitchBothCollision_shape_fixedjoint" type="fixed">
        <origin xyz="0.053 0 0" rpy="-3.14159 7.88861e-31 -3.14159" />
        <axis xyz="0 0 0" />
        <parent link="HeadPitch_link" />
        <child link="HeadPitchBothCollision_shape" />
    </joint>
    <joint name="HeadPitch_fixedjoint" type="fixed">
        <origin xyz="0 0 0" rpy="1.5708 5.55112e-17 1.5708" />
        <axis xyz="0 0 0" />
        <parent link="HeadPitch_link" />
        <child link="HeadPitch" />
    </joint>
    <joint name="HeadYaw" type="revolute">
        <origin xyz="0 0 0.1265" rpy="0 -0 0" />
        <axis xyz="0 0 1" />
        <parent link="Torso_link" />
        <child link="HeadYaw_link" />
        <limit effort="1.547" velocity="8.26797" lower="-2.08567" upper="2.08567" />
    </joint>
    <joint name="HeadPitch" type="revolute">
        <origin xyz="0 0 0" rpy="1.5708 -1.5708 -3.14159" />
        <axis xyz="0 0 1" />
        <parent link="HeadYaw_link" />
        <child link="HeadPitch_link" />
        <limit effort="1.532" velocity="7.19407" lower="-0.671952" upper="0.514872" />
    </joint>
    <joint name="LShoulderPitch" type="revolute">
        <origin xyz="0 0.098 0.1" rpy="-1.5708 -0 0" />
        <axis xyz="0 0 1" />
        <parent link="Torso_link" />
        <child link="LShoulderPitch_link" />
        <limit effort="1.329" velocity="8.26797" lower="-2.08567" upper="2.08567" />
    </joint>
    <joint name="LShoulderRoll" type="revolute">
        <origin xyz="0 0 0" rpy="-1.5708 -1.5708 3.14159" />
        <axis xyz="0 0 1" />
        <parent link="LShoulderPitch_link" />
        <child link="LShoulderRoll_link" />
        <limit effort="1.7835" velocity="7.19407" lower="-0.314159" upper="1.32645" />
    </joint>
    <joint name="LElbowYaw" type="revolute">
        <origin xyz="0.015 -0.105 0" rpy="1.5708 -0 0" />
        <axis xyz="0 0 1" />
        <parent link="LShoulderRoll_link" />
        <child link="LElbowYaw_link" />
        <limit effort="1.547" velocity="8.26797" lower="-2.08567" upper="2.08567" />
    </joint>
    <joint name="LElbowRoll" type="revolute">
        <origin xyz="0 0 0" rpy="-1.5708 -0 0" />
        <axis xyz="0 0 1" />
        <parent link="LElbowYaw_link" />
        <child link="LElbowRoll_link" />
        <limit effort="1.532" velocity="7.19407" lower="-1.54462" upper="-0.0349066" />
    </joint>
    <joint name="LHipYawPitch" type="revolute">
        <origin xyz="0 0.05 -0.085" rpy="-3.14159 -0.785398 1.5708" />
        <axis xyz="0 0 1" />
        <parent link="Torso_link" />
        <child link="LHipYawPitch_link" />
        <limit effort="3.348" velocity="4.16174" lower="-1.14529" upper="0.740718" />
    </joint>
    <joint name="LHipRoll" type="revolute">
        <origin xyz="0 0 0" rpy="-1.5708 0.785398 0" />
        <axis xyz="0 0 1" />
        <parent link="LHipYawPitch_link" />
        <child link="LHipRoll_link" />
        <limit effort="3.348" velocity="4.16174" lower="-0.379435" upper="0.79046" />
    </joint>
    <joint name="LHipPitch" type="revolute">
        <origin xyz="0 0 0" rpy="1.5708 -0 0" />
        <axis xyz="0 0 1" />
        <parent link="LHipRoll_link" />
        <child link="LHipPitch_link" />
        <limit effort="3.023" velocity="6.40239" lower="-1.53589" upper="0.48398" />
    </joint>
    <joint name="LKneePitch" type="revolute">
        <origin xyz="-0.1 0 0" rpy="0 -0 0" />
        <axis xyz="0 0 1" />
        <parent link="LHipPitch_link" />
        <child link="LKneePitch_link" />
        <limit effort="3.023" velocity="6.40239" lower="-0.0923279" upper="2.11255" />
    </joint>
    <joint name="LAnklePitch" type="revolute">
        <origin xyz="-0.1029 0 0" rpy="0 -0 0" />
        <axis xyz="0 0 1" />
        <parent link="LKneePitch_link" />
        <child link="LAnklePitch_link" />
        <limit effort="3.023" velocity="6.40239" lower="-1.18944" upper="0.922581" />
    </joint>
    <joint name="LAnkleRoll" type="revolute">
        <origin xyz="0 0 0" rpy="-1.5708 -0 0" />
        <axis xyz="0 0 1" />
        <parent link="LAnklePitch_link" />
        <child link="LAnkleRoll_link" />
        <limit effort="3.348" velocity="4.16174" lower="-0.397761" upper="0.768992" />
    </joint>
    <joint name="RHipYawPitch" type="revolute">
        <origin xyz="0 -0.05 -0.085" rpy="3.09086e-08 -0.785398 -1.5708" />
        <axis xyz="0 0 1" />
        <parent link="Torso_link" />
        <child link="RHipYawPitch_link" />
        <limit effort="3.348" velocity="4.16174" lower="-1.14529" upper="0.740718" />
        <mimic offset="0" multiplier="1" joint="LHipYawPitch" />
    </joint>
    <joint name="RHipRoll" type="revolute">
        <origin xyz="0 0 0" rpy="-1.5708 -0.785398 0" />
        <axis xyz="0 0 1" />
        <parent link="RHipYawPitch_link" />
        <child link="RHipRoll_link" />
        <limit effort="3.348" velocity="4.16174" lower="-0.79046" upper="0.379435" />
    </joint>
    <joint name="RHipPitch" type="revolute">
        <origin xyz="0 0 0" rpy="1.5708 -0 0" />
        <axis xyz="0 0 1" />
        <parent link="RHipRoll_link" />
        <child link="RHipPitch_link" />
        <limit effort="3.0226" velocity="6.40239" lower="-1.53589" upper="0.48398" />
    </joint>
    <joint name="RKneePitch" type="revolute">
        <origin xyz="-0.1 0 0" rpy="0 -0 0" />
        <axis xyz="0 0 1" />
        <parent link="RHipPitch_link" />
        <child link="RKneePitch_link" />
        <limit effort="3.0226" velocity="6.40239" lower="-0.0923279" upper="2.11255" />
    </joint>
    <joint name="RAnklePitch" type="revolute">
        <origin xyz="-0.1029 0 0" rpy="0 -0 0" />
        <axis xyz="0 0 1" />
        <parent link="RKneePitch_link" />
        <child link="RAnklePitch_link" />
        <limit effort="3.0226" velocity="6.40239" lower="-1.1863" upper="0.932006" />
    </joint>
    <joint name="RAnkleRoll" type="revolute">
        <origin xyz="0 0 0" rpy="-1.5708 -0 0" />
        <axis xyz="0 0 1" />
        <parent link="RAnklePitch_link" />
        <child link="RAnkleRoll_link" />
        <limit effort="3.348" velocity="4.16174" lower="-0.768992" upper="0.397761" />
    </joint>
    <joint name="RShoulderPitch" type="revolute">
        <origin xyz="0 -0.098 0.1" rpy="-1.5708 -0 0" />
        <axis xyz="0 0 1" />
        <parent link="Torso_link" />
        <child link="RShoulderPitch_link" />
        <limit effort="1.329" velocity="8.26797" lower="-2.08567" upper="2.08567" />
    </joint>
    <joint name="RShoulderRoll" type="revolute">
        <origin xyz="0 0 0" rpy="-1.5708 -1.5708 3.14159" />
        <axis xyz="0 0 1" />
        <parent link="RShoulderPitch_link" />
        <child link="RShoulderRoll_link" />
        <limit effort="1.783" velocity="7.19407" lower="-1.32645" upper="0.314159" />
    </joint>
    <joint name="RElbowYaw" type="revolute">
        <origin xyz="-0.015 -0.105 0" rpy="1.5708 -0 0" />
        <axis xyz="0 0 1" />
        <parent link="RShoulderRoll_link" />
        <child link="RElbowYaw_link" />
        <limit effort="1.547" velocity="8.26797" lower="-2.08567" upper="2.08567" />
    </joint>
    <joint name="RElbowRoll" type="revolute">
        <origin xyz="0 0 0" rpy="-1.5708 -0 0" />
        <axis xyz="0 0 1" />
        <parent link="RElbowYaw_link" />
        <child link="RElbowRoll_link" />
        <limit effort="1.532" velocity="7.19407" lower="0.0349066" upper="1.54462" />
    </joint>
    <joint name="HeadYaw_fixedjoint" type="fixed">
        <origin xyz="0 0 0" rpy="0 -0 0" />
        <axis xyz="0 0 0" />
        <parent link="HeadYaw_link" />
        <child link="HeadYaw" />
    </joint>
    <joint name="Head_effector_fixedjoint" type="fixed">
        <origin xyz="0 0 0" rpy="1.5708 5.55112e-17 1.5708" />
        <axis xyz="0 0 0" />
        <parent link="HeadPitch_link" />
        <child link="Head_effector" />
    </joint>
    <joint name="InfraredL_fixedjoint" type="fixed">
        <origin xyz="0.0466 0.0441 0.0257" rpy="1.5708 5.55112e-17 1.5708" />
        <axis xyz="0 0 0" />
        <parent link="HeadPitch_link" />
        <child link="InfraredL" />
    </joint>
    <joint name="InfraredR_fixedjoint" type="fixed">
        <origin xyz="0.0466 0.0441 -0.0257" rpy="1.5708 5.55112e-17 1.5708" />
        <axis xyz="0 0 0" />
        <parent link="HeadPitch_link" />
        <child link="InfraredR" />
    </joint>
    <joint name="LAnklePitchSphereCollision_shape_fixedjoint" type="fixed">
        <origin xyz="0.01 0.01 -0.005" rpy="1.5708 5.55112e-17 1.5708" />
        <axis xyz="0 0 0" />
        <parent link="LAnklePitch_link" />
        <child link="LAnklePitchSphereCollision_shape" />
    </joint>
    <joint name="LAnklePitch_fixedjoint" type="fixed">
        <origin xyz="0 0 0" rpy="1.5708 5.55112e-17 1.5708" />
        <axis xyz="0 0 0" />
        <parent link="LAnklePitch_link" />
        <child link="LAnklePitch" />
    </joint>
    <joint name="LAnkleRollBothCollision_shape_fixedjoint" type="fixed">
        <origin xyz="-0.03 -0.0025 0.0825" rpy="1.5708 -0 -3.14159" />
        <axis xyz="0 0 0" />
        <parent link="LAnkleRoll_link" />
        <child link="LAnkleRollBothCollision_shape" />
    </joint>
    <joint name="LAnkleRoll_fixedjoint" type="fixed">
        <origin xyz="0 0 0" rpy="8.74228e-08 -1.5708 3.14159" />
        <axis xyz="0 0 0" />
        <parent link="LAnkleRoll_link" />
        <child link="LAnkleRoll" />
    </joint>
    <joint name="LArm_effector_fixedjoint" type="fixed">
        <origin xyz="0 -0.1137 -0.01231" rpy="0 -0 -1.5708" />
        <axis xyz="0 0 0" />
        <parent link="LElbowRoll_link" />
        <child link="LArm_effector" />
    </joint>
    <joint name="LElbowRollBothCollision_shape_fixedjoint" type="fixed">
        <origin xyz="0 -0.06485 0" rpy="1.5708 -0 0" />
        <axis xyz="0 0 0" />
        <parent link="LElbowRoll_link" />
        <child link="LElbowRollBothCollision_shape" />
    </joint>
    <joint name="LElbowRollSphereCollision_shape_fixedjoint" type="fixed">
        <origin xyz="0 -0.116 0" rpy="0 -0 -1.5708" />
        <axis xyz="0 0 0" />
        <parent link="LElbowRoll_link" />
        <child link="LElbowRollSphereCollision_shape" />
    </joint>
    <joint name="LElbowRoll_fixedjoint" type="fixed">
        <origin xyz="0 0 0" rpy="0 -0 -1.5708" />
        <axis xyz="0 0 0" />
        <parent link="LElbowRoll_link" />
        <child link="LElbowRoll" />
    </joint>
    <joint name="LElbowYaw_fixedjoint" type="fixed">
        <origin xyz="0 0 0" rpy="1.5708 -1.5708 -3.14159" />
        <axis xyz="0 0 0" />
        <parent link="LElbowYaw_link" />
        <child link="LElbowYaw" />
    </joint>
    <joint name="LFoot/Bumper/Left_fixedjoint" type="fixed">
        <origin xyz="-0.0353 -0.019 0.0876" rpy="8.74228e-08 -1.5708 3.14159" />
        <axis xyz="0 0 0" />
        <parent link="LAnkleRoll_link" />
        <child link="LFoot/Bumper/Left" />
    </joint>
    <joint name="LFoot/Bumper/Right_fixedjoint" type="fixed">
        <origin xyz="-0.0353 0.014 0.0876" rpy="8.74228e-08 -1.5708 3.14159" />
        <axis xyz="0 0 0" />
        <parent link="LAnkleRoll_link" />
        <child link="LFoot/Bumper/Right" />
    </joint>
    <joint name="LFoot/FSR/FrontLeft_fixedjoint" type="fixed">
        <origin xyz="-0.04511 -0.0299 0.07025" rpy="8.74228e-08 -1.5708 3.14159" />
        <axis xyz="0 0 0" />
        <parent link="LAnkleRoll_link" />
        <child link="LFoot/FSR/FrontLeft" />
    </joint>
    <joint name="LFoot/FSR/FrontRight_fixedjoint" type="fixed">
        <origin xyz="-0.04511 0.0231 0.07025" rpy="8.74228e-08 -1.5708 3.14159" />
        <axis xyz="0 0 0" />
        <parent link="LAnkleRoll_link" />
        <child link="LFoot/FSR/FrontRight" />
    </joint>
    <joint name="LFoot/FSR/RearLeft_fixedjoint" type="fixed">
        <origin xyz="-0.04511 -0.0299 -0.03025" rpy="8.74228e-08 -1.5708 3.14159" />
        <axis xyz="0 0 0" />
        <parent link="LAnkleRoll_link" />
        <child link="LFoot/FSR/RearLeft" />
    </joint>
    <joint name="LFoot/FSR/RearRight_fixedjoint" type="fixed">
        <origin xyz="-0.04511 0.0191 -0.02965" rpy="8.74228e-08 -1.5708 3.14159" />
        <axis xyz="0 0 0" />
        <parent link="LAnkleRoll_link" />
        <child link="LFoot/FSR/RearRight" />
    </joint>
    <joint name="LHipPitchBothCollision_shape_fixedjoint" type="fixed">
        <origin xyz="-0.04 0.002225 0.002" rpy="-1.92942 -1.30074 1.5708" />
        <axis xyz="0 0 0" />
        <parent link="LHipPitch_link" />
        <child link="LHipPitchBothCollision_shape" />
    </joint>
    <joint name="LHipPitchMidCollision_shape_fixedjoint" type="fixed">
        <origin xyz="-0.0435 0 0.006" rpy="1.5708 5.55112e-17 1.5708" />
        <axis xyz="0 0 0" />
        <parent link="LHipPitch_link" />
        <child link="LHipPitchMidCollision_shape" />
    </joint>
    <joint name="LHipPitch_fixedjoint" type="fixed">
        <origin xyz="0 0 0" rpy="1.5708 5.55112e-17 1.5708" />
        <axis xyz="0 0 0" />
        <parent link="LHipPitch_link" />
        <child link="LHipPitch" />
    </joint>
    <joint name="LHipRoll_fixedjoint" type="fixed">
        <origin xyz="0 0 0" rpy="8.74228e-08 -1.5708 3.14159" />
        <axis xyz="0 0 0" />
        <parent link="LHipRoll_link" />
        <child link="LHipRoll" />
    </joint>
    <joint name="LHipYawPitchCollision_shape_fixedjoint" type="fixed">
        <origin xyz="0.00388908 -0.0225 -0.00742461" rpy="2.35619 -0 1.5708" />
        <axis xyz="0 0 0" />
        <parent link="LHipYawPitch_link" />
        <child link="LHipYawPitchCollision_shape" />
    </joint>
    <joint name="LHipYawPitch_fixedjoint" type="fixed">
        <origin xyz="0 0 0" rpy="2.35619 -0 1.5708" />
        <axis xyz="0 0 0" />
        <parent link="LHipYawPitch_link" />
        <child link="LHipYawPitch" />
    </joint>
    <joint name="LKneePitchBothCollision_shape_fixedjoint" type="fixed">
        <origin xyz="-0.0575 -0.004 0.004" rpy="1.32449 0.785398 -1.5708" />
        <axis xyz="0 0 0" />
        <parent link="LKneePitch_link" />
        <child link="LKneePitchBothCollision_shape" />
    </joint>
    <joint name="LKneePitch_fixedjoint" type="fixed">
        <origin xyz="0 0 0" rpy="1.5708 5.55112e-17 1.5708" />
        <axis xyz="0 0 0" />
        <parent link="LKneePitch_link" />
        <child link="LKneePitch" />
    </joint>
    <joint name="LLeg_effector_fixedjoint" type="fixed">
        <origin xyz="-0.04511 0 0" rpy="8.74228e-08 -1.5708 3.14159" />
        <axis xyz="0 0 0" />
        <parent link="LAnkleRoll_link" />
        <child link="LLeg_effector" />
    </joint>
    <joint name="LShoulderPitch_fixedjoint" type="fixed">
        <origin xyz="0 0 0" rpy="1.5708 -0 0" />
        <axis xyz="0 0 0" />
        <parent link="LShoulderPitch_link" />
        <child link="LShoulderPitch" />
    </joint>
    <joint name="LShoulderRoll_fixedjoint" type="fixed">
        <origin xyz="0 0 0" rpy="0 -0 -1.5708" />
        <axis xyz="0 0 0" />
        <parent link="LShoulderRoll_link" />
        <child link="LShoulderRoll" />
    </joint>
    <joint name="MicroFront_fixedjoint" type="fixed">
        <origin xyz="0.091 0.041 0" rpy="1.5708 5.55112e-17 1.5708" />
        <axis xyz="0 0 0" />
        <parent link="HeadPitch_link" />
        <child link="MicroFront" />
    </joint>
    <joint name="MicroLeft_fixedjoint" type="fixed">
        <origin xyz="0.0331 -0.0195 0.0606" rpy="1.5708 5.55112e-17 1.5708" />
        <axis xyz="0 0 0" />
        <parent link="HeadPitch_link" />
        <child link="MicroLeft" />
    </joint>
    <joint name="MicroRear_fixedjoint" type="fixed">
        <origin xyz="0.0693 -0.0577 0" rpy="1.5708 5.55112e-17 1.5708" />
        <axis xyz="0 0 0" />
        <parent link="HeadPitch_link" />
        <child link="MicroRear" />
    </joint>
    <joint name="MicroRight_fixedjoint" type="fixed">
        <origin xyz="0.0331 -0.0195 -0.0606" rpy="1.5708 5.55112e-17 1.5708" />
        <axis xyz="0 0 0" />
        <parent link="HeadPitch_link" />
        <child link="MicroRight" />
    </joint>
    <joint name="RAnklePitchSphereCollision_shape_fixedjoint" type="fixed">
        <origin xyz="0.01 0.01 0.005" rpy="1.5708 5.55112e-17 1.5708" />
        <axis xyz="0 0 0" />
        <parent link="RAnklePitch_link" />
        <child link="RAnklePitchSphereCollision_shape" />
    </joint>
    <joint name="RAnklePitch_fixedjoint" type="fixed">
        <origin xyz="0 0 0" rpy="1.5708 5.55112e-17 1.5708" />
        <axis xyz="0 0 0" />
        <parent link="RAnklePitch_link" />
        <child link="RAnklePitch" />
    </joint>
    <joint name="RAnkleRollBothCollision_shape_fixedjoint" type="fixed">
        <origin xyz="-0.03 0.0025 0.0825" rpy="1.5708 -0 -3.14159" />
        <axis xyz="0 0 0" />
        <parent link="RAnkleRoll_link" />
        <child link="RAnkleRollBothCollision_shape" />
    </joint>
    <joint name="RAnkleRoll_fixedjoint" type="fixed">
        <origin xyz="0 0 0" rpy="8.74228e-08 -1.5708 3.14159" />
        <axis xyz="0 0 0" />
        <parent link="RAnkleRoll_link" />
        <child link="RAnkleRoll" />
    </joint>
    <joint name="RArm_effector_fixedjoint" type="fixed">
        <origin xyz="0 -0.1137 -0.01231" rpy="0 -0 -1.5708" />
        <axis xyz="0 0 0" />
        <parent link="RElbowRoll_link" />
        <child link="RArm_effector" />
    </joint>
    <joint name="RElbowRollBothCollision_shape_fixedjoint" type="fixed">
        <origin xyz="0 -0.06485 0" rpy="1.5708 -0 0" />
        <axis xyz="0 0 0" />
        <parent link="RElbowRoll_link" />
        <child link="RElbowRollBothCollision_shape" />
    </joint>
    <joint name="RElbowRollSphereCollision_shape_fixedjoint" type="fixed">
        <origin xyz="0 -0.116 0" rpy="0 -0 -1.5708" />
        <axis xyz="0 0 0" />
        <parent link="RElbowRoll_link" />
        <child link="RElbowRollSphereCollision_shape" />
    </joint>
    <joint name="RElbowRoll_fixedjoint" type="fixed">
        <origin xyz="0 0 0" rpy="0 -0 -1.5708" />
        <axis xyz="0 0 0" />
        <parent link="RElbowRoll_link" />
        <child link="RElbowRoll" />
    </joint>
    <joint name="RElbowYaw_fixedjoint" type="fixed">
        <origin xyz="0 0 0" rpy="1.5708 -1.5708 -3.14159" />
        <axis xyz="0 0 0" />
        <parent link="RElbowYaw_link" />
        <child link="RElbowYaw" />
    </joint>
    <joint name="RFoot/Bumper/Left_fixedjoint" type="fixed">
        <origin xyz="-0.0353 -0.014 0.0876" rpy="8.74228e-08 -1.5708 3.14159" />
        <axis xyz="0 0 0" />
        <parent link="RAnkleRoll_link" />
        <child link="RFoot/Bumper/Left" />
    </joint>
    <joint name="RFoot/Bumper/Right_fixedjoint" type="fixed">
        <origin xyz="-0.0353 0.019 0.0876" rpy="8.74228e-08 -1.5708 3.14159" />
        <axis xyz="0 0 0" />
        <parent link="RAnkleRoll_link" />
        <child link="RFoot/Bumper/Right" />
    </joint>
    <joint name="RFoot/FSR/FrontLeft_fixedjoint" type="fixed">
        <origin xyz="-0.04511 -0.0231 0.07025" rpy="8.74228e-08 -1.5708 3.14159" />
        <axis xyz="0 0 0" />
        <parent link="RAnkleRoll_link" />
        <child link="RFoot/FSR/FrontLeft" />
    </joint>
    <joint name="RFoot/FSR/FrontRight_fixedjoint" type="fixed">
        <origin xyz="-0.04511 0.0299 0.07025" rpy="8.74228e-08 -1.5708 3.14159" />
        <axis xyz="0 0 0" />
        <parent link="RAnkleRoll_link" />
        <child link="RFoot/FSR/FrontRight" />
    </joint>
    <joint name="RFoot/FSR/RearLeft_fixedjoint" type="fixed">
        <origin xyz="-0.04511 -0.0191 -0.03025" rpy="8.74228e-08 -1.5708 3.14159" />
        <axis xyz="0 0 0" />
        <parent link="RAnkleRoll_link" />
        <child link="RFoot/FSR/RearLeft" />
    </joint>
    <joint name="RFoot/FSR/RearRight_fixedjoint" type="fixed">
        <origin xyz="-0.04511 0.0299 -0.02965" rpy="8.74228e-08 -1.5708 3.14159" />
        <axis xyz="0 0 0" />
        <parent link="RAnkleRoll_link" />
        <child link="RFoot/FSR/RearRight" />
    </joint>
    <joint name="RHipPitchBothCollision_shape_fixedjoint" type="fixed">
        <origin xyz="-0.04 0.002225 -0.002" rpy="1.21217 -1.30074 -1.5708" />
        <axis xyz="0 0 0" />
        <parent link="RHipPitch_link" />
        <child link="RHipPitchBothCollision_shape" />
    </joint>
    <joint name="RHipPitchMidCollision_shape_fixedjoint" type="fixed">
        <origin xyz="-0.0435 0 -0.006" rpy="1.5708 5.55112e-17 1.5708" />
        <axis xyz="0 0 0" />
        <parent link="RHipPitch_link" />
        <child link="RHipPitchMidCollision_shape" />
    </joint>
    <joint name="RHipPitch_fixedjoint" type="fixed">
        <origin xyz="0 0 0" rpy="1.5708 5.55112e-17 1.5708" />
        <axis xyz="0 0 0" />
        <parent link="RHipPitch_link" />
        <child link="RHipPitch" />
    </joint>
    <joint name="RHipRoll_fixedjoint" type="fixed">
        <origin xyz="0 0 0" rpy="8.74228e-08 -1.5708 3.14159" />
        <axis xyz="0 0 0" />
        <parent link="RHipRoll_link" />
        <child link="RHipRoll" />
    </joint>
    <joint name="RHipYawPitchCollision_shape_fixedjoint" type="fixed">
        <origin xyz="0.00388908 -0.0225 0.00742461" rpy="0.785398 -0 1.5708" />
        <axis xyz="0 0 0" />
        <parent link="RHipYawPitch_link" />
        <child link="RHipYawPitchCollision_shape" />
    </joint>
    <joint name="RHipYawPitch_fixedjoint" type="fixed">
        <origin xyz="0 0 0" rpy="0.785398 -0 1.5708" />
        <axis xyz="0 0 0" />
        <parent link="RHipYawPitch_link" />
        <child link="RHipYawPitch" />
    </joint>
    <joint name="RKneePitchBothCollision_shape_fixedjoint" type="fixed">
        <origin xyz="-0.0575 -0.004 -0.004" rpy="-1.81711 0.785398 1.5708" />
        <axis xyz="0 0 0" />
        <parent link="RKneePitch_link" />
        <child link="RKneePitchBothCollision_shape" />
    </joint>
    <joint name="RKneePitch_fixedjoint" type="fixed">
        <origin xyz="0 0 0" rpy="1.5708 5.55112e-17 1.5708" />
        <axis xyz="0 0 0" />
        <parent link="RKneePitch_link" />
        <child link="RKneePitch" />
    </joint>
    <joint name="RLeg_effector_fixedjoint" type="fixed">
        <origin xyz="-0.04511 0 0" rpy="8.74228e-08 -1.5708 3.14159" />
        <axis xyz="0 0 0" />
        <parent link="RAnkleRoll_link" />
        <child link="RLeg_effector" />
    </joint>
    <joint name="RShoulderPitch_fixedjoint" type="fixed">
        <origin xyz="0 0 0" rpy="1.5708 -0 0" />
        <axis xyz="0 0 0" />
        <parent link="RShoulderPitch_link" />
        <child link="RShoulderPitch" />
    </joint>
    <joint name="RShoulderRoll_fixedjoint" type="fixed">
        <origin xyz="0 0 0" rpy="0 -0 -1.5708" />
        <axis xyz="0 0 0" />
        <parent link="RShoulderRoll_link" />
        <child link="RShoulderRoll" />
    </joint>
    <joint name="Sonar/Left_fixedjoint" type="fixed">
        <origin xyz="0.00558253 0.0192068 0.0623853" rpy="-0.00478508 0.0436497 0.392441" />
        <axis xyz="0 0 0" />
        <parent link="Torso_link" />
        <child link="Sonar/Left" />
    </joint>
    <joint name="Sonar/Right_fixedjoint" type="fixed">
        <origin xyz="0.00558253 -0.0192068 0.0623853" rpy="0.00478508 0.0436497 -0.392441" />
        <axis xyz="0 0 0" />
        <parent link="Torso_link" />
        <child link="Sonar/Right" />
    </joint>
    <joint name="SpeakerLeft_fixedjoint" type="fixed">
        <origin xyz="0.0526 0.0038 0.0453" rpy="-1.5708 -1.57079 -1.5708" />
        <axis xyz="0 0 0" />
        <parent link="HeadPitch_link" />
        <child link="SpeakerLeft" />
    </joint>
    <joint name="SpeakerRight_fixedjoint" type="fixed">
        <origin xyz="0.0526 0.0038 -0.0453" rpy="-1.5708 1.57079 -1.5708" />
        <axis xyz="0 0 0" />
        <parent link="HeadPitch_link" />
        <child link="SpeakerRight" />
    </joint>
    <joint name="TorsoDownBackCollision_shape_fixedjoint" type="fixed">
        <origin xyz="-0.03 0 -0.06" rpy="0 -0 0" />
        <axis xyz="0 0 0" />
        <parent link="Torso_link" />
        <child link="TorsoDownBackCollision_shape" />
    </joint>
    <joint name="TorsoDownCollision_shape_fixedjoint" type="fixed">
        <origin xyz="0.0006 0 -0.015" rpy="0 -0 0" />
        <axis xyz="0 0 0" />
        <parent link="Torso_link" />
        <child link="TorsoDownCollision_shape" />
    </joint>
    <joint name="TorsoUpBackCollision_shape_fixedjoint" type="fixed">
        <origin xyz="-0.01 0 0" rpy="0 -0 0" />
        <axis xyz="0 0 0" />
        <parent link="Torso_link" />
        <child link="TorsoUpBackCollision_shape" />
    </joint>
    <joint name="TorsoUpCollision_shape_fixedjoint" type="fixed">
        <origin xyz="0.0019 0 0.056" rpy="0 -0 0" />
        <axis xyz="0 0 0" />
        <parent link="Torso_link" />
        <child link="TorsoUpCollision_shape" />
    </joint>
    <joint name="USSensor1_fixedjoint" type="fixed">
        <origin xyz="0.0537 -0.0341 0.0698" rpy="1.8999e-07 -0.1745 -0.349" />
        <axis xyz="0 0 0" />
        <parent link="Torso_link" />
        <child link="USSensor1" />
    </joint>
    <joint name="USSensor2_fixedjoint" type="fixed">
        <origin xyz="0.0477 -0.0416 0.0509" rpy="-5.21541e-07 0.2618 -0.436301" />
        <axis xyz="0 0 0" />
        <parent link="Torso_link" />
        <child link="USSensor2" />
    </joint>
    <joint name="USSensor3_fixedjoint" type="fixed">
        <origin xyz="0.0537 0.0341 0.0698" rpy="-1.8999e-07 -0.1745 0.349" />
        <axis xyz="0 0 0" />
        <parent link="Torso_link" />
        <child link="USSensor3" />
    </joint>
    <joint name="USSensor4_fixedjoint" type="fixed">
        <origin xyz="0.0477 0.0416 0.0509" rpy="5.21541e-07 0.2618 0.436301" />
        <axis xyz="0 0 0" />
        <parent link="Torso_link" />
        <child link="USSensor4" />
    </joint>
    <joint name="base_link_fixedjoint" type="fixed">
        <origin xyz="0 0 0" rpy="0 -0 0" />
        <axis xyz="0 0 0" />
        <parent link="base_link" />
        <child link="Torso_link" />
    </joint>
</robot>
